Workbook

Sheet Front Page
G23: Financial Modeling & Valuation Report
G25: ASIAN PAINTS LTD
D27: NSE / BSE: ASIANPAINT | BSE CODE: 500820 | SECTOR: PAINTS & HOME DECOR

Sheet Content
B2: Table of Content
B3: Asian Paints Ltd | BSE code: 500820
B8: 1 | C8: One Page Profile (Teaser) | K8: 1
B9: 2 | C9: Historical Financial Statements | K9: 2
B10: 3 | C10: Cash Flow Statement | K10: 3
B11: 4 | C11: Ratio Analysis | K11: 4
B12: 5 | C12: Common Size Staement | K12: 5
B13: 6 | C13: Assumptions Sheet | K13: 6
B14: 7 | C14: Forcasted Financial Statements | K14: 7
B15: 8 | C15: Beta Regression - Asian Paints Ltd | K15: 8
B16: 9 | C16: Comps Beta | K16: 9
B17: 10 | C17: Return on Market | K17: 10
B18: 11 | C18: Weighted Average Cost of Capital (WACC) | K18: 11
B19: 12 | C19: Intrinsic Growth | K19: 12
... B26: 19 | C26: Altman's Z Score Analysis | K26: 19

Sheet Teaser
B3: ='Data Sheet'!B1&" - One Page Profile" -> ASIAN PAINTS LTD - One Page Profile
C5: =InputSheet!C2 -> Asian Paints Ltd is an Indian multinational paint company, headquartered in Mumbai. The company is engaged in the business of manufacturing, selling and distribution of paints, coatings, products related to home décor, bath fittings and providing related services.
B7: Key Financial Metrics | C7: =HistoricalFS!H3 -> 44651 | D7: =HistoricalFS!I3 -> 45016 | E7: =HistoricalFS!J3 -> 45382 | F7: =HistoricalFS!K3 -> 45747 | G7: =HistoricalFS!L3 -> 46112 | I7: Share Price - 5Y
B9: Total Sales | C9: =HistoricalFS!H6 -> 29101.28 | D9: =HistoricalFS!I6 -> 34488.59 | E9: =HistoricalFS!J6 -> 35494.73 | F9: =HistoricalFS!K6 -> 33905.62 | G9: =HistoricalFS!L6 -> 35583.54
B10: Sales Growth (Y-O-Y) | C10: =HistoricalFS!H7 -> 0.34028285 | D10: =HistoricalFS!I7 -> 0.18512278 | E10: =HistoricalFS!J7 -> 0.029173127 | F10: =HistoricalFS!K7 -> -0.044770308 | G10: =HistoricalFS!L7 -> 0.049487961
B12: Gross Profit | C12: =HistoricalFS!H12 -> 8510.71 | D12: =HistoricalFS!I12 -> 10721.89 | E12: =HistoricalFS!J12 -> 12484.74 | F12: =HistoricalFS!K12 -> 11164.35 | G12: =HistoricalFS!L12 -> 12093.91
B13: Gross Profit Margins (%) | C13: =HistoricalFS!H13 -> 0.2924514 | D13: =HistoricalFS!I13 -> 0.31088224 | E13: =HistoricalFS!J13 -> 0.35173503 | F13: =HistoricalFS!K13 -> 0.32927727 | G13: =HistoricalFS!L13 -> 0.33987372
B14: EBITDA Margins (%) | C14: =HistoricalFS!H19 -> 0.16506525 | D14: =HistoricalFS!I19 -> 0.18150467 | E14: =HistoricalFS!J19 -> 0.21369313 | F14: =HistoricalFS!K19 -> 0.17714497 | G14: =HistoricalFS!L19 -> 0.18828172
B15: EBIT Margins (%) | C15: =HistoricalFS!H28 -> 0.14718012 | D15: =HistoricalFS!I28 -> 0.16913652 | E15: =HistoricalFS!J28 -> 0.21279046 | F15: =HistoricalFS!K28 -> 0.15720373 | G15: =HistoricalFS!L28 -> 0.17420555
B16: Net Profit Margins (In Rs) | C16: =HistoricalFS!H39 -> 3084.81 | D16: =HistoricalFS!I39 -> 4195.33 | E16: =HistoricalFS!J39 -> 5557.69 | F16: =HistoricalFS!K39 -> 3709.71 | G16: =HistoricalFS!L39 -> 4394.69
B17: Earning Per Share (In Rs) | C17: =HistoricalFS!H44 -> 32.160238 | D17: =HistoricalFS!I44 -> 43.737802 | E17: =HistoricalFS!J44 -> 57.940888 | F17: =HistoricalFS!K44 -> 38.675042 | G17: =HistoricalFS!L44 -> 45.816201
B18: EPS Growth (Y-O-Y) | C18: =HistoricalFS!H45 -> -0.038026039 | D18: =HistoricalFS!I45 -> 0.35999624 | E18: =HistoricalFS!J45 -> 0.3247325 | F18: =HistoricalFS!K45 -> -0.33250865 | G18: =HistoricalFS!L45 -> 0.18464516
B19: Dividend Per Share | C19: =HistoricalFS!H47 -> 19.150021 | D19: =HistoricalFS!I47 -> 25.650021 | E19: =HistoricalFS!J47 -> 33.300042 | F19: =HistoricalFS!K47 -> 24.800042 | G19: =HistoricalFS!L47 -> 27.5
B20: Dividend Growth | C20: ='Data Sheet'!G34 -> 0.072831553 | D20: ='Data Sheet'!H34 -> 0.33942522 | E20: ='Data Sheet'!I34 -> 0.29824618 | F20: ='Data Sheet'!J34 -> -0.25525494 | G20: ='Data Sheet'!K34 -> 0.1088691
B22: Key Financial Ratio | C22: =HistoricalFS!H3 -> 44651 | D22: =HistoricalFS!I3 -> 45016 | E22: =HistoricalFS!J3 -> 45382 | F22: =HistoricalFS!K3 -> 45747 | G22: =HistoricalFS!L3 -> 46112 | I22: Volumes - 5Y
B24: Price to Earning | C24: ='Data Sheet'!G96 -> 82.250636 | D24: ='Data Sheet'!H96 -> 60.478576 | E24: ='Data Sheet'!I96 -> 45.653425 | F24: ='Data Sheet'!J96 -> 68.395531 | G24: ='Data Sheet'!K96 -> 57.735036
B25: EV/EBITDA | C25: ='Data Sheet'!G99 -> 1.7928248 | D25: ='Data Sheet'!H99 -> 1.1006519 | E25: ='Data Sheet'!I99 -> 0.76064097 | F25: ='Data Sheet'!J99 -> 1.3434111 | G25: ='Data Sheet'!K99 -> 1.2527661
B26: EV/Sales | C26: ='Data Sheet'!G100 -> 0.29593307 | D26: ='Data Sheet'!H100 -> 0.19977346 | E26: ='Data Sheet'!I100 -> 0.16254375 | F26: ='Data Sheet'!J100 -> 0.23797852 | G26: ='Data Sheet'!K100 -> 0.23587295
B27: Price to Book Value | C27: ='Data Sheet'!G102 -> 0.57122302 | D27: ='Data Sheet'!H102 -> 0.36274522 | E27: ='Data Sheet'!I102 -> 0.23382136 | F27: ='Data Sheet'!J102 -> 0.33817338 | G27: ='Data Sheet'!K102 -> 0.25912647
B28: Return on Equity (%) | C28: ='Ratio Analysis'!H29 -> 0.22334986 | D28: ='Ratio Analysis'!I29 -> 0.26233552 | E28: ='Ratio Analysis'!J29 -> 0.29675358 | F28: ='Ratio Analysis'!K29 -> 0.19122404 | G28: ='Ratio Analysis'!L29 -> 0.20563234
B29: Return on Capital Employed (%) | C29: ='Ratio Analysis'!H27 -> 0.2781535 | D29: ='Ratio Analysis'!I27 -> 0.32542978 | E29: ='Ratio Analysis'!J27 -> 0.35622572 | F29: ='Ratio Analysis'!K27 -> 0.24573838 | G29: ='Ratio Analysis'!L27 -> 0.2450088
B31: Top 10 Share Holders | C31: =RawData!AB2 -> N. Shares (In Cr) | E31: =RawData!AC2 -> (%) Holding | F31: Market Value (In Cr) | I31: Share Holding Pattern
B33: =RawData!AA3 -> Life Insurance Corporation of India | C33: =RawData!AB3 -> 7.7822006 | E33: =RawData!AC3 -> 0.0811 | F33: =C33*'Data Sheet'!$B$8 -> 20585.477
B34: =RawData!AA4 -> Sattva Holding and Trading Private Limited | C34: =RawData!AB4 -> 5.4789183 | E34: =RawData!AC4 -> 0.0571 | F34: =C34*'Data Sheet'!$B$8 -> 14492.835
B35: =RawData!AA5 -> Smiti Holding and Trading Company Private Limited | C35: =RawData!AB5 -> 5.1442638 | E35: =RawData!AC5 -> 0.0536 | F35: =C35*'Data Sheet'!$B$8 -> 13607.607
B36: =RawData!AA6 -> SBI Mutual Fund | C36: =RawData!AB6 -> 4.9885007 | E36: =RawData!AC6 -> 0.052 | F36: =C36*'Data Sheet'!$B$8 -> 13195.582
B37: =RawData!AA7 -> Geetanjali Trading and Investments Private Limited | C37: =RawData!AB7 -> 4.570614 | E37: =RawData!AC7 -> 0.0477 | F37: =C37*'Data Sheet'!$B$8 -> 12090.188
B38: =RawData!AA8 -> Elcid Investments Limited | C38: =RawData!AB8 -> 2.831386 | E38: =RawData!AC8 -> 0.0295 | F38: =C38*'Data Sheet'!$B$8 -> 7489.5822
B39: =RawData!AA9 -> Shubhit Holdings Private Limited | C39: =RawData!AB9 -> 2.315073 | E39: =RawData!AC9 -> 0.0241 | F39: =C39*'Data Sheet'!$B$8 -> 6123.8311
B40: =RawData!AA10 -> ICICI Prudential Mutual Fund | C40: =RawData!AB10 -> 2.1582801 | E40: =RawData!AC10 -> 0.0225 | F40: =C40*'Data Sheet'!$B$8 -> 5709.0825
B41: =RawData!AA11 -> Sudhanva Investments and Trading Company Private Limited | C41: =RawData!AB11 -> 1.900176 | E41: =RawData!AC11 -> 0.0198 | F41: =C41*'Data Sheet'!$B$8 -> 5026.3456
B42: =RawData!AA12 -> Rupen Investment & Industries Private Limited | C42: =RawData!AB12 -> 1.8849825 | E42: =RawData!AC12 -> 0.0197 | F42: =C42*'Data Sheet'!$B$8 -> 4986.1557
B44: Managerial Remuneration | C44: Designation | D44: Remuneration | F44: Ratio to Median | I44: Capital Structure
B46: Mr. Amit Syngle | C46: MD & CEO | D46: 312446860 | F46: 249.09 | I46: Share Price | K46: ='Data Sheet'!B8 -> 2645.2
B47: R J Jeyamurugan | C47: CFO | D47: 53653863 | F47: 42.77 | I47: No of Share | K47: ='Data Sheet'!B6 -> 95.919779
B48: R Seshasayee | C48: Chairman | D48: 13700000 | F48: 10.92 | I48: Market Capitalization | K48: =K47*K46 -> 253727
B49: Manish Choksi | C49: V. Chairman | D49: 8000000 | F49: 6.38 | I49: Less: Cash & Equivalent | K49: =-'Data Sheet'!K69 -> -1073.68
I50: Add: Total Debt | K50: ='Data Sheet'!K59 -> 3928.93
I51: Add: Minority Interest | K51: 643.39
I52: Enterprise Value | K52: =SUM(K48:K51) -> 257225.64
...

Sheet HistoricalFS
B2: ="Historical Financial Statement"&" - " &'Data Sheet'!B1 -> Historical Financial Statement - ASIAN PAINTS LTD
B3: Years | C3: ='Data Sheet'!B16 -> 42825 | D3: ='Data Sheet'!C16 -> 43190 | E3: ='Data Sheet'!D16 -> 43555 | F3: ='Data Sheet'!E16 -> 43921 | G3: ='Data Sheet'!F16 -> 44286 | H3: ='Data Sheet'!G16 -> 44651 | I3: ='Data Sheet'!H16 -> 45016 | J3: ='Data Sheet'!I16 -> 45382 | ... L3: ='Data Sheet'!K16 -> 46112
A5: # | B5: ="Income Statement"&" - "&'Data Sheet'!B1 -> Income Statement - ASIAN PAINTS LTD
B6: Sales | C6: =IFERROR('Data Sheet'!B17,0) -> 15061.99 | D6: =IFERROR('Data Sheet'!C17,0) -> 16824.55 | E6: =IFERROR('Data Sheet'!D17,0) -> 19240.13 | F6: =IFERROR('Data Sheet'!E17,0) -> 20211.25 | G6: =IFERROR('Data Sheet'!F17,0) -> 21712.79 | H6: =IFERROR('Data Sheet'!G17,0) -> 29101.28 | I6: =IFERROR('Data Sheet'!H17,0) -> 34488.59 | J6: =IFERROR('Data Sheet'!I17,0) -> 35494.73 | ... L6: =IFERROR('Data Sheet'!K17,0) -> 35583.54
B7: Sales Growth | D7: =IFERROR(D6/C6-1,0) -> 0.11702039 | E7: =IFERROR(E6/D6-1,0) -> 0.14357472 | F7: =IFERROR(F6/E6-1,0) -> 0.050473671 | G7: =IFERROR(G6/F6-1,0) -> 0.074292288 | H7: =IFERROR(H6/G6-1,0) -> 0.34028285 | I7: =IFERROR(I6/H6-1,0) -> 0.18512278 | J7: =IFERROR(J6/I6-1,0) -> 0.029173127 | K7: =IFERROR(K6/J6-1,0) -> -0.044770308 | L7: =IFERROR(L6/K6-1,0) -> 0.049487961
B9: COGS | C9: =IFERROR(SUM('Data Sheet'!B18,'Data Sheet'!B20:B22)-1*'Data Sheet'!B19,0) -> 9732.66 | D9: =IFERROR(SUM('Data Sheet'!C18,'Data Sheet'!C20:C22)-1*'Data Sheet'!C19,0) -> 11194.17 | E9: =IFERROR(SUM('Data Sheet'!D18,'Data Sheet'!D20:D22)-1*'Data Sheet'!D19,0) -> 12905.81 | F9: =IFERROR(SUM('Data Sheet'!E18,'Data Sheet'!E20:E22)-1*'Data Sheet'!E19,0) -> 13158.02 | G9: =IFERROR(SUM('Data Sheet'!F18,'Data Sheet'!F20:F22)-1*'Data Sheet'!F19,0) -> 14035.07 | H9: =IFERROR(SUM('Data Sheet'!G18,'Data Sheet'!G20:G22)-1*'Data Sheet'!G19,0) -> 20590.57 | I9: =IFERROR(SUM('Data Sheet'!H18,'Data Sheet'!H20:H22)-1*'Data Sheet'!H19,0) -> 23766.7 | J9: =IFERROR(SUM('Data Sheet'!I18,'Data Sheet'!I20:I22)-1*'Data Sheet'!I19,0) -> 23009.99 | ... L9: =IFERROR(SUM('Data Sheet'!K18,'Data Sheet'!K20:K22)-1*'Data Sheet'!K19,0) -> 23489.63
B10: COGS % of Sales | C10: =IFERROR(C9/C6,0) -> 0.64617358 | D10: =IFERROR(D9/D6,0) -> 0.66534736 | E10: =IFERROR(E9/E6,0) -> 0.67077561 | F10: =IFERROR(F9/F6,0) -> 0.65102455 | G10: =IFERROR(G9/G6,0) -> 0.64639643 | H10: =IFERROR(H9/H6,0) -> 0.7075486 | I10: =IFERROR(I9/I6,0) -> 0.68911776 | J10: =IFERROR(J9/J6,0) -> 0.64826497 | ... L10: =IFERROR(L9/L6,0) -> 0.66012628
B12: Gross Profit | C12: =IFERROR(C6-C9,0) -> 5329.33 | D12: =IFERROR(D6-D9,0) -> 5630.38 | E12: =IFERROR(E6-E9,0) -> 6334.32 | F12: =IFERROR(F6-F9,0) -> 7053.23 | G12: =IFERROR(G6-G9,0) -> 7677.72 | H12: =IFERROR(H6-H9,0) -> 8510.71 | I12: =IFERROR(I6-I9,0) -> 10721.89 | J12: =IFERROR(J6-J9,0) -> 12484.74 | ... L12: =IFERROR(L6-L9,0) -> 12093.91
B13: Gross Margin | C13: =IFERROR(C12/C6,0) -> 0.35382642 | D13: =IFERROR(D12/D6,0) -> 0.33465264 | E13: =IFERROR(E12/E6,0) -> 0.32922439 | F13: =IFERROR(F12/F6,0) -> 0.34897545 | G13: =IFERROR(G12/G6,0) -> 0.35360357 | H13: =IFERROR(H12/H6,0) -> 0.2924514 | I13: =IFERROR(I12/I6,0) -> 0.31088224 | J13: =IFERROR(J12/J6,0) -> 0.35173503 | ... L13: =IFERROR(L12/L6,0) -> 0.33987372
B15: Selling & General Expenses | C15: =IFERROR(SUM('Data Sheet'!B23:B24),0) -> 2335.57 | D15: =IFERROR(SUM('Data Sheet'!C23:C24),0) -> 2426.37 | E15: =IFERROR(SUM('Data Sheet'!D23:D24),0) -> 2569.38 | F15: =IFERROR(SUM('Data Sheet'!E23:E24),0) -> 2891.46 | G15: =IFERROR(SUM('Data Sheet'!F23:F24),0) -> 2822.12 | H15: =IFERROR(SUM('Data Sheet'!G23:G24),0) -> 3707.1 | I15: =IFERROR(SUM('Data Sheet'!H23:H24),0) -> 4462.05 | J15: =IFERROR(SUM('Data Sheet'!I23:I24),0) -> 4899.76 | ... L15: =IFERROR(SUM('Data Sheet'!K23:K24),0) -> 5394.18
B16: S&G Exp % of Sales | C16: =IFERROR(C15/C6,0) -> 0.15506384 | D16: =IFERROR(D15/D6,0) -> 0.14421604 | E16: =IFERROR(E15/E6,0) -> 0.13354276 | F16: =IFERROR(F15/F6,0) -> 0.14306191 | G16: =IFERROR(G15/G6,0) -> 0.12997501 | H16: =IFERROR(H15/H6,0) -> 0.12738615 | I16: =IFERROR(I15/I6,0) -> 0.12937757 | J16: =IFERROR(J15/J6,0) -> 0.1380419 | ... L16: =IFERROR(L15/L6,0) -> 0.151592
B18: EBITDA | C18: =IFERROR(C12-C15,0) -> 2993.76 | D18: =IFERROR(D12-D15,0) -> 3204.01 | E18: =IFERROR(E12-E15,0) -> 3764.94 | F18: =IFERROR(F12-F15,0) -> 4161.77 | G18: =IFERROR(G12-G15,0) -> 4855.6 | H18: =IFERROR(H12-H15,0) -> 4803.61 | I18: =IFERROR(I12-I15,0) -> 6259.84 | J18: =IFERROR(J12-J15,0) -> 7584.98 | ... L18: =IFERROR(L12-L15,0) -> 6699.73
B19: EBITDA Margin | C19: =IFERROR(C18/C6,0) -> 0.19876258 | D19: =IFERROR(D18/D6,0) -> 0.19043659 | E19: =IFERROR(E18/E6,0) -> 0.19568163 | F19: =IFERROR(F18/F6,0) -> 0.20591354 | G19: =IFERROR(G18/G6,0) -> 0.22362856 | H19: =IFERROR(H18/H6,0) -> 0.16506525 | I19: =IFERROR(I18/I6,0) -> 0.18150467 | J19: =IFERROR(J18/J6,0) -> 0.21369313 | ... L19: =IFERROR(L18/L6,0) -> 0.18828172
B21: Other Income | C21: =IFERROR('Data Sheet'!B25,0) -> 337.9 | D21: =IFERROR('Data Sheet'!C25,0) -> 336.41 | E21: =IFERROR('Data Sheet'!D25,0) -> 273.77 | F21: =IFERROR('Data Sheet'!E25,0) -> 350.1 | G21: =IFERROR('Data Sheet'!F25,0) -> 331.65 | H21: =IFERROR('Data Sheet'!G25,0) -> 295.88 | I21: =IFERROR('Data Sheet'!H25,0) -> 431.46 | J21: =IFERROR('Data Sheet'!I25,0) -> 820.96 | ... L21: =IFERROR('Data Sheet'!K25,0) -> 727.97
B22: Other Income % of Sales | C22: =IFERROR(C21/C6,0) -> 0.022433955 | D22: =IFERROR(D21/D6,0) -> 0.019995186 | E22: =IFERROR(E21/E6,0) -> 0.014229114 | F22: =IFERROR(F21/F6,0) -> 0.017322036 | G22: =IFERROR(G21/G6,0) -> 0.015274407 | H22: =IFERROR(H21/H6,0) -> 0.01016725 | I22: =IFERROR(I21/I6,0) -> 0.012510224 | J22: =IFERROR(J21/J6,0) -> 0.023129067 | ... L22: =IFERROR(L21/L6,0) -> 0.020458054
B24: Depreciation | C24: =IFERROR('Data Sheet'!B26,0) -> 334.79 | D24: =IFERROR('Data Sheet'!C26,0) -> 360.47 | E24: =IFERROR('Data Sheet'!D26,0) -> 622.14 | F24: =IFERROR('Data Sheet'!E26,0) -> 780.5 | G24: =IFERROR('Data Sheet'!F26,0) -> 791.27 | H24: =IFERROR('Data Sheet'!G26,0) -> 816.36 | I24: =IFERROR('Data Sheet'!H26,0) -> 858.02 | J24: =IFERROR('Data Sheet'!I26,0) -> 853 | ... L24: =IFERROR('Data Sheet'!K26,0) -> 1228.85
B25: Depreciation % of Sales | C25: =IFERROR(C24/C6,0) -> 0.022227475 | D25: =IFERROR(D24/D6,0) -> 0.021425239 | E25: =IFERROR(E24/E6,0) -> 0.03233554 | F25: =IFERROR(F24/F6,0) -> 0.038617107 | G25: =IFERROR(G24/G6,0) -> 0.036442576 | H25: =IFERROR(H24/H6,0) -> 0.028052374 | I25: =IFERROR(I24/I6,0) -> 0.024878373 | J25: =IFERROR(J24/J6,0) -> 0.024031737 | ... L25: =IFERROR(L24/L6,0) -> 0.034534226
B27: EBIT | C27: =IFERROR(C18+C21-C24,0) -> 2996.87 | D27: =IFERROR(D18+D21-D24,0) -> 3179.95 | E27: =IFERROR(E18+E21-E24,0) -> 3416.57 | F27: =IFERROR(F18+F21-F24,0) -> 3731.37 | G27: =IFERROR(G18+G21-G24,0) -> 4395.98 | H27: =IFERROR(H18+H21-H24,0) -> 4283.13 | I27: =IFERROR(I18+I21-I24,0) -> 5833.28 | J27: =IFERROR(J18+J21-J24,0) -> 7552.94 | ... L27: =IFERROR(L18+L21-L24,0) -> 6198.85
B28: EBIT Margin | C28: =IFERROR(C27/C6,0) -> 0.19896906 | D28: =IFERROR(D27/D6,0) -> 0.18900654 | E28: =IFERROR(E27/E6,0) -> 0.1775752 | F28: =IFERROR(F27/F6,0) -> 0.18461847 | G28: =IFERROR(G27/G6,0) -> 0.20246039 | H28: =IFERROR(H27/H6,0) -> 0.14718012 | I28: =IFERROR(I27/I6,0) -> 0.16913652 | J28: =IFERROR(J27/J6,0) -> 0.21279046 | ... L28: =IFERROR(L27/L6,0) -> 0.17420555
B30: Interest | C30: =IFERROR('Data Sheet'!B27,0) -> 37.33 | D30: =IFERROR('Data Sheet'!C27,0) -> 41.47 | E30: =IFERROR('Data Sheet'!D27,0) -> 110.47 | F30: =IFERROR('Data Sheet'!E27,0) -> 102.33 | G30: =IFERROR('Data Sheet'!F27,0) -> 91.63 | H30: =IFERROR('Data Sheet'!G27,0) -> 95.41 | I30: =IFERROR('Data Sheet'!H27,0) -> 144.45 | J30: =IFERROR('Data Sheet'!I27,0) -> 205.17 | ... L30: =IFERROR('Data Sheet'!K27,0) -> 195.41
B31: Interest % of Sales | C31: =IFERROR(C30/C6,0) -> 0.0024784242 | D31: =IFERROR(D30/D6,0) -> 0.0024648505 | E31: =IFERROR(E30/E6,0) -> 0.0057416452 | F31: =IFERROR(F30/F6,0) -> 0.0050630218 | G31: =IFERROR(G30/G6,0) -> 0.0042200933 | H31: =IFERROR(H30/H6,0) -> 0.0032785499 | I31: =IFERROR(I30/I6,0) -> 0.0041883417 | J31: =IFERROR(J30/J6,0) -> 0.0057802947 | ... L31: =IFERROR(L30/L6,0) -> 0.005491584
B33: Earning Before Tax | C33: =IFERROR(C27-C30,0) -> 2959.54 | D33: =IFERROR(D27-D30,0) -> 3138.48 | E33: =IFERROR(E27-E30,0) -> 3306.1 | F33: =IFERROR(F27-F30,0) -> 3629.04 | G33: =IFERROR(G27-G30,0) -> 4304.35 | H33: =IFERROR(H27-H30,0) -> 4187.72 | I33: =IFERROR(I27-I30,0) -> 5688.83 | J33: =IFERROR(J27-J30,0) -> 7347.77 | ... L33: =IFERROR(L27-L30,0) -> 6003.44
B34: EBT % of Sales | C34: =IFERROR(C33/C6,0) -> 0.19649064 | D34: =IFERROR(D33/D6,0) -> 0.18654169 | E34: =IFERROR(E33/E6,0) -> 0.17183356 | F34: =IFERROR(F33/F6,0) -> 0.17955545 | G34: =IFERROR(G33/G6,0) -> 0.1982403 | H34: =IFERROR(H33/H6,0) -> 0.14390157 | I34: =IFERROR(I33/I6,0) -> 0.16494818 | J34: =IFERROR(J33/J6,0) -> 0.20701017 | ... L34: =IFERROR(L33/L6,0) -> 0.16871396
B36: Tax | C36: =IFERROR('Data Sheet'!B29,0) -> 943.29 | D36: =IFERROR('Data Sheet'!C29,0) -> 1040.96 | E36: =IFERROR('Data Sheet'!D29,0) -> 1098.06 | F36: =IFERROR('Data Sheet'!E29,0) -> 854.85 | G36: =IFERROR('Data Sheet'!F29,0) -> 1097.6 | H36: =IFERROR('Data Sheet'!G29,0) -> 1102.91 | I36: =IFERROR('Data Sheet'!H29,0) -> 1493.5 | J36: =IFERROR('Data Sheet'!I29,0) -> 1790.08 | ... L36: =IFERROR('Data Sheet'!K29,0) -> 1608.75
B37: Effective Tax Rate | C37: =IFERROR(C36/C33,0) -> 0.31872859 | D37: =IFERROR(D36/D33,0) -> 0.33167648 | E37: =IFERROR(E36/E33,0) -> 0.33213151 | F37: =IFERROR(F36/F33,0) -> 0.23555816 | G37: =IFERROR(G36/G33,0) -> 0.25499785 | H37: =IFERROR(H36/H33,0) -> 0.26336766 | I37: =IFERROR(I36/I33,0) -> 0.26253201 | J37: =IFERROR(J36/J33,0) -> 0.24362221 | ... L37: =IFERROR(L36/L33,0) -> 0.26797136
B39: Net Profit | C39: =IFERROR(C33-C36,0) -> 2016.25 | D39: =IFERROR(D33-D36,0) -> 2097.52 | E39: =IFERROR(E33-E36,0) -> 2208.04 | F39: =IFERROR(F33-F36,0) -> 2774.19 | G39: =IFERROR(G33-G36,0) -> 3206.75 | H39: =IFERROR(H33-H36,0) -> 3084.81 | I39: =IFERROR(I33-I36,0) -> 4195.33 | J39: =IFERROR(J33-J36,0) -> 5557.69 | ... L39: =IFERROR(L33-L36,0) -> 4394.69
B40: Net Profit Margin | C40: =IFERROR(C39/C6,0) -> 0.13386345 | D40: =IFERROR(D39/D6,0) -> 0.1246702 | E40: =IFERROR(E39/E6,0) -> 0.11476222 | F40: =IFERROR(F39/F6,0) -> 0.13725969 | G40: =IFERROR(G39/G6,0) -> 0.14768945 | H40: =IFERROR(H39/H6,0) -> 0.10600255 | I40: =IFERROR(I39/I6,0) -> 0.121644 | J40: =IFERROR(J39/J6,0) -> 0.15657789 | ... L40: =IFERROR(L39/L6,0) -> 0.12350345
B42: No of Equity Shares | C42: =IFERROR('Data Sheet'!B93,0) -> 95.92 | D42: =IFERROR('Data Sheet'!C93,0) -> 95.92 | E42: =IFERROR('Data Sheet'!D93,0) -> 95.92 | F42: =IFERROR('Data Sheet'!E93,0) -> 95.92 | G42: =IFERROR('Data Sheet'!F93,0) -> 95.92 | H42: =IFERROR('Data Sheet'!G93,0) -> 95.92 | I42: =IFERROR('Data Sheet'!H93,0) -> 95.92 | J42: =IFERROR('Data Sheet'!I93,0) -> 95.92 | ... L42: =IFERROR('Data Sheet'!K93,0) -> 95.92
B44: Earning Per Shares | C44: =IFERROR(C39/C42,0) -> 21.020121 | D44: =IFERROR(D39/D42,0) -> 21.867389 | E44: =IFERROR(E39/E42,0) -> 23.0196 | F44: =IFERROR(F39/F42,0) -> 28.921914 | G44: =IFERROR(G39/G42,0) -> 33.431505 | H44: =IFERROR(H39/H42,0) -> 32.160238 | I44: =IFERROR(I39/I42,0) -> 43.737802 | J44: =IFERROR(J39/J42,0) -> 57.940888 | ... L44: =IFERROR(L39/L42,0) -> 45.816201
B45: EPS Growth Rate | D45: =IFERROR(D44/C44-1,0) -> 0.040307502 | E45: =IFERROR(E44/D44-1,0) -> 0.052690797 | F45: =IFERROR(F44/E44-1,0) -> 0.25640387 | G45: =IFERROR(G44/F44-1,0) -> 0.15592299 | H45: =IFERROR(H44/G44-1,0) -> -0.038026039 | I45: =IFERROR(I44/H44-1,0) -> 0.35999624 | J45: =IFERROR(J44/I44-1,0) -> 0.3247325 | K45: =IFERROR(K44/J44-1,0) -> -0.33250865 | L45: =IFERROR(L44/K44-1,0) -> 0.18464516
B47: Dividend Per Shares | C47: =IFERROR('Data Sheet'!B31/HistoricalFS!C42,0) -> 10.300042 | D47: =IFERROR('Data Sheet'!C31/HistoricalFS!D42,0) -> 8.6999583 | E47: =IFERROR('Data Sheet'!D31/HistoricalFS!E42,0) -> 10.5 | F47: =IFERROR('Data Sheet'!E31/HistoricalFS!F42,0) -> 12 | G47: =IFERROR('Data Sheet'!F31/HistoricalFS!G42,0) -> 17.849979 | H47: =IFERROR('Data Sheet'!G31/HistoricalFS!H42,0) -> 19.150021 | I47: =IFERROR('Data Sheet'!H31/HistoricalFS!I42,0) -> 25.650021 | J47: =IFERROR('Data Sheet'!I31/HistoricalFS!J42,0) -> 33.300042 | ... L47: =IFERROR('Data Sheet'!K31/HistoricalFS!L42,0) -> 27.5
B48: Dividend Payout Ratio | C48: =IFERROR(C47/C44,0) -> 0.49000868 | D48: =IFERROR(D47/D44,0) -> 0.3978508 | E48: =IFERROR(E47/E44,0) -> 0.45613304 | F48: =IFERROR(F47/F44,0) -> 0.4149103 | G48: =IFERROR(G47/G44,0) -> 0.53392687 | H48: =IFERROR(H47/H44,0) -> 0.59545645 | I48: =IFERROR(I47/I44,0) -> 0.5864497 | J48: =IFERROR(J47/J44,0) -> 0.57472439 | ... L48: =IFERROR(L47/L44,0) -> 0.60022436
B50: Retained Earnings | C50: =IFERROR(IF(C44>C47,1-C48),0) -> 0.50999132 | D50: =IFERROR(IF(D44>D47,1-D48),0) -> 0.6021492 | E50: =IFERROR(IF(E44>E47,1-E48),0) -> 0.54386696 | F50: =IFERROR(IF(F44>F47,1-F48),0) -> 0.5850897 | G50: =IFERROR(IF(G44>G47,1-G48),0) -> 0.46607313 | H50: =IFERROR(IF(H44>H47,1-H48),0) -> 0.40454355 | I50: =IFERROR(IF(I44>I47,1-I48),0) -> 0.4135503 | J50: =IFERROR(IF(J44>J47,1-J48),0) -> 0.42527561 | ... L50: =IFERROR(IF(L44>L47,1-L48),0) -> 0.39977564
A52: # | B52: ="Balance Sheet"&" - "&'Data Sheet'!B1 -> Balance Sheet - ASIAN PAINTS LTD
B53: Equity Share Capital | C53: =IFERROR('Data Sheet'!B57,0) -> 95.92 | D53: =IFERROR('Data Sheet'!C57,0) -> 95.92 | E53: =IFERROR('Data Sheet'!D57,0) -> 95.92 | F53: =IFERROR('Data Sheet'!E57,0) -> 95.92 | G53: =IFERROR('Data Sheet'!F57,0) -> 95.92 | H53: =IFERROR('Data Sheet'!G57,0) -> 95.92 | I53: =IFERROR('Data Sheet'!H57,0) -> 95.92 | J53: =IFERROR('Data Sheet'!I57,0) -> 95.92 | ... L53: =IFERROR('Data Sheet'!K57,0) -> 95.92
B54: Reserves | C54: =IFERROR('Data Sheet'!B58,0) -> 7507.97 | D54: =IFERROR('Data Sheet'!C58,0) -> 8314.31 | E54: =IFERROR('Data Sheet'!D58,0) -> 9374.63 | F54: =IFERROR('Data Sheet'!E58,0) -> 10034.24 | G54: =IFERROR('Data Sheet'!F58,0) -> 12710.37 | H54: =IFERROR('Data Sheet'!G58,0) -> 13715.64 | I54: =IFERROR('Data Sheet'!H58,0) -> 15896.31 | J54: =IFERROR('Data Sheet'!I58,0) -> 18632.38 | ... L54: =IFERROR('Data Sheet'!K58,0) -> 21275.67
B55: Borrowings | C55: =IFERROR('Data Sheet'!B59,0) -> 560.34 | D55: =IFERROR('Data Sheet'!C59,0) -> 533.43 | E55: =IFERROR('Data Sheet'!D59,0) -> 1319.6 | F55: =IFERROR('Data Sheet'!E59,0) -> 1118.5 | G55: =IFERROR('Data Sheet'!F59,0) -> 1093.12 | H55: =IFERROR('Data Sheet'!G59,0) -> 1586.88 | I55: =IFERROR('Data Sheet'!H59,0) -> 1932.62 | J55: =IFERROR('Data Sheet'!I59,0) -> 2474.38 | ... L55: =IFERROR('Data Sheet'!K59,0) -> 3928.93
B56: Trade Payables | C56: =IFERROR('Data Sheet'!B74,0) -> 1923 | D56: =IFERROR('Data Sheet'!C74,0) -> 2160 | E56: =IFERROR('Data Sheet'!D74,0) -> 2394 | F56: =IFERROR('Data Sheet'!E74,0) -> 2137 | G56: =IFERROR('Data Sheet'!F74,0) -> 3379 | H56: =IFERROR('Data Sheet'!G74,0) -> 4164 | I56: =IFERROR('Data Sheet'!H74,0) -> 3635 | J56: =IFERROR('Data Sheet'!I74,0) -> 3831 | ... L56: =IFERROR('Data Sheet'!K74,0) -> 3863
B57: Other Liabilities | C57: =IFERROR('Data Sheet'!B60-'Data Sheet'!B74,0) -> 2317.96 | D57: =IFERROR('Data Sheet'!C60-'Data Sheet'!C74,0) -> 2659.82 | E57: =IFERROR('Data Sheet'!D60-'Data Sheet'!D74,0) -> 3064.69 | F57: =IFERROR('Data Sheet'!E60-'Data Sheet'!E74,0) -> 2752.31 | G57: =IFERROR('Data Sheet'!F60-'Data Sheet'!F74,0) -> 3076.93 | H57: =IFERROR('Data Sheet'!G60-'Data Sheet'!G74,0) -> 3395.99 | I57: =IFERROR('Data Sheet'!H60-'Data Sheet'!H74,0) -> 4219.48 | J57: =IFERROR('Data Sheet'!I60-'Data Sheet'!I74,0) -> 4867.09 | ... L57: =IFERROR('Data Sheet'!K60-'Data Sheet'!K74,0) -> 5355.23
B58: Total Liabilities | C58: =IFERROR(SUM(C53:C57),0) -> 12405.19 | D58: =IFERROR(SUM(D53:D57),0) -> 13763.48 | E58: =IFERROR(SUM(E53:E57),0) -> 16248.84 | F58: =IFERROR(SUM(F53:F57),0) -> 16137.97 | G58: =IFERROR(SUM(G53:G57),0) -> 20355.34 | H58: =IFERROR(SUM(H53:H57),0) -> 22958.43 | I58: =IFERROR(SUM(I53:I57),0) -> 25779.33 | J58: =IFERROR(SUM(J53:J57),0) -> 29900.77 | ... L58: =IFERROR(SUM(L53:L57),0) -> 34518.75
...

Sheet Ratio Analysis
B2: ='Data Sheet'!B1 -> ASIAN PAINTS LTD
B3: (ASIANPAINT | BSE Code: 500820)
B4: =CONCATENATE("INR "&'Data Sheet'!B8) -> INR 2645.2
B5: 52 Week (High - INR 2,985.7 & Low - 2115.0)
B8: ="Ratio Analysis"&" - "&'Data Sheet'!B1 -> Ratio Analysis - ASIAN PAINTS LTD
B9: Years | C9: =HistoricalFS!C3 -> 42825 | D9: =HistoricalFS!D3 -> 43190 | E9: =HistoricalFS!E3 -> 43555 | F9: =HistoricalFS!F3 -> 43921 | G9: =HistoricalFS!G3 -> 44286 | H9: =HistoricalFS!H3 -> 44651 | I9: =HistoricalFS!I3 -> 45016 | J9: =HistoricalFS!J3 -> 45382 | ... L9: =HistoricalFS!L3 -> 46112 | M9: Trend Line | N9: Mean | O9: Median
B11: Sales Growth | D11: =HistoricalFS!D6/HistoricalFS!C6-1 -> 0.11702039 | E11: =HistoricalFS!E6/HistoricalFS!D6-1 -> 0.14357472 | F11: =HistoricalFS!F6/HistoricalFS!E6-1 -> 0.050473671 | G11: =HistoricalFS!G6/HistoricalFS!F6-1 -> 0.074292288 | H11: =HistoricalFS!H6/HistoricalFS!G6-1 -> 0.34028285 | I11: =HistoricalFS!I6/HistoricalFS!H6-1 -> 0.18512278 | J11: =HistoricalFS!J6/HistoricalFS!I6-1 -> 0.029173127 | K11: =HistoricalFS!K6/HistoricalFS!J6-1 -> -0.044770308 | L11: =HistoricalFS!L6/HistoricalFS!K6-1 -> 0.049487961 | N11: =IFERROR(AVERAGE(D11:L11),0) -> 0.10496194 | O11: =IFERROR(MEDIAN(D11:L11),0) -> 0.074292288
B12: EBITDA Growth | D12: =HistoricalFS!D18/HistoricalFS!C18-1 -> 0.070229411 | E12: =HistoricalFS!E18/HistoricalFS!D18-1 -> 0.17507124 | F12: =HistoricalFS!F18/HistoricalFS!E18-1 -> 0.10540141 | G12: =HistoricalFS!G18/HistoricalFS!F18-1 -> 0.16671512 | H12: =HistoricalFS!H18/HistoricalFS!G18-1 -> -0.010707225 | I12: =HistoricalFS!I18/HistoricalFS!H18-1 -> 0.30315325 | J12: =HistoricalFS!J18/HistoricalFS!I18-1 -> 0.21168912 | K12: =HistoricalFS!K18/HistoricalFS!J18-1 -> -0.20814425 | L12: =HistoricalFS!L18/HistoricalFS!K18-1 -> 0.11546716 | N12: =IFERROR(AVERAGE(D12:L12),0) -> 0.10320836 | O12: =IFERROR(MEDIAN(D12:L12),0) -> 0.11546716
B13: EBIT Growth | D13: =HistoricalFS!D27/HistoricalFS!C27-1 -> 0.061090404 | E13: =HistoricalFS!E27/HistoricalFS!D27-1 -> 0.074409975 | F13: =HistoricalFS!F27/HistoricalFS!E27-1 -> 0.092139192 | G13: =HistoricalFS!G27/HistoricalFS!F27-1 -> 0.1781142 | H13: =HistoricalFS!H27/HistoricalFS!G27-1 -> -0.025671181 | I13: =HistoricalFS!I27/HistoricalFS!H27-1 -> 0.3619199 | J13: =HistoricalFS!J27/HistoricalFS!I27-1 -> 0.29480155 | K13: =HistoricalFS!K27/HistoricalFS!J27-1 -> -0.29430262 | L13: =HistoricalFS!L27/HistoricalFS!K27-1 -> 0.16299162 | N13: =IFERROR(AVERAGE(D13:L13),0) -> 0.10061034 | O13: =IFERROR(MEDIAN(D13:L13),0) -> 0.092139192
B14: Net Profit Growth | D14: =HistoricalFS!D39/HistoricalFS!C39-1 -> 0.040307502 | E14: =HistoricalFS!E39/HistoricalFS!D39-1 -> 0.052690797 | F14: =HistoricalFS!F39/HistoricalFS!E39-1 -> 0.25640387 | G14: =HistoricalFS!G39/HistoricalFS!F39-1 -> 0.15592299 | H14: =HistoricalFS!H39/HistoricalFS!G39-1 -> -0.038026039 | I14: =HistoricalFS!I39/HistoricalFS!H39-1 -> 0.35999624 | J14: =HistoricalFS!J39/HistoricalFS!I39-1 -> 0.3247325 | K14: =HistoricalFS!K39/HistoricalFS!J39-1 -> -0.33250865 | L14: =HistoricalFS!L39/HistoricalFS!K39-1 -> 0.18464516 | N14: =IFERROR(AVERAGE(D14:L14),0) -> 0.11157382 | O14: =IFERROR(MEDIAN(D14:L14),0) -> 0.15592299
B15: Dividend Growth | D15: =HistoricalFS!D47/HistoricalFS!C47-1 -> -0.15534727 | E15: =HistoricalFS!E47/HistoricalFS!D47-1 -> 0.20690234 | F15: =HistoricalFS!F47/HistoricalFS!E47-1 -> 0.14285714 | G15: =HistoricalFS!G47/HistoricalFS!F47-1 -> 0.48749826 | H15: =HistoricalFS!H47/HistoricalFS!G47-1 -> 0.072831553 | I15: =HistoricalFS!I47/HistoricalFS!H47-1 -> 0.33942522 | J15: =HistoricalFS!J47/HistoricalFS!I47-1 -> 0.29824618 | K15: =HistoricalFS!K47/HistoricalFS!J47-1 -> -0.25525494 | L15: =HistoricalFS!L47/HistoricalFS!K47-1 -> 0.1088691 | N15: =IFERROR(AVERAGE(D15:L15),0) -> 0.13844751 | O15: =IFERROR(MEDIAN(D15:L15),0) -> 0.14285714
B17: Gross Margin | C17: =HistoricalFS!C13 -> 0.35382642 | D17: =HistoricalFS!D13 -> 0.33465264 | E17: =HistoricalFS!E13 -> 0.32922439 | F17: =HistoricalFS!F13 -> 0.34897545 | G17: =HistoricalFS!G13 -> 0.35360357 | H17: =HistoricalFS!H13 -> 0.2924514 | I17: =HistoricalFS!I13 -> 0.31088224 | J17: =HistoricalFS!J13 -> 0.35173503 | ... L17: =HistoricalFS!L13 -> 0.33987372 | N17: =IFERROR(AVERAGE(C17:L17),0) -> 0.33445021 | O17: =IFERROR(MEDIAN(C17:L17),0) -> 0.33726318
B18: EBITDA Margin | C18: =HistoricalFS!C19 -> 0.19876258 | D18: =HistoricalFS!D19 -> 0.19043659 | E18: =HistoricalFS!E19 -> 0.19568163 | F18: =HistoricalFS!F19 -> 0.20591354 | G18: =HistoricalFS!G19 -> 0.22362856 | H18: =HistoricalFS!H19 -> 0.16506525 | I18: =HistoricalFS!I19 -> 0.18150467 | J18: =HistoricalFS!J19 -> 0.21369313 | ... L18: =HistoricalFS!L19 -> 0.18828172 | N18: =IFERROR(AVERAGE(C18:L18),0) -> 0.19401126 | O18: =IFERROR(MEDIAN(C18:L18),0) -> 0.19305911
B19: EBIT Margin | C19: =HistoricalFS!C28 -> 0.19896906 | D19: =HistoricalFS!D28 -> 0.18900654 | E19: =HistoricalFS!E28 -> 0.1775752 | F19: =HistoricalFS!F28 -> 0.18461847 | G19: =HistoricalFS!G28 -> 0.20246039 | H19: =HistoricalFS!H28 -> 0.14718012 | I19: =HistoricalFS!I28 -> 0.16913652 | J19: =HistoricalFS!J28 -> 0.21279046 | ... L19: =HistoricalFS!L28 -> 0.17420555 | N19: =IFERROR(AVERAGE(C19:L19),0) -> 0.1813146 | O19: =IFERROR(MEDIAN(C19:L19),0) -> 0.18109684
B20: EBT Margin | C20: =HistoricalFS!C34 -> 0.19649064 | D20: =HistoricalFS!D34 -> 0.18654169 | E20: =HistoricalFS!E34 -> 0.17183356 | F20: =HistoricalFS!F34 -> 0.17955545 | G20: =HistoricalFS!G34 -> 0.1982403 | H20: =HistoricalFS!H34 -> 0.14390157 | I20: =HistoricalFS!I34 -> 0.16494818 | J20: =HistoricalFS!J34 -> 0.20701017 | ... L20: =HistoricalFS!L34 -> 0.16871396 | N20: =IFERROR(AVERAGE(C20:L20),0) -> 0.17677436 | O20: =IFERROR(MEDIAN(C20:L20),0) -> 0.1756945
B21: Net Profit Margin | C21: =HistoricalFS!C40 -> 0.13386345 | D21: =HistoricalFS!D40 -> 0.1246702 | E21: =HistoricalFS!E40 -> 0.11476222 | F21: =HistoricalFS!F40 -> 0.13725969 | G21: =HistoricalFS!G40 -> 0.14768945 | H21: =HistoricalFS!H40 -> 0.10600255 | I21: =HistoricalFS!I40 -> 0.121644 | J21: =HistoricalFS!J40 -> 0.15657789 | ... L21: =HistoricalFS!L40 -> 0.12350345 | N21: =IFERROR(AVERAGE(C21:L21),0) -> 0.12753857 | O21: =IFERROR(MEDIAN(C21:L21),0) -> 0.12408683
B23: Sales Exp % Sales | C23: =HistoricalFS!C16 -> 0.15506384 | D23: =HistoricalFS!D16 -> 0.14421604 | E23: =HistoricalFS!E16 -> 0.13354276 | F23: =HistoricalFS!F16 -> 0.14306191 | G23: =HistoricalFS!G16 -> 0.12997501 | H23: =HistoricalFS!H16 -> 0.12738615 | I23: =HistoricalFS!I16 -> 0.12937757 | J23: =HistoricalFS!J16 -> 0.1380419 | ... L23: =HistoricalFS!L16 -> 0.151592 | N23: =IFERROR(AVERAGE(C23:L23),0) -> 0.14043895 | O23: =IFERROR(MEDIAN(C23:L23),0) -> 0.1405519
B24: Depreciation % Sales | C24: =HistoricalFS!C25 -> 0.022227475 | D24: =HistoricalFS!D25 -> 0.021425239 | E24: =HistoricalFS!E25 -> 0.03233554 | F24: =HistoricalFS!F25 -> 0.038617107 | G24: =HistoricalFS!G25 -> 0.036442576 | H24: =HistoricalFS!H25 -> 0.028052374 | I24: =HistoricalFS!I25 -> 0.024878373 | J24: =HistoricalFS!J25 -> 0.024031737 | ... L24: =HistoricalFS!L25 -> 0.034534226 | N24: =IFERROR(AVERAGE(C24:L24),0) -> 0.029281514 | O24: =IFERROR(MEDIAN(C24:L24),0) -> 0.029161436
B25: Operating Income % Sales | C25: =C19 -> 0.19896906 | D25: =D19 -> 0.18900654 | E25: =E19 -> 0.1775752 | F25: =F19 -> 0.18461847 | G25: =G19 -> 0.20246039 | H25: =H19 -> 0.14718012 | I25: =I19 -> 0.16913652 | J25: =J19 -> 0.21279046 | ... L25: =L19 -> 0.17420555 | N25: =IFERROR(AVERAGE(C25:L25),0) -> 0.1813146 | O25: =IFERROR(MEDIAN(C25:L25),0) -> 0.18109684
B27: Return on Capital Employed | C27: =HistoricalFS!C27/SUM(HistoricalFS!C53:C55) -> 0.3670732 | D27: =HistoricalFS!D27/SUM(HistoricalFS!D53:D55) -> 0.35555354 | E27: =HistoricalFS!E27/SUM(HistoricalFS!E53:E55) -> 0.31663786 | F27: =HistoricalFS!F27/SUM(HistoricalFS!F53:F55) -> 0.33171684 | G27: =HistoricalFS!G27/SUM(HistoricalFS!G53:G55) -> 0.31627098 | H27: =HistoricalFS!H27/SUM(HistoricalFS!H53:H55) -> 0.2781535 | I27: =HistoricalFS!I27/SUM(HistoricalFS!I53:I55) -> 0.32542978 | J27: =HistoricalFS!J27/SUM(HistoricalFS!J53:J55) -> 0.35622572 | ... L27: =HistoricalFS!L27/SUM(HistoricalFS!L53:L55) -> 0.2450088 | N27: =IFERROR(AVERAGE(C27:L27),0) -> 0.31378086 | O27: =IFERROR(MEDIAN(C27:L27),0) -> 0.32103382
B28: Retained Earning % | C28: =HistoricalFS!C50 -> 0.50999132 | D28: =HistoricalFS!D50 -> 0.6021492 | E28: =HistoricalFS!E50 -> 0.54386696 | F28: =HistoricalFS!F50 -> 0.5850897 | G28: =HistoricalFS!G50 -> 0.46607313 | H28: =HistoricalFS!H50 -> 0.40454355 | I28: =HistoricalFS!I50 -> 0.4135503 | J28: =HistoricalFS!J50 -> 0.42527561 | ... L28: =HistoricalFS!L50 -> 0.39977564 | N28: =IFERROR(AVERAGE(C28:L28),0) -> 0.47090739 | O28: =IFERROR(MEDIAN(C28:L28),0) -> 0.44567437
B29: Return on Equity % | C29: =HistoricalFS!C39/SUM(HistoricalFS!C53:C54) -> 0.26516033 | D29: =HistoricalFS!D39/SUM(HistoricalFS!D53:D54) -> 0.24940103 | E29: =HistoricalFS!E39/SUM(HistoricalFS!E53:E54) -> 0.23314802 | F29: =HistoricalFS!F39/SUM(HistoricalFS!F53:F54) -> 0.27385451 | G29: =HistoricalFS!G39/SUM(HistoricalFS!G53:G54) -> 0.25040429 | H29: =HistoricalFS!H39/SUM(HistoricalFS!H53:H54) -> 0.22334986 | I29: =HistoricalFS!I39/SUM(HistoricalFS!I53:I54) -> 0.26233552 | J29: =HistoricalFS!J39/SUM(HistoricalFS!J53:J54) -> 0.29675358 | ... L29: =HistoricalFS!L39/SUM(HistoricalFS!L53:L54) -> 0.20563234 | N29: =IFERROR(AVERAGE(C29:L29),0) -> 0.24512635 | O29: =IFERROR(MEDIAN(C29:L29),0) -> 0.24990266
B30: Self Sustained Growth Rate | C30: =C29*C28 -> 0.13522947 | D30: =D29*D28 -> 0.15017663 | E30: =E29*E28 -> 0.12680151 | F30: =F29*F28 -> 0.16022945 | G30: =G29*G28 -> 0.11670671 | H30: =H29*H28 -> 0.090354746 | I30: =I29*I28 -> 0.10848893 | J30: =J29*J28 -> 0.12620206 | ... L30: =L29*L28 -> 0.082206799 | N30: =IFERROR(AVERAGE(C30:L30),0) -> 0.11649996 | O30: =IFERROR(MEDIAN(C30:L30),0) -> 0.12145438
B31: Interest Coverage Ratio | C31: =HistoricalFS!C27/HistoricalFS!C30 -> 80.280471 | D31: =HistoricalFS!D27/HistoricalFS!D30 -> 76.680733 | E31: =HistoricalFS!E27/HistoricalFS!E30 -> 30.927582 | F31: =HistoricalFS!F27/HistoricalFS!F30 -> 36.464087 | G31: =HistoricalFS!G27/HistoricalFS!G30 -> 47.975336 | H31: =HistoricalFS!H27/HistoricalFS!H30 -> 44.891835 | I31: =HistoricalFS!I27/HistoricalFS!I30 -> 40.382693 | J31: =HistoricalFS!J27/HistoricalFS!J30 -> 36.813082 | ... L31: =HistoricalFS!L27/HistoricalFS!L30 -> 31.722276 | N31: =IFERROR(AVERAGE(C31:L31),0) -> 44.96166 | O31: =IFERROR(MEDIAN(C31:L31),0) -> 38.597887
B33: Debtor Turnover Ratio | C33: =HistoricalFS!C6/HistoricalFS!C66 -> 10.411994 | D33: =HistoricalFS!D6/HistoricalFS!D66 -> 9.7216332 | E33: =HistoricalFS!E6/HistoricalFS!E66 -> 10.087468 | F33: =HistoricalFS!F6/HistoricalFS!F66 -> 11.258369 | G33: =HistoricalFS!G6/HistoricalFS!G66 -> 8.344109 | H33: =HistoricalFS!H6/HistoricalFS!H66 -> 7.5169136 | I33: =HistoricalFS!I6/HistoricalFS!I66 -> 7.4377909 | J33: =HistoricalFS!J6/HistoricalFS!J66 -> 7.2600464 | ... L33: =HistoricalFS!L6/HistoricalFS!L66 -> 7.9751535 | N33: =IFERROR(AVERAGE(C33:L33),0) -> 8.7873554 | O33: =IFERROR(MEDIAN(C33:L33),0) -> 8.1596312
B34: Creditor Turnover Ratio | C34: =HistoricalFS!C6/HistoricalFS!C57 -> 6.4979508 | D34: =HistoricalFS!D6/HistoricalFS!D57 -> 6.3254468 | E34: =HistoricalFS!E6/HistoricalFS!E57 -> 6.278002 | F34: =HistoricalFS!F6/HistoricalFS!F57 -> 7.343377 | G34: =HistoricalFS!G6/HistoricalFS!G57 -> 7.0566409 | H34: =HistoricalFS!H6/HistoricalFS!H57 -> 8.5693067 | I34: =HistoricalFS!I6/HistoricalFS!I57 -> 8.1736588 | J34: =HistoricalFS!J6/HistoricalFS!J57 -> 7.2928033 | ... L34: =HistoricalFS!L6/HistoricalFS!L57 -> 6.6446334 | N34: =IFERROR(AVERAGE(C34:L34),0) -> 7.1220343 | O34: =IFERROR(MEDIAN(C34:L34),0) -> 7.0475818
B35: Inventory Turnover Ratio | C35: =HistoricalFS!C6/HistoricalFS!C67 -> 5.7336635 | D35: =HistoricalFS!D6/HistoricalFS!D67 -> 6.3290399 | E35: =HistoricalFS!E6/HistoricalFS!E67 -> 6.1082493 | F35: =HistoricalFS!F6/HistoricalFS!F67 -> 5.9623548 | G35: =HistoricalFS!G6/HistoricalFS!G67 -> 5.715998 | H35: =HistoricalFS!H6/HistoricalFS!H67 -> 4.7296237 | I35: =HistoricalFS!I6/HistoricalFS!I67 -> 5.5531459 | J35: =HistoricalFS!J6/HistoricalFS!J67 -> 5.9922798 | ... L35: =HistoricalFS!L6/HistoricalFS!L67 -> 6.1952403 | N35: =IFERROR(AVERAGE(C35:L35),0) -> 5.7365622 | O35: =IFERROR(MEDIAN(C35:L35),0) -> 5.8480092
B36: Fixed Asset Turnover | C36: =HistoricalFS!C6/HistoricalFS!C60 -> 4.5590724 | D36: =HistoricalFS!D6/HistoricalFS!D60 -> 4.5078961 | E36: =HistoricalFS!E6/HistoricalFS!E60 -> 2.9615874 | F36: =HistoricalFS!F6/HistoricalFS!F60 -> 3.2222977 | G36: =HistoricalFS!G6/HistoricalFS!G60 -> 3.7061903 | H36: =HistoricalFS!H6/HistoricalFS!H60 -> 5.2728689 | I36: =HistoricalFS!I6/HistoricalFS!I60 -> 5.9767488 | J36: =HistoricalFS!J6/HistoricalFS!J60 -> 4.9666458 | ... L36: =HistoricalFS!L6/HistoricalFS!L60 -> 3.6911314 | N36: =IFERROR(AVERAGE(C36:L36),0) -> 4.2541798 | O36: =IFERROR(MEDIAN(C36:L36),0) -> 4.1070432
B37: Capital Turnover Ratio | C37: =HistoricalFS!C6/SUM(HistoricalFS!C53:C54) -> 1.9808269 | D37: =HistoricalFS!D6/SUM(HistoricalFS!D53:D54) -> 2.0004863 | E37: =HistoricalFS!E6/SUM(HistoricalFS!E53:E54) -> 2.0315747 | F37: =HistoricalFS!F6/SUM(HistoricalFS!F53:F54) -> 1.995156 | G37: =HistoricalFS!G6/SUM(HistoricalFS!G53:G54) -> 1.6954785 | H37: =HistoricalFS!H6/SUM(HistoricalFS!H53:H54) -> 2.1070234 | I37: =HistoricalFS!I6/SUM(HistoricalFS!I53:I54) -> 2.1565842 | J37: =HistoricalFS!J6/SUM(HistoricalFS!J53:J54) -> 1.8952457 | ... L37: =HistoricalFS!L6/SUM(HistoricalFS!L53:L54) -> 1.6649926 | N37: =IFERROR(AVERAGE(C37:L37),0) -> 1.9275098 | O37: =IFERROR(MEDIAN(C37:L37),0) -> 1.9879915
B39: Debtor Days | C39: =(365/C33) -> 35.055726 | D39: =(365/D33) -> 37.545132 | E39: =(365/E33) -> 36.183511 | F39: =(365/F33) -> 32.420325 | G39: =(365/G33) -> 43.743436 | H39: =(365/H33) -> 48.557163 | I39: =(365/I33) -> 49.073711 | J39: =(365/J33) -> 50.275161 | ... L39: =(365/L33) -> 45.767144 | N39: =IFERROR(AVERAGE(C39:L39),0) -> 42.505852 | O39: =IFERROR(MEDIAN(C39:L39),0) -> 44.75529
B40: Payable Days | C40: =365/C34 -> 56.171555 | D40: =365/D34 -> 57.703433 | E40: =365/E34 -> 58.139516 | F40: =365/F34 -> 49.704652 | G40: =365/G34 -> 51.724327 | H40: =365/H34 -> 42.593877 | I40: =365/I34 -> 44.655644 | J40: =365/J34 -> 50.049341 | ... L40: =365/L34 -> 54.931548 | N40: =IFERROR(AVERAGE(C40:L40),0) -> 51.753137 | O40: =IFERROR(MEDIAN(C40:L40),0) -> 51.7909
B41: Inventory Days | C41: =365/C35 -> 63.659125 | D41: =365/D35 -> 57.670675 | E41: =365/E35 -> 59.755256 | F41: =365/F35 -> 61.217423 | G41: =365/G35 -> 63.855866 | H41: =365/H35 -> 77.173159 | I41: =365/I35 -> 65.728509 | J41: =365/J35 -> 60.911709 | ... L41: =365/L35 -> 58.916197 | N41: =IFERROR(AVERAGE(C41:L41),0) -> 64.122205 | O41: =IFERROR(MEDIAN(C41:L41),0) -> 62.438274
B42: Cash Conversion Cycle | C42: =SUM(C39+C41-C40) -> 42.543296 | D42: =SUM(D39+D41-D40) -> 37.512373 | E42: =SUM(E39+E41-E40) -> 37.799251 | F42: =SUM(F39+F41-F40) -> 43.933097 | G42: =SUM(G39+G41-G40) -> 55.874975 | H42: =SUM(H39+H41-H40) -> 83.136445 | I42: =SUM(I39+I41-I40) -> 70.146576 | J42: =SUM(J39+J41-J40) -> 61.137528 | ... L42: =SUM(L39+L41-L40) -> 49.751793 | N42: =IFERROR(AVERAGE(C42:L42),0) -> 54.87492 | O42: =IFERROR(MEDIAN(C42:L42),0) -> 52.813384
B44: CFO/Sales | C44: =HistoricalFS!C84/HistoricalFS!C6 -> 0.10144742 | D44: =HistoricalFS!D84/HistoricalFS!D6 -> 0.12559028 | E44: =HistoricalFS!E84/HistoricalFS!E6 -> 0.12832554 | F44: =HistoricalFS!F84/HistoricalFS!F6 -> 0.15031233 | G44: =HistoricalFS!G84/HistoricalFS!G6 -> 0.16966958 | H44: =HistoricalFS!H84/HistoricalFS!H6 -> 0.033881671 | I44: =HistoricalFS!I84/HistoricalFS!I6 -> 0.12160544 | J44: =HistoricalFS!J84/HistoricalFS!J6 -> 0.17196919 | ... L44: =HistoricalFS!L84/HistoricalFS!L6 -> 0.19919322 | N44: =IFERROR(AVERAGE(C44:L44),0) -> 0.13324745 | O44: =IFERROR(MEDIAN(C44:L44),0) -> 0.12940269
B45: CFO/Total Assets | C45: =HistoricalFS!C84/HistoricalFS!C71 -> 0.12317425 | D45: =HistoricalFS!D84/HistoricalFS!D71 -> 0.15352222 | E45: =HistoricalFS!E84/HistoricalFS!E71 -> 0.15194931 | F45: =HistoricalFS!F84/HistoricalFS!F71 -> 0.18825168 | G45: =HistoricalFS!G84/HistoricalFS!G71 -> 0.18098445 | H45: =HistoricalFS!H84/HistoricalFS!H71 -> 0.042947188 | I45: =HistoricalFS!I84/HistoricalFS!I71 -> 0.16268848 | J45: =HistoricalFS!J84/HistoricalFS!J71 -> 0.2041419 | ... L45: =HistoricalFS!L84/HistoricalFS!L71 -> 0.20533768 | N45: =IFERROR(AVERAGE(C45:L45),0) -> 0.1558738 | O45: =IFERROR(MEDIAN(C45:L45),0) -> 0.15810535
B46: CFO/Total Debt | C46: =HistoricalFS!C84/HistoricalFS!C55 -> 2.7269158 | D46: =HistoricalFS!D84/HistoricalFS!D55 -> 3.961157 | E46: =HistoricalFS!E84/HistoricalFS!E55 -> 1.8710215 | F46: =HistoricalFS!F84/HistoricalFS!F55 -> 2.7161377 | G46: =HistoricalFS!G84/HistoricalFS!G55 -> 3.3701698 | H46: =HistoricalFS!H84/HistoricalFS!H55 -> 0.62134503 | I46: =HistoricalFS!I84/HistoricalFS!I55 -> 2.170111 | J46: =HistoricalFS!J84/HistoricalFS!J55 -> 2.4668806 | ... L46: =HistoricalFS!L84/HistoricalFS!L55 -> 1.8040535 | N46: =IFERROR(AVERAGE(C46:L46),0) -> 2.3639425 | O46: =IFERROR(MEDIAN(C46:L46),0) -> 2.3184958

Sheet Common Size Statement
B2: ='Data Sheet'!B1 -> ASIAN PAINTS LTD
B3: (ASIANPAINT | BSE Code: 500820)
B4: =CONCATENATE("INR "&'Data Sheet'!B8) -> INR 2645.2
B5: 52 Week (High - INR 2,985.7 & Low - 2115.0)
B8: ="Common Size Income Statement"&" - "&'Data Sheet'!B1 -> Common Size Income Statement - ASIAN PAINTS LTD
B10: Particulars | C10: ='Data Sheet'!B16 -> 42825 | D10: ='Data Sheet'!C16 -> 43190 | E10: ='Data Sheet'!D16 -> 43555 | F10: ='Data Sheet'!E16 -> 43921 | G10: ='Data Sheet'!F16 -> 44286 | H10: ='Data Sheet'!G16 -> 44651 | I10: ='Data Sheet'!H16 -> 45016 | J10: ='Data Sheet'!I16 -> 45382 | ... L10: ='Data Sheet'!K16 -> 46112
B12: Sales | C12: ='Data Sheet'!B17/'Data Sheet'!B$17 -> 1 | D12: ='Data Sheet'!C17/'Data Sheet'!C$17 -> 1 | E12: ='Data Sheet'!D17/'Data Sheet'!D$17 -> 1 | F12: ='Data Sheet'!E17/'Data Sheet'!E$17 -> 1 | G12: ='Data Sheet'!F17/'Data Sheet'!F$17 -> 1 | H12: ='Data Sheet'!G17/'Data Sheet'!G$17 -> 1 | I12: ='Data Sheet'!H17/'Data Sheet'!H$17 -> 1 | J12: ='Data Sheet'!I17/'Data Sheet'!I$17 -> 1 | ... L12: ='Data Sheet'!K17/'Data Sheet'!K$17 -> 1
B13: Raw Material Cost | C13: ='Data Sheet'!B18/'Data Sheet'!B$17 -> 0.49479518 | D13: ='Data Sheet'!C18/'Data Sheet'!C$17 -> 0.48311366 | E13: ='Data Sheet'!D18/'Data Sheet'!D$17 -> 0.51841646 | F13: ='Data Sheet'!E18/'Data Sheet'!E$17 -> 0.49388286 | G13: ='Data Sheet'!F18/'Data Sheet'!F$17 -> 0.48015709 | H13: ='Data Sheet'!G18/'Data Sheet'!G$17 -> 0.58840195 | I13: ='Data Sheet'!H18/'Data Sheet'!H$17 -> 0.55048728 | J13: ='Data Sheet'!I18/'Data Sheet'!I$17 -> 0.49051902 | ... L13: ='Data Sheet'!K18/'Data Sheet'!K$17 -> 0.48173987
B14: Change in Inventory | C14: ='Data Sheet'!B19/'Data Sheet'!B$17 -> 0.035094964 | D14: ='Data Sheet'!C19/'Data Sheet'!C$17 -> -0.0084477742 | E14: ='Data Sheet'!D19/'Data Sheet'!D$17 -> 0.015242101 | F14: ='Data Sheet'!E19/'Data Sheet'!E$17 -> 0.011832519 | G14: ='Data Sheet'!F19/'Data Sheet'!F$17 -> 0.0042578591 | H14: ='Data Sheet'!G19/'Data Sheet'!G$17 -> 0.045529612 | I14: ='Data Sheet'!H19/'Data Sheet'!H$17 -> 0.0089806513 | J14: ='Data Sheet'!I19/'Data Sheet'!I$17 -> -0.010249409 | ... L14: ='Data Sheet'!K19/'Data Sheet'!K$17 -> -0.016965147
B15: Power and Fuel | C15: ='Data Sheet'!B20/'Data Sheet'!B$17 -> 0.0070389105 | D15: ='Data Sheet'!C20/'Data Sheet'!C$17 -> 0.006555896 | E15: ='Data Sheet'!D20/'Data Sheet'!D$17 -> 0.0062177335 | F15: ='Data Sheet'!E20/'Data Sheet'!E$17 -> 0.0048383945 | G15: ='Data Sheet'!F20/'Data Sheet'!F$17 -> 0.0039631019 | H15: ='Data Sheet'!G20/'Data Sheet'!G$17 -> 0.0040283451 | I15: ='Data Sheet'!H20/'Data Sheet'!H$17 -> 0.0040097319 | J15: ='Data Sheet'!I20/'Data Sheet'!I$17 -> 0.0037540784 | ... L15: ='Data Sheet'!K20/'Data Sheet'!K$17 -> 0.0046959915
B16: Other Mfr. Exp | C16: ='Data Sheet'!B21/'Data Sheet'!B$17 -> 0.11039378 | D16: ='Data Sheet'!C21/'Data Sheet'!C$17 -> 0.10054831 | E16: ='Data Sheet'!D21/'Data Sheet'!D$17 -> 0.096795084 | F16: ='Data Sheet'!E21/'Data Sheet'!E$17 -> 0.096288948 | G16: ='Data Sheet'!F21/'Data Sheet'!F$17 -> 0.09525768 | H16: ='Data Sheet'!G21/'Data Sheet'!G$17 -> 0.098980182 | I16: ='Data Sheet'!H21/'Data Sheet'!H$17 -> 0.084555501 | J16: ='Data Sheet'!I21/'Data Sheet'!I$17 -> 0.077960306 | ... L16: ='Data Sheet'!K21/'Data Sheet'!K$17 -> 0.077763764
B17: Employee Cost | C17: ='Data Sheet'!B22/'Data Sheet'!B$17 -> 0.069040678 | D17: ='Data Sheet'!C22/'Data Sheet'!C$17 -> 0.066681724 | E17: ='Data Sheet'!D22/'Data Sheet'!D$17 -> 0.064588441 | F17: ='Data Sheet'!E22/'Data Sheet'!E$17 -> 0.067846867 | G17: ='Data Sheet'!F22/'Data Sheet'!F$17 -> 0.071276423 | H17: ='Data Sheet'!G22/'Data Sheet'!G$17 -> 0.061667734 | I17: ='Data Sheet'!H22/'Data Sheet'!H$17 -> 0.059045905 | J17: ='Data Sheet'!I22/'Data Sheet'!I$17 -> 0.06578216 | ... L17: ='Data Sheet'!K22/'Data Sheet'!K$17 -> 0.078961509
B18: Selling and admin | C18: ='Data Sheet'!B23/'Data Sheet'!B$17 -> 0.28973861 | D18: ='Data Sheet'!C23/'Data Sheet'!C$17 -> 0.13402558 | E18: ='Data Sheet'!D23/'Data Sheet'!D$17 -> 0.12301736 | F18: ='Data Sheet'!E23/'Data Sheet'!E$17 -> 0.11436749 | G18: ='Data Sheet'!F23/'Data Sheet'!F$17 -> 0.10342706 | H18: ='Data Sheet'!G23/'Data Sheet'!G$17 -> 0.10109452 | I18: ='Data Sheet'!H23/'Data Sheet'!H$17 -> 0.10150719 | J18: ='Data Sheet'!I23/'Data Sheet'!I$17 -> 0.10739228 | ... L18: ='Data Sheet'!K23/'Data Sheet'!K$17 -> 0.11556102
B19: Other Expenses | C19: ='Data Sheet'!B24/'Data Sheet'!B$17 -> -0.13467477 | D19: ='Data Sheet'!C24/'Data Sheet'!C$17 -> 0.010190466 | E19: ='Data Sheet'!D24/'Data Sheet'!D$17 -> 0.010525397 | F19: ='Data Sheet'!E24/'Data Sheet'!E$17 -> 0.028694415 | G19: ='Data Sheet'!F24/'Data Sheet'!F$17 -> 0.026547947 | H19: ='Data Sheet'!G24/'Data Sheet'!G$17 -> 0.026291627 | I19: ='Data Sheet'!H24/'Data Sheet'!H$17 -> 0.027870377 | J19: ='Data Sheet'!I24/'Data Sheet'!I$17 -> 0.03064962 | ... L19: ='Data Sheet'!K24/'Data Sheet'!K$17 -> 0.036030985
B20: Other Income | C20: ='Data Sheet'!B25/'Data Sheet'!B$17 -> 0.022433955 | D20: ='Data Sheet'!C25/'Data Sheet'!C$17 -> 0.019995186 | E20: ='Data Sheet'!D25/'Data Sheet'!D$17 -> 0.014229114 | F20: ='Data Sheet'!E25/'Data Sheet'!E$17 -> 0.017322036 | G20: ='Data Sheet'!F25/'Data Sheet'!F$17 -> 0.015274407 | H20: ='Data Sheet'!G25/'Data Sheet'!G$17 -> 0.01016725 | I20: ='Data Sheet'!H25/'Data Sheet'!H$17 -> 0.012510224 | J20: ='Data Sheet'!I25/'Data Sheet'!I$17 -> 0.023129067 | ... L20: ='Data Sheet'!K25/'Data Sheet'!K$17 -> 0.020458054
B21: Depreciation | C21: ='Data Sheet'!B26/'Data Sheet'!B$17 -> 0.022227475 | D21: ='Data Sheet'!C26/'Data Sheet'!C$17 -> 0.021425239 | E21: ='Data Sheet'!D26/'Data Sheet'!D$17 -> 0.03233554 | F21: ='Data Sheet'!E26/'Data Sheet'!E$17 -> 0.038617107 | G21: ='Data Sheet'!F26/'Data Sheet'!F$17 -> 0.036442576 | H21: ='Data Sheet'!G26/'Data Sheet'!G$17 -> 0.028052374 | I21: ='Data Sheet'!H26/'Data Sheet'!H$17 -> 0.024878373 | J21: ='Data Sheet'!I26/'Data Sheet'!I$17 -> 0.024031737 | ... L21: ='Data Sheet'!K26/'Data Sheet'!K$17 -> 0.034534226
B22: Interest | C22: ='Data Sheet'!B27/'Data Sheet'!B$17 -> 0.0024784242 | D22: ='Data Sheet'!C27/'Data Sheet'!C$17 -> 0.0024648505 | E22: ='Data Sheet'!D27/'Data Sheet'!D$17 -> 0.0057416452 | F22: ='Data Sheet'!E27/'Data Sheet'!E$17 -> 0.0050630218 | G22: ='Data Sheet'!F27/'Data Sheet'!F$17 -> 0.0042200933 | H22: ='Data Sheet'!G27/'Data Sheet'!G$17 -> 0.0032785499 | I22: ='Data Sheet'!H27/'Data Sheet'!H$17 -> 0.0041883417 | J22: ='Data Sheet'!I27/'Data Sheet'!I$17 -> 0.0057802947 | ... L22: ='Data Sheet'!K27/'Data Sheet'!K$17 -> 0.005491584
B23: Profit before tax | C23: ='Data Sheet'!B28/'Data Sheet'!B$17 -> 0.19649064 | D23: ='Data Sheet'!C28/'Data Sheet'!C$17 -> 0.18654169 | E23: ='Data Sheet'!D28/'Data Sheet'!D$17 -> 0.17183356 | F23: ='Data Sheet'!E28/'Data Sheet'!E$17 -> 0.17955545 | G23: ='Data Sheet'!F28/'Data Sheet'!F$17 -> 0.1982403 | H23: ='Data Sheet'!G28/'Data Sheet'!G$17 -> 0.14390157 | I23: ='Data Sheet'!H28/'Data Sheet'!H$17 -> 0.16494818 | J23: ='Data Sheet'!I28/'Data Sheet'!I$17 -> 0.20701017 | ... L23: ='Data Sheet'!K28/'Data Sheet'!K$17 -> 0.16871396
... B26: Dividend Amount | C26: ='Data Sheet'!B31/'Data Sheet'!B$17 -> 0.065594254 | D26: ='Data Sheet'!C31/'Data Sheet'!C$17 -> 0.049600138 | E26: ='Data Sheet'!D31/'Data Sheet'!D$17 -> 0.05234684 | F26: ='Data Sheet'!E31/'Data Sheet'!E$17 -> 0.056950461 | G26: ='Data Sheet'!F31/'Data Sheet'!F$17 -> 0.078855366 | H26: ='Data Sheet'!G31/'Data Sheet'!G$17 -> 0.063119904 | I26: ='Data Sheet'!H31/'Data Sheet'!H$17 -> 0.071338086 | J26: ='Data Sheet'!I31/'Data Sheet'!I$17 -> 0.089989134 | ... L26: ='Data Sheet'!K31/'Data Sheet'!K$17 -> 0.07412978
B27: EBITDA | C27: =HistoricalFS!C18/'Data Sheet'!B$17 -> 0.19876258 | D27: =HistoricalFS!D18/'Data Sheet'!C$17 -> 0.19043659 | E27: =HistoricalFS!E18/'Data Sheet'!D$17 -> 0.19568163 | F27: =HistoricalFS!F18/'Data Sheet'!E$17 -> 0.20591354 | G27: =HistoricalFS!G18/'Data Sheet'!F$17 -> 0.22362856 | H27: =HistoricalFS!H18/'Data Sheet'!G$17 -> 0.16506525 | I27: =HistoricalFS!I18/'Data Sheet'!H$17 -> 0.18150467 | J27: =HistoricalFS!J18/'Data Sheet'!I$17 -> 0.21369313 | ... L27: =HistoricalFS!L18/'Data Sheet'!K$17 -> 0.18828172
B29: ="Common Size Balance Sheet"&" - "&'Data Sheet'!B1 -> Common Size Balance Sheet - ASIAN PAINTS LTD
B31: Particulars | C31: =C10 -> 42825 | D31: =D10 -> 43190 | E31: =E10 -> 43555 | F31: =F10 -> 43921 | G31: =G10 -> 44286 | H31: =H10 -> 44651 | I31: =I10 -> 45016 | J31: =J10 -> 45382 | ... L31: =L10 -> 46112
B33: Total Liabilities | C33: ='Data Sheet'!B61/'Data Sheet'!B$61 -> 1 | D33: ='Data Sheet'!C61/'Data Sheet'!C$61 -> 1 | E33: ='Data Sheet'!D61/'Data Sheet'!D$61 -> 1 | F33: ='Data Sheet'!E61/'Data Sheet'!E$61 -> 1 | G33: ='Data Sheet'!F61/'Data Sheet'!F$61 -> 1 | H33: ='Data Sheet'!G61/'Data Sheet'!G$61 -> 1 | I33: ='Data Sheet'!H61/'Data Sheet'!H$61 -> 1 | J33: ='Data Sheet'!I61/'Data Sheet'!I$61 -> 1 | ... L33: ='Data Sheet'!K61/'Data Sheet'!K$61 -> 1
B34: Equity Share Capital | C34: ='Data Sheet'!B57/'Data Sheet'!B$61 -> 0.0077322476 | D34: ='Data Sheet'!C57/'Data Sheet'!C$61 -> 0.0069691677 | E34: ='Data Sheet'!D57/'Data Sheet'!D$61 -> 0.0059031906 | F34: ='Data Sheet'!E57/'Data Sheet'!E$61 -> 0.0059437463 | G34: ='Data Sheet'!F57/'Data Sheet'!F$61 -> 0.004712277 | H34: ='Data Sheet'!G57/'Data Sheet'!G$61 -> 0.004177986 | I34: ='Data Sheet'!H57/'Data Sheet'!H$61 -> 0.0037208104 | J34: ='Data Sheet'!I57/'Data Sheet'!I$61 -> 0.0032079441 | ... L34: ='Data Sheet'!K57/'Data Sheet'!K$61 -> 0.0027787796
B35: Reserves | C35: ='Data Sheet'!B58/'Data Sheet'!B$61 -> 0.60522813 | D35: ='Data Sheet'!C58/'Data Sheet'!C$61 -> 0.60408487 | E35: ='Data Sheet'!D58/'Data Sheet'!D$61 -> 0.57694149 | F35: ='Data Sheet'!E58/'Data Sheet'!E$61 -> 0.62177833 | G35: ='Data Sheet'!F58/'Data Sheet'!F$61 -> 0.62442435 | H35: ='Data Sheet'!G58/'Data Sheet'!G$61 -> 0.59741193 | I35: ='Data Sheet'!H58/'Data Sheet'!H$61 -> 0.61663007 | J35: ='Data Sheet'!I58/'Data Sheet'!I$61 -> 0.62314047 | ... L35: ='Data Sheet'!K58/'Data Sheet'!K$61 -> 0.61635111
B36: Borrowings | C36: ='Data Sheet'!B59/'Data Sheet'!B$61 -> 0.045169804 | D36: ='Data Sheet'!C59/'Data Sheet'!C$61 -> 0.038756913 | E36: ='Data Sheet'!D59/'Data Sheet'!D$61 -> 0.081211951 | F36: ='Data Sheet'!E59/'Data Sheet'!E$61 -> 0.069308593 | G36: ='Data Sheet'!F59/'Data Sheet'!F$61 -> 0.053701879 | H36: ='Data Sheet'!G59/'Data Sheet'!G$61 -> 0.069119709 | I36: ='Data Sheet'!H59/'Data Sheet'!H$61 -> 0.074967813 | J36: ='Data Sheet'!I59/'Data Sheet'!I$61 -> 0.082753053 | ... L36: ='Data Sheet'!K59/'Data Sheet'!K$61 -> 0.11382017
B37: Other Liabilities | C37: ='Data Sheet'!B60/'Data Sheet'!B$61 -> 0.34186981 | D37: ='Data Sheet'!C60/'Data Sheet'!C$61 -> 0.35018905 | E37: ='Data Sheet'!D60/'Data Sheet'!D$61 -> 0.33594337 | F37: ='Data Sheet'!E60/'Data Sheet'!E$61 -> 0.30296933 | G37: ='Data Sheet'!F60/'Data Sheet'!F$61 -> 0.31716149 | H37: ='Data Sheet'!G60/'Data Sheet'!G$61 -> 0.32929037 | I37: ='Data Sheet'!H60/'Data Sheet'!H$61 -> 0.30468131 | J37: ='Data Sheet'!I60/'Data Sheet'!I$61 -> 0.29089853 | ... L37: ='Data Sheet'!K60/'Data Sheet'!K$61 -> 0.26704994
B39: Total Assets | C39: ='Data Sheet'!B66/'Data Sheet'!B$66 -> 1 | D39: ='Data Sheet'!C66/'Data Sheet'!C$66 -> 1 | E39: ='Data Sheet'!D66/'Data Sheet'!D$66 -> 1 | F39: ='Data Sheet'!E66/'Data Sheet'!E$66 -> 1 | G39: ='Data Sheet'!F66/'Data Sheet'!F$66 -> 1 | H39: ='Data Sheet'!G66/'Data Sheet'!G$66 -> 1 | I39: ='Data Sheet'!H66/'Data Sheet'!H$66 -> 1 | J39: ='Data Sheet'!I66/'Data Sheet'!I$66 -> 1 | ... L39: ='Data Sheet'!K66/'Data Sheet'!K$66 -> 1
B40: Net Block | C40: ='Data Sheet'!B62/'Data Sheet'!B$66 -> 0.26631918 | D40: ='Data Sheet'!C62/'Data Sheet'!C$66 -> 0.27116979 | E40: ='Data Sheet'!D62/'Data Sheet'!D$66 -> 0.39981685 | F40: ='Data Sheet'!E62/'Data Sheet'!E$66 -> 0.38866784 | G40: ='Data Sheet'!F62/'Data Sheet'!F$66 -> 0.28781244 | H40: ='Data Sheet'!G62/'Data Sheet'!G$66 -> 0.24039362 | I40: ='Data Sheet'!H62/'Data Sheet'!H$66 -> 0.22384057 | J40: ='Data Sheet'!I62/'Data Sheet'!I$66 -> 0.23901124 | ... L40: ='Data Sheet'!K62/'Data Sheet'!K$66 -> 0.27927663
B41: Capital Work in Progress | C41: ='Data Sheet'!B63/'Data Sheet'!B$66 -> 0.020760665 | D41: ='Data Sheet'!C63/'Data Sheet'!C$66 -> 0.10208973 | E41: ='Data Sheet'!D63/'Data Sheet'!D$66 -> 0.01290369 | F41: ='Data Sheet'!E63/'Data Sheet'!E$66 -> 0.0086900645 | G41: ='Data Sheet'!F63/'Data Sheet'!F$66 -> 0.0089892873 | H41: ='Data Sheet'!G63/'Data Sheet'!G$66 -> 0.018574005 | I41: ='Data Sheet'!H63/'Data Sheet'!H$66 -> 0.039550679 | J41: ='Data Sheet'!I63/'Data Sheet'!I$66 -> 0.090244164 | ... L41: ='Data Sheet'!K63/'Data Sheet'!K$66 -> 0.053555531
B42: Investments | C42: ='Data Sheet'!B64/'Data Sheet'!B$66 -> 0.21378068 | D42: ='Data Sheet'!C64/'Data Sheet'!C$66 -> 0.15553479 | E42: ='Data Sheet'!D64/'Data Sheet'!D$66 -> 0.15807775 | F42: ='Data Sheet'!E64/'Data Sheet'!E$66 -> 0.12509938 | G42: ='Data Sheet'!F64/'Data Sheet'!F$66 -> 0.23270552 | H42: ='Data Sheet'!G64/'Data Sheet'!G$66 -> 0.14145262 | I42: ='Data Sheet'!H64/'Data Sheet'!H$66 -> 0.165315 | J42: ='Data Sheet'!I64/'Data Sheet'!I$66 -> 0.15343819 | ... L42: ='Data Sheet'!K64/'Data Sheet'!K$66 -> 0.20457693
B43: Other Assets | C43: ='Data Sheet'!B75/'Data Sheet'!B$66 -> 0.10617895 | D43: ='Data Sheet'!C75/'Data Sheet'!C$66 -> 0.1229224 | E43: ='Data Sheet'!D75/'Data Sheet'!D$66 -> 0.09058862 | F43: ='Data Sheet'!E75/'Data Sheet'!E$66 -> 0.10774032 | G43: ='Data Sheet'!F75/'Data Sheet'!F$66 -> 0.12603671 | H43: ='Data Sheet'!G75/'Data Sheet'!G$66 -> 0.12529864 | I43: ='Data Sheet'!H75/'Data Sheet'!H$66 -> 0.11777536 | J43: ='Data Sheet'!I75/'Data Sheet'!I$66 -> 0.11944141 | ... L43: ='Data Sheet'!K75/'Data Sheet'!K$66 -> 0.13583603
B44: Receivables | C44: ='Data Sheet'!B67/'Data Sheet'!B$66 -> 0.11661248 | D44: ='Data Sheet'!C67/'Data Sheet'!C$66 -> 0.12574073 | E44: ='Data Sheet'!D67/'Data Sheet'!D$66 -> 0.11738253 | F44: ='Data Sheet'!E67/'Data Sheet'!E$66 -> 0.111242 | G44: ='Data Sheet'!F67/'Data Sheet'!F$66 -> 0.12783722 | H44: ='Data Sheet'!G67/'Data Sheet'!G$66 -> 0.16862826 | I44: ='Data Sheet'!H67/'Data Sheet'!H$66 -> 0.17987046 | J44: ='Data Sheet'!I67/'Data Sheet'!I$66 -> 0.16350917 | ... L44: ='Data Sheet'!K67/'Data Sheet'!K$66 -> 0.12925729
B45: Inventory | C45: ='Data Sheet'!B68/'Data Sheet'!B$66 -> 0.21176137 | D45: ='Data Sheet'!C68/'Data Sheet'!C$66 -> 0.19314229 | E45: ='Data Sheet'!D68/'Data Sheet'!D$66 -> 0.19385138 | F45: ='Data Sheet'!E68/'Data Sheet'!E$66 -> 0.21005182 | G45: ='Data Sheet'!F68/'Data Sheet'!F$66 -> 0.18661442 | H45: ='Data Sheet'!G68/'Data Sheet'!G$66 -> 0.26800526 | I45: ='Data Sheet'!H68/'Data Sheet'!H$66 -> 0.24091549 | J45: ='Data Sheet'!I68/'Data Sheet'!I$66 -> 0.19810226 | ... L45: ='Data Sheet'!K68/'Data Sheet'!K$66 -> 0.16639334
B46: Cash & Bank | C46: ='Data Sheet'!B69/'Data Sheet'!B$66 -> 0.064586677 | D46: ='Data Sheet'!C69/'Data Sheet'!C$66 -> 0.029400268 | E46: ='Data Sheet'!D69/'Data Sheet'!D$66 -> 0.027379185 | F46: ='Data Sheet'!E69/'Data Sheet'!E$66 -> 0.048508579 | G46: ='Data Sheet'!F69/'Data Sheet'!F$66 -> 0.030004412 | H46: ='Data Sheet'!G69/'Data Sheet'!G$66 -> 0.037647609 | I46: ='Data Sheet'!H69/'Data Sheet'!H$66 -> 0.032732426 | J46: ='Data Sheet'!I69/'Data Sheet'!I$66 -> 0.036253581 | ... L46: ='Data Sheet'!K69/'Data Sheet'!K$66 -> 0.031104255

Sheet Assumption Sheet
B2: ='Data Sheet'!B1 -> ASIAN PAINTS LTD
B3: (ASIANPAINT | BSE Code: 500820)
B4: =CONCATENATE("INR "&'Data Sheet'!B8) -> INR 2645.2
B5: 52 Week (High - INR 2,985.7 & Low - 2115.0)
B8: ="Assumption Sheet"&" - "&'Data Sheet'!B1 -> Assumption Sheet - ASIAN PAINTS LTD
A10: # | B10: 1. P & L Drivers
B11: Drivers | C11: =IFERROR(HistoricalFS!G3,0) -> 44286 | D11: =IFERROR(HistoricalFS!H3,0) -> 44651 | E11: =IFERROR(HistoricalFS!I3,0) -> 45016 | F11: =IFERROR(HistoricalFS!J3,0) -> 45382 | G11: =IFERROR(HistoricalFS!K3,0) -> 45747 | H11: =IFERROR(HistoricalFS!L3,0) -> 46112 | I11: =H11+365 -> 46477 | J11: =I11+365 -> 46842 | K11: =J11+365 -> 47207 | L11: =K11+365 -> 47572 | M11: =L11+365 -> 47937
B12: Sales Growth Rate (%) | C12: =IFERROR(HistoricalFS!G7,0) -> 0.074292288 | D12: =IFERROR(HistoricalFS!H7,0) -> 0.34028285 | E12: =IFERROR(HistoricalFS!I7,0) -> 0.18512278 | F12: =IFERROR(HistoricalFS!J7,0) -> 0.029173127 | G12: =IFERROR(HistoricalFS!K7,0) -> -0.044770308 | H12: =IFERROR(HistoricalFS!L7,0) -> 0.049487961 | I12: =IF($C$55="Bull Case",I58,I57) -> 0.07 | J12: =IF($C$55="Bull Case",J58,J57) -> 0.07 | K12: =IF($C$55="Bull Case",K58,K57) -> 0.075 | L12: =IF($C$55="Bull Case",L58,L57) -> 0.075 | M12: =IF($C$55="Bull Case",M58,M57) -> 0.08
B13: COGS % of Sales | C13: =IFERROR(HistoricalFS!G10,0) -> 0.64639643 | D13: =IFERROR(HistoricalFS!H10,0) -> 0.7075486 | E13: =IFERROR(HistoricalFS!I10,0) -> 0.68911776 | F13: =IFERROR(HistoricalFS!J10,0) -> 0.64826497 | G13: =IFERROR(HistoricalFS!K10,0) -> 0.67072273 | H13: =IFERROR(HistoricalFS!L10,0) -> 0.66012628 | I13: =IF($C$55="Bull Case",I60,I59) -> 0.66 | J13: =IF($C$55="Bull Case",J60,J59) -> 0.66 | K13: =IF($C$55="Bull Case",K60,K59) -> 0.655 | L13: =IF($C$55="Bull Case",L60,L59) -> 0.655 | M13: =IF($C$55="Bull Case",M60,M59) -> 0.65
B14: Gross Margin (%) | C14: =1-C13 -> 0.35360357 | D14: =1-D13 -> 0.2924514 | E14: =1-E13 -> 0.31088224 | F14: =1-F13 -> 0.35173503 | G14: =1-G13 -> 0.32927727 | H14: =1-H13 -> 0.33987372 | I14: =1-I13 -> 0.34 | J14: =1-J13 -> 0.34 | ... M14: =1-M13 -> 0.35
B15: S&G Exp % Of Sales | C15: =IFERROR(HistoricalFS!G16,0) -> 0.12997501 | D15: =IFERROR(HistoricalFS!H16,0) -> 0.12738615 | E15: =IFERROR(HistoricalFS!I16,0) -> 0.12937757 | F15: =IFERROR(HistoricalFS!J16,0) -> 0.1380419 | G15: =IFERROR(HistoricalFS!K16,0) -> 0.1521323 | H15: =IFERROR(HistoricalFS!L16,0) -> 0.151592 | I15: =IF($C$55="Bull Case",I62,I61) -> 0.15 | J15: =IF($C$55="Bull Case",J62,J61) -> 0.15 | K15: =IF($C$55="Bull Case",K62,K61) -> 0.15 | L15: =IF($C$55="Bull Case",L62,L61) -> 0.15 | M15: =IF($C$55="Bull Case",M62,M61) -> 0.15
B16: EBITDA Margin (%) | C16: =IFERROR(HistoricalFS!G19,0) -> 0.22362856 | D16: =IFERROR(HistoricalFS!H19,0) -> 0.16506525 | E16: =IFERROR(HistoricalFS!I19,0) -> 0.18150467 | F16: =IFERROR(HistoricalFS!J19,0) -> 0.21369313 | G16: =IFERROR(HistoricalFS!K19,0) -> 0.17714497 | H16: =IFERROR(HistoricalFS!L19,0) -> 0.18828172 | I16: =I14-I15 -> 0.19 | J16: =J14-J15 -> 0.19 | K16: =K14-K15 -> 0.195 | L16: =L14-L15 -> 0.195 | M16: =M14-M15 -> 0.2
B17: Depreciation (Cr) | C17: =IFERROR(HistoricalFS!G24,0) -> 791.27 | D17: =IFERROR(HistoricalFS!H24,0) -> 816.36 | E17: =IFERROR(HistoricalFS!I24,0) -> 858.02 | F17: =IFERROR(HistoricalFS!J24,0) -> 853 | G17: =IFERROR(HistoricalFS!K24,0) -> 1026.34 | H17: =IFERROR(HistoricalFS!L24,0) -> 1228.85 | I17: 1350 | J17: 1450 | K17: 1550 | L17: 1650 | M17: 1750
