Workbook
Name UPDATE: 'Data Sheet'!$E$1

Sheet Front Page

Sheet Index
B3: Table of Content
B4: (TITAN | BSE Code: 500114)
B9: 1 | C9: One Page Profile (Teaser) | M9: 1
B10: 2 | C10: Historical Income Statement & Balance Sheet | M10: 2
B11: 3 | C11: Historical Cash Flow Statement | M11: 3
B12: 4 | C12: Ratio Analysis | M12: 4
B13: 5 | C13: Common Size Staement | M13: 5
B14: 6 | C14: Assumptions Sheet | M14: 6
B15: 7 | C15: Forcasted Financial Statements | M15: 7
B16: 8 | C16: Beta Regression - Titan Company Ltd. | M16: 8-10
B17: 9 | C17: Comps Beta | M17: 11-13
B18: 10 | C18: Return on Market | M18: 14
B19: 11 | C19: Weighted Average Cost of Capital (WACC) | M19: 15
B20: 12 | C20: Intrinsic Growth | M20: 16
B21: 13 | C21: DCF Valuation (FCFF) | M21: 17
B22: 14 | C22: Comparable Company Valuation | M22: 18
B23: 15 | C23: Football Field Analysis | M23: 19
B24: 16 | C24: Value at Risk - Historical | M24: 20
B25: 17 | C25: Value at Risk - Monte Carlo Method | M25: 21
B26: 18 | C26: DUPONT Analysis (ROE & ROA) | M26: 22-23
B27: 19 | C27: Altman's Z Score Analysis | M27: 24-25

Sheet One Page Summary
B4: ='Data Sheet'!B1&" - One Page Profile" -> TITAN COMPANY LTD - One Page Profile
C5: Titan Company Limited is an Indian fashion accessories company that mainly manufactures items such as jewellery, watches and eyewear. Part of the Tata Group and started as a joint venture with TIDCO, the company has its corporate headquarters in Electronic City, Bangalore and registered office in Hosur, Tamil Nadu. In 1994, Titan diversified into jewellery with Tanishq and subsequently into eyewear with Titan Eyeplus.
B8: Key Financial Metrics | C8: =HistoricalFS!H5 -> 44651 | D8: =HistoricalFS!I5 -> 45016 | E8: =HistoricalFS!J5 -> 45382 | F8: =HistoricalFS!K5 -> 45747 | G8: =HistoricalFS!L5 -> 46112 | I8: Share Price - 5Y
B10: Total Sales | C10: =HistoricalFS!H9 -> 28799 | D10: =HistoricalFS!I9 -> 40575 | E10: =HistoricalFS!J9 -> 51084 | F10: =HistoricalFS!K9 -> 60456 | G10: =HistoricalFS!L9 -> 87584
B11: Sales Growth (Y-O-Y) | C11: =HistoricalFS!H10 -> 0.3305766 | D11: =HistoricalFS!I10 -> 0.40890309 | E11: =HistoricalFS!J10 -> 0.25900185 | F11: =HistoricalFS!K10 -> 0.18346253 | G11: =HistoricalFS!L10 -> 0.44872304
B13: Gross Profit | C13: =HistoricalFS!H15 -> 5574 | D13: =HistoricalFS!I15 -> 8280 | E13: =HistoricalFS!J15 -> 9420 | F13: =HistoricalFS!K15 -> 10432 | G13: =HistoricalFS!L15 -> 14123
B14: Gross Profit Margins (%) | C14: =HistoricalFS!H16 -> 0.19354839 | D14: =HistoricalFS!I16 -> 0.20406654 | E14: =HistoricalFS!J16 -> 0.18440216 | F14: =HistoricalFS!K16 -> 0.17255525 | G14: =HistoricalFS!L16 -> 0.16125091
B15: EBITDA Margins (%) | C15: =HistoricalFS!H22 -> 0.11611514 | D15: =HistoricalFS!I22 -> 0.12032039 | E15: =HistoricalFS!J22 -> 0.10359408 | F15: =HistoricalFS!K22 -> 0.0941842 | G15: =HistoricalFS!L22 -> 0.095416971
B16: EBIT Margins (%) | C16: =HistoricalFS!H31 -> 0.10840654 | D16: =HistoricalFS!I31 -> 0.11699322 | E16: =HistoricalFS!J31 -> 0.1026153 | F16: =HistoricalFS!K31 -> 0.090776763 | G16: =HistoricalFS!L31 -> 0.09112395
B17: Net Profit Margins (In Rs) | C17: =HistoricalFS!H42 -> 2198 | D17: =HistoricalFS!I42 -> 3274 | E17: =HistoricalFS!J42 -> 3496 | F17: =HistoricalFS!K42 -> 3337 | G17: =HistoricalFS!L42 -> 5073
B18: Earning Per Share (In Rs) | C18: =HistoricalFS!H47 -> 24.757828 | D18: =HistoricalFS!I47 -> 36.877675 | E18: =HistoricalFS!J47 -> 39.378238 | F18: =HistoricalFS!K47 -> 37.587294 | G18: =HistoricalFS!L47 -> 57.141248
B19: EPS Growth (Y-O-Y) | C19: =HistoricalFS!H48 -> 1.2566735 | D19: =HistoricalFS!I48 -> 0.48953594 | E19: =HistoricalFS!J48 -> 0.067806964 | F19: =HistoricalFS!K48 -> -0.045480549 | G19: =HistoricalFS!L48 -> 0.52022775
B20: Dividend Per Share | C20: =HistoricalFS!H50 -> 7.5185853 | D20: =HistoricalFS!I50 -> 10.02478 | E20: =HistoricalFS!J50 -> 11.027258 | F20: =HistoricalFS!K50 -> 11.027258 | G20: =HistoricalFS!L50 -> 15.037171
B21: Dividend Growth | C21: ='Data Sheet'!G97 -> 0.875 | D21: ='Data Sheet'!H97 -> 0.33333333 | E21: ='Data Sheet'!I97 -> 0.1 | F21: ='Data Sheet'!J97 -> 0 | G21: ='Data Sheet'!K97 -> 0.36363636
B23: Key Financial Ratio | C23: =C8 -> 44651 | D23: =D8 -> 45016 | E23: =E8 -> 45382 | F23: =F8 -> 45747 | G23: =G8 -> 46112 | I23: Volumes in Million - 5Y
B25: Price to Earning | C25: ='Data Sheet'!G105 -> 185.16971 | D25: ='Data Sheet'!H105 -> 124.31369 | E25: ='Data Sheet'!I105 -> 116.41963 | F25: ='Data Sheet'!J105 -> 121.96675 | G25: ='Data Sheet'!K105 -> 80.229259
B26: EV/EBITDA | C26: ='Data Sheet'!G101 -> 69.037499 | D26: ='Data Sheet'!H101 -> 47.377473 | E26: ='Data Sheet'!I101 -> 66.425889 | F26: ='Data Sheet'!J101 -> 51.134038 | G26: ='Data Sheet'!K101 -> 52.136775
B27: EV/Sales | C27: ='Data Sheet'!G102 -> 8.0162991 | D27: ='Data Sheet'!H102 -> 5.7004762 | E27: ='Data Sheet'!I102 -> 6.8813289 | F27: ='Data Sheet'!J102 -> 4.8160185 | G27: ='Data Sheet'!K102 -> 4.9747332
B28: Price to Book Value | C28: ='Data Sheet'!G104 -> 0.27261636 | D28: ='Data Sheet'!H104 -> 0.21220994 | E28: ='Data Sheet'!I104 -> 0.40474822 | F28: ='Data Sheet'!J104 -> 0.26353665 | G28: ='Data Sheet'!K104 -> 0.29194421
B29: Return on Equity (%) | C29: ='DUPONT Analysis'!F57 -> 0.26166667 | D29: ='DUPONT Analysis'!G57 -> 0.30953957 | E29: ='DUPONT Analysis'!H57 -> 0.32912822 | F29: ='DUPONT Analysis'!I57 -> 0.31755246 | G29: ='DUPONT Analysis'!J57 -> 0.37128115
B30: Return on Capital Employed (%) | C30: ='Ratio Analysis'!H21 -> 0.18832187 | D30: ='Ratio Analysis'!I21 -> 0.22372514 | E30: ='Ratio Analysis'!J21 -> 0.21034469 | F30: ='Ratio Analysis'!K21 -> 0.16937749 | G30: ='Ratio Analysis'!L21 -> 0.1722865
B32: Top 10 Share Holders | C32: =comps_data!C11 -> No. of Shares (Cr) | E32: =comps_data!D11 -> Shareholding (%) | F32: Market Value (In Cr) | I32: Share Holding Pattern
B34: =comps_data!B12 -> Tamilnadu Industrial Development Corporation Ltd | C34: =comps_data!C12 -> 24.747672 | E34: =comps_data!D12 -> 0.2788 | F34: =C34*'Data Sheet'!$B$6 -> 2197.0641
B35: =comps_data!B13 -> Tata Sons Private Limited | C35: =comps_data!C13 -> 18.50589 | E35: =comps_data!D13 -> 0.2084 | F35: =C35*'Data Sheet'!$B$6 -> 1642.9273
B36: =comps_data!B14 -> Rekha Jhunjhunwala | C36: =comps_data!C14 -> 3.7643895 | E36: =comps_data!D14 -> 0.0424 | F36: =C36*'Data Sheet'!$B$6 -> 334.19729
B37: =comps_data!B15 -> Life Insurance Corporation Of India | C37: =comps_data!C15 -> 1.9224672 | E37: =comps_data!D15 -> 0.0217 | F37: =C37*'Data Sheet'!$B$6 -> 170.67398
B38: =comps_data!B16 -> Tata Investment Corporation Ltd | C38: =comps_data!C16 -> 1.787564 | E38: =comps_data!D16 -> 0.0201 | F38: =C38*'Data Sheet'!$B$6 -> 158.69746
B39: =comps_data!B17 -> Sbi Nifty 50 Etf | C39: =comps_data!C17 -> 1.5999057 | E39: =comps_data!D17 -> 0.018 | F39: =C39*'Data Sheet'!$B$6 -> 142.03741
B40: =comps_data!B18 -> Nps Trust A/C Uti Pension Fund Limited-Scheme State Govt | C40: =comps_data!C18 -> 1.5386048 | E40: =comps_data!D18 -> 0.0173 | F40: =C40*'Data Sheet'!$B$6 -> 136.59521
B41: =comps_data!B19 -> Tata Chemicals Limited | C41: =comps_data!C19 -> 1.382618 | E41: =comps_data!D19 -> 0.0156 | F41: =C41*'Data Sheet'!$B$6 -> 122.74691
B42: =comps_data!B20 -> Icici Prudential Balanced Advantage Fund | C42: =comps_data!C20 -> 1.1184971 | E42: =comps_data!D20 -> 0.0126 | F42: =C42*'Data Sheet'!$B$6 -> 99.298625
B43: =comps_data!B21 -> Uti Nifty 50 Etf | C43: =comps_data!C21 -> 0.9851148 | E43: =comps_data!D21 -> 0.0111 | F43: =C43*'Data Sheet'!$B$6 -> 87.457129
B45: Managerial Remuneration | C45: Designation | D45: Remuneration | F45: Ratio to Median | I45: Capital Structure
B47: Dr. S Vijayakumar, IAS | C47: Chairman | D47: - | F47: - | I47: Share Price | K47: ='Data Sheet'!B8 -> 4584.4
B48: Mr. N. N. Tata | C48: Vice Chairman | D48: 7440000 | F48: 6.91X | I48: No of Share | K48: ='Data Sheet'!B6 -> 88.778617
B49: Mr. Ajoy Chawla | C49: MD | D49: 29597925 | F49: 5.13X | I49: Market Capitalization | K49: =K48*K47 -> 406996.69
B50: Mr. Puneet Chhatwal | C50: Director | D50: - | F50: - | I50: Less: Cash & Equivalent | K50: =-'Data Sheet'!K69 -> -1917
I51: Add: Total Debt | K51: ='Data Sheet'!K59 -> 30621
I52: Add: Minority Interest | K52: Nil
I53: Enterprise Value | K53: =SUM(K49:K52) -> 435700.69
...

Sheet HistoricalFS
B4: ="Historical Financial Statements"&" - "&'Data Sheet'!B1 -> Historical Financial Statements - TITAN COMPANY LTD
B5: Years | C5: ='Data Sheet'!B16 -> 42825 | D5: ='Data Sheet'!C16 -> 43190 | E5: ='Data Sheet'!D16 -> 43555 | F5: ='Data Sheet'!E16 -> 43921 | G5: ='Data Sheet'!F16 -> 44286 | H5: ='Data Sheet'!G16 -> 44651 | I5: ='Data Sheet'!H16 -> 45016 | J5: ='Data Sheet'!I16 -> 45382 | ... L5: ='Data Sheet'!K16 -> 46112
A7: # | B7: ="Income Statement"&" - "&'Data Sheet'!B1 -> Income Statement - TITAN COMPANY LTD
B9: Sales | C9: =IFERROR('Data Sheet'!B17,0) -> 13260.83 | D9: =IFERROR('Data Sheet'!C17,0) -> 16119.77 | E9: =IFERROR('Data Sheet'!D17,0) -> 19778.52 | F9: =IFERROR('Data Sheet'!E17,0) -> 21052 | G9: =IFERROR('Data Sheet'!F17,0) -> 21644 | H9: =IFERROR('Data Sheet'!G17,0) -> 28799 | I9: =IFERROR('Data Sheet'!H17,0) -> 40575 | J9: =IFERROR('Data Sheet'!I17,0) -> 51084 | ... L9: =IFERROR('Data Sheet'!K17,0) -> 87584
B10: Sales Growth | D10: =IFERROR(D9/C9-1,0) -> 0.21559284 | E10: =IFERROR(E9/D9-1,0) -> 0.22697284 | F10: =IFERROR(F9/E9-1,0) -> 0.064387022 | G10: =IFERROR(G9/F9-1,0) -> 0.028120844 | H10: =IFERROR(H9/G9-1,0) -> 0.3305766 | I10: =IFERROR(I9/H9-1,0) -> 0.40890309 | J10: =IFERROR(J9/I9-1,0) -> 0.25900185 | K10: =IFERROR(K9/J9-1,0) -> 0.18346253 | L10: =IFERROR(L9/K9-1,0) -> 0.44872304
B12: COGS | C12: =IFERROR(SUM('Data Sheet'!B18,'Data Sheet'!B20:B22)-1*'Data Sheet'!B19,0) -> 10606.01 | D12: =IFERROR(SUM('Data Sheet'!C18,'Data Sheet'!C20:C22)-1*'Data Sheet'!C19,0) -> 12762.63 | E12: =IFERROR(SUM('Data Sheet'!D18,'Data Sheet'!D20:D22)-1*'Data Sheet'!D19,0) -> 15660.48 | F12: =IFERROR(SUM('Data Sheet'!E18,'Data Sheet'!E20:E22)-1*'Data Sheet'!E19,0) -> 16626 | G12: =IFERROR(SUM('Data Sheet'!F18,'Data Sheet'!F20:F22)-1*'Data Sheet'!F19,0) -> 17661 | H12: =IFERROR(SUM('Data Sheet'!G18,'Data Sheet'!G20:G22)-1*'Data Sheet'!G19,0) -> 23225 | I12: =IFERROR(SUM('Data Sheet'!H18,'Data Sheet'!H20:H22)-1*'Data Sheet'!H19,0) -> 32295 | J12: =IFERROR(SUM('Data Sheet'!I18,'Data Sheet'!I20:I22)-1*'Data Sheet'!I19,0) -> 41664 | ... L12: =IFERROR(SUM('Data Sheet'!K18,'Data Sheet'!K20:K22)-1*'Data Sheet'!K19,0) -> 73461
B13: COGS % of Sales | C13: =IFERROR(C12/C9,0) -> 0.79979986 | D13: =IFERROR(D12/D9,0) -> 0.79173772 | E13: =IFERROR(E12/E9,0) -> 0.79179231 | F13: =IFERROR(F12/F9,0) -> 0.78975869 | G13: =IFERROR(G12/G9,0) -> 0.81597671 | H13: =IFERROR(H12/H9,0) -> 0.80645161 | I13: =IFERROR(I12/I9,0) -> 0.79593346 | J13: =IFERROR(J12/J9,0) -> 0.81559784 | ... L13: =IFERROR(L12/L9,0) -> 0.83874909
B15: Gross Profit | C15: =C9-C12 -> 2654.82 | D15: =D9-D12 -> 3357.14 | E15: =E9-E12 -> 4118.04 | F15: =F9-F12 -> 4426 | G15: =G9-G12 -> 3983 | H15: =H9-H12 -> 5574 | I15: =I9-I12 -> 8280 | J15: =J9-J12 -> 9420 | ... L15: =L9-L12 -> 14123
B16: Gross Margins | C16: =IFERROR(C15/C9,0) -> 0.20020014 | D16: =IFERROR(D15/D9,0) -> 0.20826228 | E16: =IFERROR(E15/E9,0) -> 0.20820769 | F16: =IFERROR(F15/F9,0) -> 0.21024131 | G16: =IFERROR(G15/G9,0) -> 0.18402329 | H16: =IFERROR(H15/H9,0) -> 0.19354839 | I16: =IFERROR(I15/I9,0) -> 0.20406654 | J16: =IFERROR(J15/J9,0) -> 0.18440216 | ... L16: =IFERROR(L15/L9,0) -> 0.16125091
B18: Selling & General Expenses | C18: =IFERROR(SUM('Data Sheet'!B23:B24),0) -> 1490.92 | D18: =IFERROR(SUM('Data Sheet'!C23:C24),0) -> 1712.94 | E18: =IFERROR(SUM('Data Sheet'!D23:D24),0) -> 2124.25 | F18: =IFERROR(SUM('Data Sheet'!E23:E24),0) -> 1963 | G18: =IFERROR(SUM('Data Sheet'!F23:F24),0) -> 2258 | H18: =IFERROR(SUM('Data Sheet'!G23:G24),0) -> 2230 | I18: =IFERROR(SUM('Data Sheet'!H23:H24),0) -> 3398 | J18: =IFERROR(SUM('Data Sheet'!I23:I24),0) -> 4128 | ... L18: =IFERROR(SUM('Data Sheet'!K23:K24),0) -> 5766
B19: S&G % of Sales | C19: =IFERROR(C18/C9,0) -> 0.11243037 | D19: =IFERROR(D18/D9,0) -> 0.1062633 | E19: =IFERROR(E18/E9,0) -> 0.10740187 | F19: =IFERROR(F18/F9,0) -> 0.093245297 | G19: =IFERROR(G18/G9,0) -> 0.10432452 | H19: =IFERROR(H18/H9,0) -> 0.077433244 | I19: =IFERROR(I18/I9,0) -> 0.083746149 | J19: =IFERROR(J18/J9,0) -> 0.080808081 | ... L19: =IFERROR(L18/L9,0) -> 0.065833942
B21: EBITDA | C21: =C15-C18 -> 1163.9 | D21: =D15-D18 -> 1644.2 | E21: =E15-E18 -> 1993.79 | F21: =F15-F18 -> 2463 | G21: =G15-G18 -> 1725 | H21: =H15-H18 -> 3344 | I21: =I15-I18 -> 4882 | J21: =J15-J18 -> 5292 | ... L21: =L15-L18 -> 8357
B22: EBITDA Margins | C22: =IFERROR(C21/C9,0) -> 0.08776977 | D22: =IFERROR(D21/D9,0) -> 0.10199897 | E22: =IFERROR(E21/E9,0) -> 0.10080582 | F22: =IFERROR(F21/F9,0) -> 0.11699601 | G22: =IFERROR(G21/G9,0) -> 0.079698762 | H22: =IFERROR(H21/H9,0) -> 0.11611514 | I22: =IFERROR(I21/I9,0) -> 0.12032039 | J22: =IFERROR(J21/J9,0) -> 0.10359408 | ... L22: =IFERROR(L21/L9,0) -> 0.095416971
B24: Other Income | C24: =IFERROR('Data Sheet'!B25,0) -> -42.38 | D24: =IFERROR('Data Sheet'!C25,0) -> 69.93 | E24: =IFERROR('Data Sheet'!D25,0) -> 178.48 | F24: =IFERROR('Data Sheet'!E25,0) -> 153 | G24: =IFERROR('Data Sheet'!F25,0) -> 180 | H24: =IFERROR('Data Sheet'!G25,0) -> 177 | I24: =IFERROR('Data Sheet'!H25,0) -> 306 | J24: =IFERROR('Data Sheet'!I25,0) -> 534 | ... L24: =IFERROR('Data Sheet'!K25,0) -> 450
B25: Other Income % of Sales | C25: =IFERROR(C24/C9,0) -> -0.0031958784 | D25: =IFERROR(D24/D9,0) -> 0.0043381512 | E25: =IFERROR(E24/E9,0) -> 0.009023931 | F25: =IFERROR(F24/F9,0) -> 0.007267718 | G25: =IFERROR(G24/G9,0) -> 0.0083163925 | H25: =IFERROR(H24/H9,0) -> 0.0061460467 | I25: =IFERROR(I24/I9,0) -> 0.0075415896 | J25: =IFERROR(J24/J9,0) -> 0.010453371 | ... L25: =IFERROR(L24/L9,0) -> 0.0051379247
B27: Depreciation | C27: =IFERROR('Data Sheet'!B26,0) -> 110.53 | D27: =IFERROR('Data Sheet'!C26,0) -> 131.43 | E27: =IFERROR('Data Sheet'!D26,0) -> 162.84 | F27: =IFERROR('Data Sheet'!E26,0) -> 348 | G27: =IFERROR('Data Sheet'!F26,0) -> 375 | H27: =IFERROR('Data Sheet'!G26,0) -> 399 | I27: =IFERROR('Data Sheet'!H26,0) -> 441 | J27: =IFERROR('Data Sheet'!I26,0) -> 584 | ... L27: =IFERROR('Data Sheet'!K26,0) -> 826
B28: Depreciation % of Sales | C28: =IFERROR(C27/C9,0) -> 0.008335074 | D28: =IFERROR(D27/D9,0) -> 0.0081533421 | E28: =IFERROR(E27/E9,0) -> 0.0082331742 | F28: =IFERROR(F27/F9,0) -> 0.016530496 | G28: =IFERROR(G27/G9,0) -> 0.017325818 | H28: =IFERROR(H27/H9,0) -> 0.013854648 | I28: =IFERROR(I27/I9,0) -> 0.010868762 | J28: =IFERROR(J27/J9,0) -> 0.011432151 | ... L28: =IFERROR(L27/L9,0) -> 0.0094309463
B30: EBIT | C30: =SUM(C21,C24)-C27 -> 1010.99 | D30: =SUM(D21,D24)-D27 -> 1582.7 | E30: =SUM(E21,E24)-E27 -> 2009.43 | F30: =SUM(F21,F24)-F27 -> 2268 | G30: =SUM(G21,G24)-G27 -> 1530 | H30: =SUM(H21,H24)-H27 -> 3122 | I30: =SUM(I21,I24)-I27 -> 4747 | J30: =SUM(J21,J24)-J27 -> 5242 | ... L30: =SUM(L21,L24)-L27 -> 7981
B31: EBIT Margins | C31: =IFERROR(C30/C9,0) -> 0.076238818 | D31: =IFERROR(D30/D9,0) -> 0.098183783 | E31: =IFERROR(E30/E9,0) -> 0.10159658 | F31: =IFERROR(F30/F9,0) -> 0.10773323 | G31: =IFERROR(G30/G9,0) -> 0.070689337 | H31: =IFERROR(H30/H9,0) -> 0.10840654 | I31: =IFERROR(I30/I9,0) -> 0.11699322 | J31: =IFERROR(J30/J9,0) -> 0.1026153 | ... L31: =IFERROR(L30/L9,0) -> 0.09112395
B33: Interest Expense | C33: =IFERROR('Data Sheet'!B27,0) -> 37.74 | D33: =IFERROR('Data Sheet'!C27,0) -> 52.92 | E33: =IFERROR('Data Sheet'!D27,0) -> 52.54 | F33: =IFERROR('Data Sheet'!E27,0) -> 166 | G33: =IFERROR('Data Sheet'!F27,0) -> 203 | H33: =IFERROR('Data Sheet'!G27,0) -> 218 | I33: =IFERROR('Data Sheet'!H27,0) -> 300 | J33: =IFERROR('Data Sheet'!I27,0) -> 619 | ... L33: =IFERROR('Data Sheet'!K27,0) -> 1180
B34: Interest % of Sales | C34: =IFERROR(C33/C9,0) -> 0.0028459757 | D34: =IFERROR(D33/D9,0) -> 0.0032829253 | E34: =IFERROR(E33/E9,0) -> 0.0026564172 | F34: =IFERROR(F33/F9,0) -> 0.0078852366 | G34: =IFERROR(G33/G9,0) -> 0.0093790427 | H34: =IFERROR(H33/H9,0) -> 0.0075697073 | I34: =IFERROR(I33/I9,0) -> 0.0073937153 | J34: =IFERROR(J33/J9,0) -> 0.012117297 | ... L34: =IFERROR(L33/L9,0) -> 0.01347278
B36: Earning before Tax | C36: =C30-C33 -> 973.25 | D36: =D30-D33 -> 1529.78 | E36: =E30-E33 -> 1956.89 | F36: =F30-F33 -> 2102 | G36: =G30-G33 -> 1327 | H36: =H30-H33 -> 2904 | I36: =I30-I33 -> 4447 | J36: =J30-J33 -> 4623 | ... L36: =L30-L33 -> 6801
B37: EBT % of Sales | C37: =IFERROR(C36/C9,0) -> 0.073392842 | D37: =IFERROR(D36/D9,0) -> 0.094900858 | E37: =IFERROR(E36/E9,0) -> 0.098940163 | F37: =IFERROR(F36/F9,0) -> 0.099847995 | G37: =IFERROR(G36/G9,0) -> 0.061310294 | H37: =IFERROR(H36/H9,0) -> 0.10083683 | I37: =IFERROR(I36/I9,0) -> 0.10959951 | J37: =IFERROR(J36/J9,0) -> 0.090498003 | ... L37: =IFERROR(L36/L9,0) -> 0.077651169
B39: Tax Expense | C39: =IFERROR('Data Sheet'!B29,0) -> 275.97 | D39: =IFERROR('Data Sheet'!C29,0) -> 427.87 | E39: =IFERROR('Data Sheet'!D29,0) -> 568.24 | F39: =IFERROR('Data Sheet'!E29,0) -> 609 | G39: =IFERROR('Data Sheet'!F29,0) -> 353 | H39: =IFERROR('Data Sheet'!G29,0) -> 706 | I39: =IFERROR('Data Sheet'!H29,0) -> 1173 | J39: =IFERROR('Data Sheet'!I29,0) -> 1127 | ... L39: =IFERROR('Data Sheet'!K29,0) -> 1728
B40: Effective Tax Rate | C40: =IFERROR(C39/C36,0) -> 0.2835551 | D40: =IFERROR(D39/D36,0) -> 0.27969381 | E40: =IFERROR(E39/E36,0) -> 0.29037912 | F40: =IFERROR(F39/F36,0) -> 0.28972407 | G40: =IFERROR(G39/G36,0) -> 0.26601356 | H40: =IFERROR(H39/H36,0) -> 0.24311295 | I40: =IFERROR(I39/I36,0) -> 0.26377333 | J40: =IFERROR(J39/J36,0) -> 0.24378109 | ... L40: =IFERROR(L39/L36,0) -> 0.25408028
B42: Net Profit | C42: =C36-C39 -> 697.28 | D42: =D36-D39 -> 1101.91 | E42: =E36-E39 -> 1388.65 | F42: =F36-F39 -> 1493 | G42: =G36-G39 -> 974 | H42: =H36-H39 -> 2198 | I42: =I36-I39 -> 3274 | J42: =J36-J39 -> 3496 | ... L42: =L36-L39 -> 5073
B43: Net Profit Margins | C43: =IFERROR(C42/C9,0) -> 0.052581927 | D43: =IFERROR(D42/D9,0) -> 0.068357675 | E43: =IFERROR(E42/E9,0) -> 0.070210006 | F43: =IFERROR(F42/F9,0) -> 0.070919628 | G43: =IFERROR(G42/G9,0) -> 0.045000924 | H43: =IFERROR(H42/H9,0) -> 0.076322095 | I43: =IFERROR(I42/I9,0) -> 0.08069008 | J43: =IFERROR(J42/J9,0) -> 0.068436301 | ... L43: =IFERROR(L42/L9,0) -> 0.057921538
B45: No of Equity Shares | C45: =IFERROR('Data Sheet'!B93,0) -> 88.78 | D45: =IFERROR('Data Sheet'!C93,0) -> 88.78 | E45: =IFERROR('Data Sheet'!D93,0) -> 88.78 | F45: =IFERROR('Data Sheet'!E93,0) -> 88.78 | G45: =IFERROR('Data Sheet'!F93,0) -> 88.78 | H45: =IFERROR('Data Sheet'!G93,0) -> 88.78 | I45: =IFERROR('Data Sheet'!H93,0) -> 88.78 | J45: =IFERROR('Data Sheet'!I93,0) -> 88.78 | ... L45: =IFERROR('Data Sheet'!K93,0) -> 88.78
B47: Earnings Per Share | C47: =IFERROR(C42/C45,0) -> 7.8540212 | D47: =IFERROR(D42/D45,0) -> 12.411692 | E47: =IFERROR(E42/E45,0) -> 15.641473 | F47: =IFERROR(F42/F45,0) -> 16.816851 | G47: =IFERROR(G42/G45,0) -> 10.970939 | H47: =IFERROR(H42/H45,0) -> 24.757828 | I47: =IFERROR(I42/I45,0) -> 36.877675 | J47: =IFERROR(J42/J45,0) -> 39.378238 | ... L47: =IFERROR(L42/L45,0) -> 57.141248
B48: EPS Growth Rate | D48: =D47/C47-1 -> 0.58029773 | E48: =E47/D47-1 -> 0.26022089 | F48: =F47/E47-1 -> 0.075144925 | G48: =G47/F47-1 -> -0.34762224 | H48: =H47/G47-1 -> 1.2566735 | I48: =I47/H47-1 -> 0.48953594 | J48: =J47/I47-1 -> 0.067806964 | K48: =K47/J47-1 -> -0.045480549 | L48: =L47/K47-1 -> 0.52022775
B50: Dividend Per Shares | C50: =IFERROR('Data Sheet'!B31/HistoricalFS!C45,0) -> 2.6000225 | D50: =IFERROR('Data Sheet'!C31/HistoricalFS!D45,0) -> 3.7499437 | E50: =IFERROR('Data Sheet'!D31/HistoricalFS!E45,0) -> 5 | F50: =IFERROR('Data Sheet'!E31/HistoricalFS!F45,0) -> 4.0099121 | G50: =IFERROR('Data Sheet'!F31/HistoricalFS!G45,0) -> 4.0099121 | H50: =IFERROR('Data Sheet'!G31/HistoricalFS!H45,0) -> 7.5185853 | I50: =IFERROR('Data Sheet'!H31/HistoricalFS!I45,0) -> 10.02478 | J50: =IFERROR('Data Sheet'!I31/HistoricalFS!J45,0) -> 11.027258 | ... L50: =IFERROR('Data Sheet'!K31/HistoricalFS!L45,0) -> 15.037171
B51: Dividend Payout Ratio | C51: =IFERROR(C50/C47,0) -> 0.33104348 | D51: =IFERROR(D50/D47,0) -> 0.30212994 | E51: =IFERROR(E50/E47,0) -> 0.31966298 | F51: =IFERROR(F50/F47,0) -> 0.23844608 | G51: =IFERROR(G50/G47,0) -> 0.36550308 | H51: =IFERROR(H50/H47,0) -> 0.30368517 | I51: =IFERROR(I50/I47,0) -> 0.27183873 | J51: =IFERROR(J50/J47,0) -> 0.28003432 | ... L51: =IFERROR(L50/L47,0) -> 0.26315789
B53: Retained Earnings | C53: =IFERROR(1-C51,0) -> 0.66895652 | D53: =IFERROR(1-D51,0) -> 0.69787006 | E53: =IFERROR(1-E51,0) -> 0.68033702 | F53: =IFERROR(1-F51,0) -> 0.76155392 | G53: =IFERROR(1-G51,0) -> 0.63449692 | H53: =IFERROR(1-H51,0) -> 0.69631483 | I53: =IFERROR(1-I51,0) -> 0.72816127 | J53: =IFERROR(1-J51,0) -> 0.71996568 | ... L53: =IFERROR(1-L51,0) -> 0.73684211
A55: # | B55: ="Balance Sheet"&" - "&'Data Sheet'!B1 -> Balance Sheet - TITAN COMPANY LTD
B56: Equity Share Capital | C56: =IFERROR('Data Sheet'!B57,0) -> 88.78 | D56: =IFERROR('Data Sheet'!C57,0) -> 88.78 | E56: =IFERROR('Data Sheet'!D57,0) -> 88.78 | F56: =IFERROR('Data Sheet'!E57,0) -> 89 | G56: =IFERROR('Data Sheet'!F57,0) -> 89 | H56: =IFERROR('Data Sheet'!G57,0) -> 89 | I56: =IFERROR('Data Sheet'!H57,0) -> 89 | J56: =IFERROR('Data Sheet'!I57,0) -> 89 | ... L56: =IFERROR('Data Sheet'!K57,0) -> 89
B57: Reserves | C57: =IFERROR('Data Sheet'!B58,0) -> 4143.6 | D57: =IFERROR('Data Sheet'!C58,0) -> 5001.1 | E57: =IFERROR('Data Sheet'!D58,0) -> 5981.37 | F57: =IFERROR('Data Sheet'!E58,0) -> 6580 | G57: =IFERROR('Data Sheet'!F58,0) -> 7408 | H57: =IFERROR('Data Sheet'!G58,0) -> 9214 | I57: =IFERROR('Data Sheet'!H58,0) -> 11762 | J57: =IFERROR('Data Sheet'!I58,0) -> 9304 | ... L57: =IFERROR('Data Sheet'!K58,0) -> 15614
B58: Borrowings | C58: =IFERROR('Data Sheet'!B59,0) -> 1882.43 | D58: =IFERROR('Data Sheet'!C59,0) -> 1691.01 | E58: =IFERROR('Data Sheet'!D59,0) -> 2392.98 | F58: =IFERROR('Data Sheet'!E59,0) -> 3562 | G58: =IFERROR('Data Sheet'!F59,0) -> 5638 | H58: =IFERROR('Data Sheet'!G59,0) -> 7275 | I58: =IFERROR('Data Sheet'!H59,0) -> 9367 | J58: =IFERROR('Data Sheet'!I59,0) -> 15528 | ... L58: =IFERROR('Data Sheet'!K59,0) -> 30621
B59: Trade Payables | C59: =IFERROR('Data Sheet'!B33,0) -> 783 | D59: =IFERROR('Data Sheet'!C33,0) -> 878 | E59: =IFERROR('Data Sheet'!D33,0) -> 906 | F59: =IFERROR('Data Sheet'!E33,0) -> 596 | G59: =IFERROR('Data Sheet'!F33,0) -> 789 | H59: =IFERROR('Data Sheet'!G33,0) -> 1294 | I59: =IFERROR('Data Sheet'!H33,0) -> 1214 | J59: =IFERROR('Data Sheet'!I33,0) -> 1410 | ... L59: =IFERROR('Data Sheet'!K33,0) -> 2864
B60: Other Liabilities | C60: =IFERROR('Data Sheet'!B60-'Data Sheet'!B33,0) -> 1509.76 | D60: =IFERROR('Data Sheet'!C60-'Data Sheet'!C33,0) -> 1862.15 | E60: =IFERROR('Data Sheet'!D60-'Data Sheet'!D33,0) -> 2340.71 | F60: =IFERROR('Data Sheet'!E60-'Data Sheet'!E33,0) -> 2717 | G60: =IFERROR('Data Sheet'!F60-'Data Sheet'!F33,0) -> 2520 | H60: =IFERROR('Data Sheet'!G60-'Data Sheet'!G33,0) -> 3316 | I60: =IFERROR('Data Sheet'!H60-'Data Sheet'!H33,0) -> 4588 | J60: =IFERROR('Data Sheet'!I60-'Data Sheet'!I33,0) -> 5216 | ... L60: =IFERROR('Data Sheet'!K60-'Data Sheet'!K33,0) -> 11373
B61: Total Liabilities | C61: =SUM(C56:C60) -> 8407.57 | D61: =SUM(D56:D60) -> 9521.04 | E61: =SUM(E56:E60) -> 11709.84 | F61: =SUM(F56:F60) -> 13544 | G61: =SUM(G56:G60) -> 16444 | H61: =SUM(H56:H60) -> 21188 | I61: =SUM(I56:I60) -> 27020 | J61: =SUM(J56:J60) -> 31547 | ... L61: =SUM(L56:L60) -> 60561
...

Sheet Ratio Analysis
B2: ="Ratio Analysis"&" - " &'Data Sheet'!B1 -> Ratio Analysis - TITAN COMPANY LTD
B3: Years | C3: =HistoricalFS!C5 -> 42825 | D3: =HistoricalFS!D5 -> 43190 | E3: =HistoricalFS!E5 -> 43555 | F3: =HistoricalFS!F5 -> 43921 | G3: =HistoricalFS!G5 -> 44286 | H3: =HistoricalFS!H5 -> 44651 | I3: =HistoricalFS!I5 -> 45016 | J3: =HistoricalFS!J5 -> 45382 | ... L3: =HistoricalFS!L5 -> 46112 | M3: Trend Line | N3: Average | O3: Median
B5: Sales Growth | D5: =HistoricalFS!D10 -> 0.21559284 | E5: =HistoricalFS!E10 -> 0.22697284 | F5: =HistoricalFS!F10 -> 0.064387022 | G5: =HistoricalFS!G10 -> 0.028120844 | H5: =HistoricalFS!H10 -> 0.3305766 | I5: =HistoricalFS!I10 -> 0.40890309 | J5: =HistoricalFS!J10 -> 0.25900185 | K5: =HistoricalFS!K10 -> 0.18346253 | L5: =HistoricalFS!L10 -> 0.44872304 | N5: =AVERAGE(D5:L5) -> 0.24063785 | O5: =MEDIAN(D5:L5) -> 0.22697284
B6: EBITDA Growth | D6: =HistoricalFS!D21/HistoricalFS!C21-1 -> 0.41266432 | E6: =HistoricalFS!E21/HistoricalFS!D21-1 -> 0.21262012 | F6: =HistoricalFS!F21/HistoricalFS!E21-1 -> 0.23533572 | G6: =HistoricalFS!G21/HistoricalFS!F21-1 -> -0.29963459 | H6: =HistoricalFS!H21/HistoricalFS!G21-1 -> 0.93855072 | I6: =HistoricalFS!I21/HistoricalFS!H21-1 -> 0.45992823 | J6: =HistoricalFS!J21/HistoricalFS!I21-1 -> 0.083981975 | K6: =HistoricalFS!K21/HistoricalFS!J21-1 -> 0.075963719 | L6: =HistoricalFS!L21/HistoricalFS!K21-1 -> 0.46768528 | N6: =AVERAGE(D6:L6) -> 0.28745505 | O6: =MEDIAN(D6:L6) -> 0.23533572
B7: EBIT Growth | D7: =HistoricalFS!D30/HistoricalFS!C30-1 -> 0.56549521 | E7: =HistoricalFS!E30/HistoricalFS!D30-1 -> 0.26962153 | F7: =HistoricalFS!F30/HistoricalFS!E30-1 -> 0.12867828 | G7: =HistoricalFS!G30/HistoricalFS!F30-1 -> -0.32539683 | H7: =HistoricalFS!H30/HistoricalFS!G30-1 -> 1.0405229 | I7: =HistoricalFS!I30/HistoricalFS!H30-1 -> 0.52049968 | J7: =HistoricalFS!J30/HistoricalFS!I30-1 -> 0.10427639 | K7: =HistoricalFS!K30/HistoricalFS!J30-1 -> 0.046928653 | L7: =HistoricalFS!L30/HistoricalFS!K30-1 -> 0.45426385 | N7: =AVERAGE(D7:L7) -> 0.3116544 | O7: =MEDIAN(D7:L7) -> 0.26962153
B8: Net Profit Growth | D8: =HistoricalFS!D42/HistoricalFS!C42-1 -> 0.58029773 | E8: =HistoricalFS!E42/HistoricalFS!D42-1 -> 0.26022089 | F8: =HistoricalFS!F42/HistoricalFS!E42-1 -> 0.075144925 | G8: =HistoricalFS!G42/HistoricalFS!F42-1 -> -0.34762224 | H8: =HistoricalFS!H42/HistoricalFS!G42-1 -> 1.2566735 | I8: =HistoricalFS!I42/HistoricalFS!H42-1 -> 0.48953594 | J8: =HistoricalFS!J42/HistoricalFS!I42-1 -> 0.067806964 | K8: =HistoricalFS!K42/HistoricalFS!J42-1 -> -0.045480549 | L8: =HistoricalFS!L42/HistoricalFS!K42-1 -> 0.52022775 | N8: =AVERAGE(D8:L8) -> 0.31742277 | O8: =MEDIAN(D8:L8) -> 0.26022089
B9: Dividend Growth | D9: =HistoricalFS!D50/HistoricalFS!C50-1 -> 0.44227353 | E9: =HistoricalFS!E50/HistoricalFS!D50-1 -> 0.33335336 | F9: =HistoricalFS!F50/HistoricalFS!E50-1 -> -0.19801757 | G9: =HistoricalFS!G50/HistoricalFS!F50-1 -> 0 | H9: =HistoricalFS!H50/HistoricalFS!G50-1 -> 0.875 | I9: =HistoricalFS!I50/HistoricalFS!H50-1 -> 0.33333333 | J9: =HistoricalFS!J50/HistoricalFS!I50-1 -> 0.1 | K9: =HistoricalFS!K50/HistoricalFS!J50-1 -> 0 | L9: =HistoricalFS!L50/HistoricalFS!K50-1 -> 0.36363636 | N9: =AVERAGE(D9:L9) -> 0.24995322 | O9: =MEDIAN(D9:L9) -> 0.33333333
B11: Gross Margins | C11: =HistoricalFS!C16 -> 0.20020014 | D11: =HistoricalFS!D16 -> 0.20826228 | E11: =HistoricalFS!E16 -> 0.20820769 | F11: =HistoricalFS!F16 -> 0.21024131 | G11: =HistoricalFS!G16 -> 0.18402329 | H11: =HistoricalFS!H16 -> 0.19354839 | I11: =HistoricalFS!I16 -> 0.20406654 | J11: =HistoricalFS!J16 -> 0.18440216 | ... L11: =HistoricalFS!L16 -> 0.16125091 | N11: =AVERAGE(C11:L11) -> 0.1926758 | O11: =MEDIAN(C11:L11) -> 0.19687426
B12: EBITDA Margins | C12: =HistoricalFS!C22 -> 0.08776977 | D12: =HistoricalFS!D22 -> 0.10199897 | E12: =HistoricalFS!E22 -> 0.10080582 | F12: =HistoricalFS!F22 -> 0.11699601 | G12: =HistoricalFS!G22 -> 0.079698762 | H12: =HistoricalFS!H22 -> 0.11611514 | I12: =HistoricalFS!I22 -> 0.12032039 | J12: =HistoricalFS!J22 -> 0.10359408 | ... L12: =HistoricalFS!L22 -> 0.095416971 | N12: =AVERAGE(C12:L12) -> 0.10169001 | O12: =MEDIAN(C12:L12) -> 0.1014024
B13: EBIT Margins | C13: =HistoricalFS!C31 -> 0.076238818 | D13: =HistoricalFS!D31 -> 0.098183783 | E13: =HistoricalFS!E31 -> 0.10159658 | F13: =HistoricalFS!F31 -> 0.10773323 | G13: =HistoricalFS!G31 -> 0.070689337 | H13: =HistoricalFS!H31 -> 0.10840654 | I13: =HistoricalFS!I31 -> 0.11699322 | J13: =HistoricalFS!J31 -> 0.1026153 | ... L13: =HistoricalFS!L31 -> 0.09112395 | N13: =AVERAGE(C13:L13) -> 0.096435753 | O13: =MEDIAN(C13:L13) -> 0.099890182
B14: EBT Margins | C14: =HistoricalFS!C37 -> 0.073392842 | D14: =HistoricalFS!D37 -> 0.094900858 | E14: =HistoricalFS!E37 -> 0.098940163 | F14: =HistoricalFS!F37 -> 0.099847995 | G14: =HistoricalFS!G37 -> 0.061310294 | H14: =HistoricalFS!H37 -> 0.10083683 | I14: =HistoricalFS!I37 -> 0.10959951 | J14: =HistoricalFS!J37 -> 0.090498003 | ... L14: =HistoricalFS!L37 -> 0.077651169 | N14: =AVERAGE(C14:L14) -> 0.08819909 | O14: =MEDIAN(C14:L14) -> 0.092699431
B15: Net Profit Margins | C15: =HistoricalFS!C43 -> 0.052581927 | D15: =HistoricalFS!D43 -> 0.068357675 | E15: =HistoricalFS!E43 -> 0.070210006 | F15: =HistoricalFS!F43 -> 0.070919628 | G15: =HistoricalFS!G43 -> 0.045000924 | H15: =HistoricalFS!H43 -> 0.076322095 | I15: =HistoricalFS!I43 -> 0.08069008 | J15: =HistoricalFS!J43 -> 0.068436301 | ... L15: =HistoricalFS!L43 -> 0.057921538 | N15: =AVERAGE(C15:L15) -> 0.064563734 | O15: =MEDIAN(C15:L15) -> 0.068396988
B17: S&E % of Sales | C17: =HistoricalFS!C19 -> 0.11243037 | D17: =HistoricalFS!D19 -> 0.1062633 | E17: =HistoricalFS!E19 -> 0.10740187 | F17: =HistoricalFS!F19 -> 0.093245297 | G17: =HistoricalFS!G19 -> 0.10432452 | H17: =HistoricalFS!H19 -> 0.077433244 | I17: =HistoricalFS!I19 -> 0.083746149 | J17: =HistoricalFS!J19 -> 0.080808081 | ... L17: =HistoricalFS!L19 -> 0.065833942 | N17: =AVERAGE(C17:L17) -> 0.090985782 | O17: =MEDIAN(C17:L17) -> 0.088495723
B18: Depreciation % of Sales | C18: =HistoricalFS!C28 -> 0.008335074 | D18: =HistoricalFS!D28 -> 0.0081533421 | E18: =HistoricalFS!E28 -> 0.0082331742 | F18: =HistoricalFS!F28 -> 0.016530496 | G18: =HistoricalFS!G28 -> 0.017325818 | H18: =HistoricalFS!H28 -> 0.013854648 | I18: =HistoricalFS!I28 -> 0.010868762 | J18: =HistoricalFS!J28 -> 0.011432151 | ... L18: =HistoricalFS!L28 -> 0.0094309463 | N18: =AVERAGE(C18:L18) -> 0.011562729 | O18: =MEDIAN(C18:L18) -> 0.011150456
B19: Operating Income % of Sales | C19: =C13 -> 0.076238818 | D19: =D13 -> 0.098183783 | E19: =E13 -> 0.10159658 | F19: =F13 -> 0.10773323 | G19: =G13 -> 0.070689337 | H19: =H13 -> 0.10840654 | I19: =I13 -> 0.11699322 | J19: =J13 -> 0.1026153 | ... L19: =L13 -> 0.09112395 | N19: =AVERAGE(C19:L19) -> 0.096435753 | O19: =MEDIAN(C19:L19) -> 0.099890182
B21: Return on capital employed | C21: =HistoricalFS!C30/SUM(HistoricalFS!C56:C58) -> 0.16533465 | D21: =HistoricalFS!D30/SUM(HistoricalFS!D56:D58) -> 0.23340594 | E21: =HistoricalFS!E30/SUM(HistoricalFS!E56:E58) -> 0.23743343 | F21: =HistoricalFS!F30/SUM(HistoricalFS!F56:F58) -> 0.22167921 | G21: =HistoricalFS!G30/SUM(HistoricalFS!G56:G58) -> 0.11648268 | H21: =HistoricalFS!H30/SUM(HistoricalFS!H56:H58) -> 0.18832187 | I21: =HistoricalFS!I30/SUM(HistoricalFS!I56:I58) -> 0.22372514 | J21: =HistoricalFS!J30/SUM(HistoricalFS!J56:J58) -> 0.21034469 | ... L21: =HistoricalFS!L30/SUM(HistoricalFS!L56:L58) -> 0.1722865 | N21: =AVERAGE(C21:L21) -> 0.19383916 | O21: =MEDIAN(C21:L21) -> 0.19933328
B22: Return on Equity % | C22: =HistoricalFS!C42/SUM(HistoricalFS!C56:C57) -> 0.16474891 | D22: =HistoricalFS!D42/SUM(HistoricalFS!D56:D57) -> 0.21649037 | E22: =HistoricalFS!E42/SUM(HistoricalFS!E56:E57) -> 0.228767 | F22: =HistoricalFS!F42/SUM(HistoricalFS!F56:F57) -> 0.22387164 | G22: =HistoricalFS!G42/SUM(HistoricalFS!G56:G57) -> 0.12991863 | H22: =HistoricalFS!H42/SUM(HistoricalFS!H56:H57) -> 0.23626787 | I22: =HistoricalFS!I42/SUM(HistoricalFS!I56:I57) -> 0.27626361 | J22: =HistoricalFS!J42/SUM(HistoricalFS!J56:J57) -> 0.37219206 | ... L22: =HistoricalFS!L42/SUM(HistoricalFS!L56:L57) -> 0.32305929 | N22: =AVERAGE(C22:L22) -> 0.24586578 | O22: =MEDIAN(C22:L22) -> 0.23251743
B23: Retained Earnings % | C23: =HistoricalFS!C53 -> 0.66895652 | D23: =HistoricalFS!D53 -> 0.69787006 | E23: =HistoricalFS!E53 -> 0.68033702 | F23: =HistoricalFS!F53 -> 0.76155392 | G23: =HistoricalFS!G53 -> 0.63449692 | H23: =HistoricalFS!H53 -> 0.69631483 | I23: =HistoricalFS!I53 -> 0.72816127 | J23: =HistoricalFS!J53 -> 0.71996568 | ... L23: =HistoricalFS!L53 -> 0.73684211 | N23: =AVERAGE(C23:L23) -> 0.7031121 | O23: =MEDIAN(C23:L23) -> 0.70224639
B24: Self Sustained Growth Rate | C24: =C22*C23 -> 0.11020986 | D24: =D22*D23 -> 0.15108215 | E24: =E22*E23 -> 0.15563866 | F24: =F22*F23 -> 0.17049033 | G24: =G22*G23 -> 0.082432973 | H24: =H22*H23 -> 0.16451682 | I24: =I22*I23 -> 0.20116446 | J24: =J22*J23 -> 0.26796551 | ... L24: =L22*L23 -> 0.23804369 | N24: =AVERAGE(C24:L24) -> 0.17444006 | O24: =MEDIAN(C24:L24) -> 0.16750358
B25: Interest Coverage Ratio | C25: =HistoricalFS!C30/HistoricalFS!C33 -> 26.788288 | D25: =HistoricalFS!D30/HistoricalFS!D33 -> 29.907407 | E25: =HistoricalFS!E30/HistoricalFS!E33 -> 38.245718 | F25: =HistoricalFS!F30/HistoricalFS!F33 -> 13.662651 | G25: =HistoricalFS!G30/HistoricalFS!G33 -> 7.5369458 | H25: =HistoricalFS!H30/HistoricalFS!H33 -> 14.321101 | I25: =HistoricalFS!I30/HistoricalFS!I33 -> 15.823333 | J25: =HistoricalFS!J30/HistoricalFS!J33 -> 8.4684976 | ... L25: =HistoricalFS!L30/HistoricalFS!L33 -> 6.7635593 | N25: =AVERAGE(C25:L25) -> 16.727616 | O25: =MEDIAN(C25:L25) -> 13.991876
B27: Debtor Turnover Ratio | C27: =HistoricalFS!C9/HistoricalFS!C69 -> 63.87683 | D27: =HistoricalFS!D9/HistoricalFS!D69 -> 54.515777 | E27: =HistoricalFS!E9/HistoricalFS!E69 -> 47.041313 | F27: =HistoricalFS!F9/HistoricalFS!F69 -> 67.474359 | G27: =HistoricalFS!G9/HistoricalFS!G69 -> 59.136612 | H27: =HistoricalFS!H9/HistoricalFS!H69 -> 50.971681 | I27: =HistoricalFS!I9/HistoricalFS!I69 -> 60.200297 | J27: =HistoricalFS!J9/HistoricalFS!J69 -> 50.180747 | ... L27: =HistoricalFS!L9/HistoricalFS!L69 -> 95.615721 | N27: =AVERAGE(C27:L27) -> 60.562008 | O27: =MEDIAN(C27:L27) -> 57.871677
B28: Creditor Turnover Ratio | C28: =HistoricalFS!C12/HistoricalFS!C59 -> 13.545351 | D28: =HistoricalFS!D12/HistoricalFS!D59 -> 14.536025 | E28: =HistoricalFS!E12/HistoricalFS!E59 -> 17.285298 | F28: =HistoricalFS!F12/HistoricalFS!F59 -> 27.895973 | G28: =HistoricalFS!G12/HistoricalFS!G59 -> 22.38403 | H28: =HistoricalFS!H12/HistoricalFS!H59 -> 17.948223 | I28: =HistoricalFS!I12/HistoricalFS!I59 -> 26.602142 | J28: =HistoricalFS!J12/HistoricalFS!J59 -> 29.548936 | ... L28: =HistoricalFS!L12/HistoricalFS!L59 -> 25.649791 | N28: =AVERAGE(C28:L28) -> 22.087921 | O28: =MEDIAN(C28:L28) -> 23.933737
B29: Inventory Turnover Ratio | C29: =HistoricalFS!C12/HistoricalFS!C70 -> 2.153181 | D29: =HistoricalFS!D12/HistoricalFS!D70 -> 2.1540885 | E29: =HistoricalFS!E12/HistoricalFS!E70 -> 2.2248729 | F29: =HistoricalFS!F12/HistoricalFS!F70 -> 2.0518327 | G29: =HistoricalFS!G12/HistoricalFS!G70 -> 2.1004995 | H29: =HistoricalFS!H12/HistoricalFS!H70 -> 1.7065912 | I29: =HistoricalFS!I12/HistoricalFS!I70 -> 1.9473589 | J29: =HistoricalFS!J12/HistoricalFS!J70 -> 2.1869718 | ... L29: =HistoricalFS!L12/HistoricalFS!L70 -> 1.7186674 | N29: =AVERAGE(C29:L29) -> 2.0018972 | O29: =MEDIAN(C29:L29) -> 2.0761661
B30: Fixed Asset Turnover Ratio | C30: =HistoricalFS!C9/HistoricalFS!C63 -> 11.155554 | D30: =HistoricalFS!D9/HistoricalFS!D63 -> 10.937482 | E30: =HistoricalFS!E9/HistoricalFS!E63 -> 12.624883 | F30: =HistoricalFS!F9/HistoricalFS!F63 -> 7.9954425 | G30: =HistoricalFS!G9/HistoricalFS!G63 -> 8.5786762 | H30: =HistoricalFS!H9/HistoricalFS!H63 -> 11.320362 | I30: =HistoricalFS!I9/HistoricalFS!I63 -> 13.534023 | J30: =HistoricalFS!J9/HistoricalFS!J63 -> 13.772985 | ... L30: =HistoricalFS!L9/HistoricalFS!L63 -> 12.733934 | N30: =AVERAGE(C30:L30) -> 11.753665 | O30: =MEDIAN(C30:L30) -> 11.972622
B31: Capital Turnover Ratio | C31: =HistoricalFS!C9/SUM(HistoricalFS!C56:C58) -> 2.1686414 | D31: =HistoricalFS!D9/SUM(HistoricalFS!D56:D58) -> 2.3772351 | E31: =HistoricalFS!E9/SUM(HistoricalFS!E56:E58) -> 2.3370219 | F31: =HistoricalFS!F9/SUM(HistoricalFS!F56:F58) -> 2.0576679 | G31: =HistoricalFS!G9/SUM(HistoricalFS!G56:G58) -> 1.6478112 | H31: =HistoricalFS!H9/SUM(HistoricalFS!H56:H58) -> 1.7371818 | I31: =HistoricalFS!I9/SUM(HistoricalFS!I56:I58) -> 1.9122915 | J31: =HistoricalFS!J9/SUM(HistoricalFS!J56:J58) -> 2.0498375 | ... L31: =HistoricalFS!L9/SUM(HistoricalFS!L56:L58) -> 1.890683 | N31: =AVERAGE(C31:L31) -> 2.004424 | O31: =MEDIAN(C31:L31) -> 1.9810645
B32: In Days
B33: Debtor Days | C33: =365/C27 -> 5.714122 | D33: =365/D27 -> 6.6953095 | E33: =365/E27 -> 7.7591372 | F33: =365/F27 -> 5.4094623 | G33: =365/G27 -> 6.1721493 | H33: =365/H27 -> 7.1608389 | I33: =365/I27 -> 6.063093 | J33: =365/J27 -> 7.2737061 | ... L33: =365/L27 -> 3.8173639 | N33: =AVERAGE(C33:L33) -> 6.2513177 | O33: =MEDIAN(C33:L33) -> 6.3100723
B34: Creditor Days | C34: =365/C28 -> 26.946514 | D34: =365/D28 -> 25.110028 | E34: =365/E28 -> 21.116211 | F34: =365/F28 -> 13.084326 | G34: =365/G28 -> 16.306268 | H34: =365/H28 -> 20.336276 | I34: =365/I28 -> 13.7207 | J34: =365/J28 -> 12.352391 | ... L34: =365/L28 -> 14.230136 | N34: =AVERAGE(C34:L34) -> 17.752587 | O34: =MEDIAN(C34:L34) -> 15.314646
B35: Inventory Days | C35: =365/C29 -> 169.51663 | D35: =365/D29 -> 169.44522 | E35: =365/E29 -> 164.05431 | F35: =365/F29 -> 177.88975 | G35: =365/G29 -> 173.76819 | H35: =365/H29 -> 213.87664 | I35: =365/I29 -> 187.43335 | J35: =365/J29 -> 166.89744 | ... L35: =365/L29 -> 212.37384 | N35: =AVERAGE(C35:L35) -> 184.08999 | O35: =MEDIAN(C35:L35) -> 175.82897
B36: Cash Conversion Cycle | C36: =SUM(C33,C35)-C34 -> 148.28424 | D36: =SUM(D33,D35)-D34 -> 151.0305 | E36: =SUM(E33,E35)-E34 -> 150.69724 | F36: =SUM(F33,F35)-F34 -> 170.21489 | G36: =SUM(G33,G35)-G34 -> 163.63407 | H36: =SUM(H33,H35)-H34 -> 200.7012 | I36: =SUM(I33,I35)-I34 -> 179.77574 | J36: =SUM(J33,J35)-J34 -> 161.81876 | ... L36: =SUM(L33,L35)-L34 -> 201.96107 | N36: =AVERAGE(C36:L36) -> 172.58872 | O36: =MEDIAN(C36:L36) -> 166.92448
B38: CFO/Sales | C38: =HistoricalFS!C89/HistoricalFS!C9 -> 0.12910202 | D38: =HistoricalFS!D89/HistoricalFS!D9 -> -0.0031638169 | E38: =HistoricalFS!E89/HistoricalFS!E9 -> 0.062845956 | F38: =HistoricalFS!F89/HistoricalFS!F9 -> -0.016530496 | G38: =HistoricalFS!G89/HistoricalFS!G9 -> 0.19123083 | H38: =HistoricalFS!H89/HistoricalFS!H9 -> -0.025139762 | I38: =HistoricalFS!I89/HistoricalFS!I9 -> 0.033764633 | J38: =HistoricalFS!J89/HistoricalFS!J9 -> 0.033180644 | ... L38: =HistoricalFS!L89/HistoricalFS!L9 -> 0.063824443 | N38: =AVERAGE(C38:L38) -> 0.04601658 | O38: =MEDIAN(C38:L38) -> 0.033472639
B39: CFO/Total Assets | C39: =HistoricalFS!C89/HistoricalFS!C74 -> 0.20362602 | D39: =HistoricalFS!D89/HistoricalFS!D74 -> -0.0053565577 | E39: =HistoricalFS!E89/HistoricalFS!E74 -> 0.10615004 | F39: =HistoricalFS!F89/HistoricalFS!F74 -> -0.025694034 | G39: =HistoricalFS!G89/HistoricalFS!G74 -> 0.25170275 | H39: =HistoricalFS!H89/HistoricalFS!H74 -> -0.034170285 | I39: =HistoricalFS!I89/HistoricalFS!I74 -> 0.050703183 | J39: =HistoricalFS!J89/HistoricalFS!J74 -> 0.053729356 | ... L39: =HistoricalFS!L89/HistoricalFS!L74 -> 0.092303628 | N39: =AVERAGE(C39:L39) -> 0.067968373 | O39: =MEDIAN(C39:L39) -> 0.05221627
B40: CFO/Total Debt | C40: =HistoricalFS!C89/HistoricalFS!C58 -> 0.90946277 | D40: =HistoricalFS!D89/HistoricalFS!D58 -> -0.03015949 | E40: =HistoricalFS!E89/HistoricalFS!E58 -> 0.51943602 | F40: =HistoricalFS!F89/HistoricalFS!F58 -> -0.097697923 | G40: =HistoricalFS!G89/HistoricalFS!G58 -> 0.73412558 | H40: =HistoricalFS!H89/HistoricalFS!H58 -> -0.0995189 | I40: =HistoricalFS!I89/HistoricalFS!I58 -> 0.14625814 | J40: =HistoricalFS!J89/HistoricalFS!J58 -> 0.10915765 | ... L40: =HistoricalFS!L89/HistoricalFS!L58 -> 0.18255446 | N40: =AVERAGE(C40:L40) -> 0.23475799 | O40: =MEDIAN(C40:L40) -> 0.1277079

Sheet Common Size Statement
B2: ="Common Size Income Statement"&" - "&'Data Sheet'!B1 -> Common Size Income Statement - TITAN COMPANY LTD
B4: Pariculars | C4: ='Data Sheet'!B16 -> 42825 | D4: ='Data Sheet'!C16 -> 43190 | E4: ='Data Sheet'!D16 -> 43555 | F4: ='Data Sheet'!E16 -> 43921 | G4: ='Data Sheet'!F16 -> 44286 | H4: ='Data Sheet'!G16 -> 44651 | I4: ='Data Sheet'!H16 -> 45016 | J4: ='Data Sheet'!I16 -> 45382 | ... L4: ='Data Sheet'!K16 -> 46112
B6: ='Data Sheet'!A17 -> Sales | C6: ='Data Sheet'!B17/'Data Sheet'!B17 -> 1 | D6: ='Data Sheet'!C17/'Data Sheet'!C17 -> 1 | E6: ='Data Sheet'!D17/'Data Sheet'!D17 -> 1 | F6: ='Data Sheet'!E17/'Data Sheet'!E17 -> 1 | G6: ='Data Sheet'!F17/'Data Sheet'!F17 -> 1 | H6: ='Data Sheet'!G17/'Data Sheet'!G17 -> 1 | I6: ='Data Sheet'!H17/'Data Sheet'!H17 -> 1 | J6: ='Data Sheet'!I17/'Data Sheet'!I17 -> 1 | ... L6: ='Data Sheet'!K17/'Data Sheet'!K17 -> 1
B7: ='Data Sheet'!A18 -> Raw Material Cost | C7: ='Data Sheet'!B18/'Data Sheet'!B$17 -> 0.74061277 | D7: ='Data Sheet'!C18/'Data Sheet'!C$17 -> 0.78567064 | E7: ='Data Sheet'!D18/'Data Sheet'!D$17 -> 0.76702706 | F7: ='Data Sheet'!E18/'Data Sheet'!E$17 -> 0.76159035 | G7: ='Data Sheet'!F18/'Data Sheet'!F$17 -> 0.75272593 | H7: ='Data Sheet'!G18/'Data Sheet'!G$17 -> 0.91794854 | I7: ='Data Sheet'!H18/'Data Sheet'!H$17 -> 0.8031793 | J7: ='Data Sheet'!I18/'Data Sheet'!I$17 -> 0.82419153 | ... L7: ='Data Sheet'!K18/'Data Sheet'!K$17 -> 0.91618332
B8: ='Data Sheet'!A19 -> Change in Inventory | C8: ='Data Sheet'!B19/'Data Sheet'!B$17 -> 0.02365689 | D8: ='Data Sheet'!C19/'Data Sheet'!C$17 -> 0.060708683 | E8: ='Data Sheet'!D19/'Data Sheet'!D$17 -> 0.039255212 | F8: ='Data Sheet'!E19/'Data Sheet'!E$17 -> 0.041706251 | G8: ='Data Sheet'!F19/'Data Sheet'!F$17 -> -0.0056366661 | H8: ='Data Sheet'!G19/'Data Sheet'!G$17 -> 0.16649884 | I8: ='Data Sheet'!H19/'Data Sheet'!H$17 -> 0.055058534 | J8: ='Data Sheet'!I19/'Data Sheet'!I$17 -> 0.05228643 | ... L8: ='Data Sheet'!K19/'Data Sheet'!K$17 -> 0.11344538
B9: ='Data Sheet'!A20 -> Power and Fuel | C9: ='Data Sheet'!B20/'Data Sheet'!B$17 -> 0.0033059771 | D9: ='Data Sheet'!C20/'Data Sheet'!C$17 -> 0.0028114545 | E9: ='Data Sheet'!D20/'Data Sheet'!D$17 -> 0.0024526608 | F9: ='Data Sheet'!E20/'Data Sheet'!E$17 -> 0.0024700741 | G9: ='Data Sheet'!F20/'Data Sheet'!F$17 -> 0.0017094807 | H9: ='Data Sheet'!G20/'Data Sheet'!G$17 -> 0.0015625543 | I9: ='Data Sheet'!H20/'Data Sheet'!H$17 -> 0.0014540974 | J9: ='Data Sheet'!I20/'Data Sheet'!I$17 -> 0.0013898677 | ... L9: ='Data Sheet'!K20/'Data Sheet'!K$17 -> 0.00099333212
B10: ='Data Sheet'!A21 -> Other Mfr. Exp | C10: ='Data Sheet'!B21/'Data Sheet'!B$17 -> 0.012097282 | D10: ='Data Sheet'!C21/'Data Sheet'!C$17 -> 0.007743907 | E10: ='Data Sheet'!D21/'Data Sheet'!D$17 -> 0.0097722175 | F10: ='Data Sheet'!E21/'Data Sheet'!E$17 -> 0.010212806 | G10: ='Data Sheet'!F21/'Data Sheet'!F$17 -> 0.0065145075 | H10: ='Data Sheet'!G21/'Data Sheet'!G$17 -> 0.0063543873 | I10: ='Data Sheet'!H21/'Data Sheet'!H$17 -> 0.0055452865 | J10: ='Data Sheet'!I21/'Data Sheet'!I$17 -> 0.0055986219 | ... L10: ='Data Sheet'!K21/'Data Sheet'!K$17 -> 0.0042816039
B11: ='Data Sheet'!A22 -> Employee Cost | C11: ='Data Sheet'!B22/'Data Sheet'!B$17 -> 0.067440726 | D11: ='Data Sheet'!C22/'Data Sheet'!C$17 -> 0.056220405 | E11: ='Data Sheet'!D22/'Data Sheet'!D$17 -> 0.051795584 | F11: ='Data Sheet'!E22/'Data Sheet'!E$17 -> 0.057191716 | G11: ='Data Sheet'!F22/'Data Sheet'!F$17 -> 0.049390131 | H11: ='Data Sheet'!G22/'Data Sheet'!G$17 -> 0.047084968 | I11: ='Data Sheet'!H22/'Data Sheet'!H$17 -> 0.040813309 | J11: ='Data Sheet'!I22/'Data Sheet'!I$17 -> 0.036704252 | ... L11: ='Data Sheet'!K22/'Data Sheet'!K$17 -> 0.030736208
B12: ='Data Sheet'!A23 -> Selling and admin | C12: ='Data Sheet'!B23/'Data Sheet'!B$17 -> 0.09133365 | D12: ='Data Sheet'!C23/'Data Sheet'!C$17 -> 0.079269741 | E12: ='Data Sheet'!D23/'Data Sheet'!D$17 -> 0.073530274 | F12: ='Data Sheet'!E23/'Data Sheet'!E$17 -> 0.069827095 | G12: ='Data Sheet'!F23/'Data Sheet'!F$17 -> 0.047542044 | H12: ='Data Sheet'!G23/'Data Sheet'!G$17 -> 0.058925657 | I12: ='Data Sheet'!H23/'Data Sheet'!H$17 -> 0.066913124 | J12: ='Data Sheet'!I23/'Data Sheet'!I$17 -> 0.063601128 | ... L12: ='Data Sheet'!K23/'Data Sheet'!K$17 -> 0.0477827
B13: ='Data Sheet'!A24 -> Other Expenses | C13: ='Data Sheet'!B24/'Data Sheet'!B$17 -> 0.021096719 | D13: ='Data Sheet'!C24/'Data Sheet'!C$17 -> 0.026993561 | E13: ='Data Sheet'!D24/'Data Sheet'!D$17 -> 0.033871594 | F13: ='Data Sheet'!E24/'Data Sheet'!E$17 -> 0.023418203 | G13: ='Data Sheet'!F24/'Data Sheet'!F$17 -> 0.05678248 | H13: ='Data Sheet'!G24/'Data Sheet'!G$17 -> 0.018507587 | I13: ='Data Sheet'!H24/'Data Sheet'!H$17 -> 0.016833025 | J13: ='Data Sheet'!I24/'Data Sheet'!I$17 -> 0.017206953 | ... L13: ='Data Sheet'!K24/'Data Sheet'!K$17 -> 0.018051242
B14: ='Data Sheet'!A25 -> Other Income | C14: ='Data Sheet'!B25/'Data Sheet'!B$17 -> -0.0031958784 | D14: ='Data Sheet'!C25/'Data Sheet'!C$17 -> 0.0043381512 | E14: ='Data Sheet'!D25/'Data Sheet'!D$17 -> 0.009023931 | F14: ='Data Sheet'!E25/'Data Sheet'!E$17 -> 0.007267718 | G14: ='Data Sheet'!F25/'Data Sheet'!F$17 -> 0.0083163925 | H14: ='Data Sheet'!G25/'Data Sheet'!G$17 -> 0.0061460467 | I14: ='Data Sheet'!H25/'Data Sheet'!H$17 -> 0.0075415896 | J14: ='Data Sheet'!I25/'Data Sheet'!I$17 -> 0.010453371 | ... L14: ='Data Sheet'!K25/'Data Sheet'!K$17 -> 0.0051379247
B15: ='Data Sheet'!A26 -> Depreciation | C15: ='Data Sheet'!B26/'Data Sheet'!B$17 -> 0.008335074 | D15: ='Data Sheet'!C26/'Data Sheet'!C$17 -> 0.0081533421 | E15: ='Data Sheet'!D26/'Data Sheet'!D$17 -> 0.0082331742 | F15: ='Data Sheet'!E26/'Data Sheet'!E$17 -> 0.016530496 | G15: ='Data Sheet'!F26/'Data Sheet'!F$17 -> 0.017325818 | H15: ='Data Sheet'!G26/'Data Sheet'!G$17 -> 0.013854648 | I15: ='Data Sheet'!H26/'Data Sheet'!H$17 -> 0.010868762 | J15: ='Data Sheet'!I26/'Data Sheet'!I$17 -> 0.011432151 | ... L15: ='Data Sheet'!K26/'Data Sheet'!K$17 -> 0.0094309463
B16: ='Data Sheet'!A27 -> Interest | C16: ='Data Sheet'!B27/'Data Sheet'!B$17 -> 0.0028459757 | D16: ='Data Sheet'!C27/'Data Sheet'!C$17 -> 0.0032829253 | E16: ='Data Sheet'!D27/'Data Sheet'!D$17 -> 0.0026564172 | F16: ='Data Sheet'!E27/'Data Sheet'!E$17 -> 0.0078852366 | G16: ='Data Sheet'!F27/'Data Sheet'!F$17 -> 0.0093790427 | H16: ='Data Sheet'!G27/'Data Sheet'!G$17 -> 0.0075697073 | I16: ='Data Sheet'!H27/'Data Sheet'!H$17 -> 0.0073937153 | J16: ='Data Sheet'!I27/'Data Sheet'!I$17 -> 0.012117297 | ... L16: ='Data Sheet'!K27/'Data Sheet'!K$17 -> 0.01347278
B17: ='Data Sheet'!A28 -> Profit before tax | C17: ='Data Sheet'!B28/'Data Sheet'!B$17 -> 0.073392842 | D17: ='Data Sheet'!C28/'Data Sheet'!C$17 -> 0.094900858 | E17: ='Data Sheet'!D28/'Data Sheet'!D$17 -> 0.098940163 | F17: ='Data Sheet'!E28/'Data Sheet'!E$17 -> 0.099847995 | G17: ='Data Sheet'!F28/'Data Sheet'!F$17 -> 0.061310294 | H17: ='Data Sheet'!G28/'Data Sheet'!G$17 -> 0.10083683 | I17: ='Data Sheet'!H28/'Data Sheet'!H$17 -> 0.10959951 | J17: ='Data Sheet'!I28/'Data Sheet'!I$17 -> 0.090498003 | ... L17: ='Data Sheet'!K28/'Data Sheet'!K$17 -> 0.077651169
B18: ='Data Sheet'!A29 -> Tax | C18: ='Data Sheet'!B29/'Data Sheet'!B$17 -> 0.020810915 | D18: ='Data Sheet'!C29/'Data Sheet'!C$17 -> 0.026543183 | E18: ='Data Sheet'!D29/'Data Sheet'!D$17 -> 0.028730158 | F18: ='Data Sheet'!E29/'Data Sheet'!E$17 -> 0.028928368 | G18: ='Data Sheet'!F29/'Data Sheet'!F$17 -> 0.01630937 | H18: ='Data Sheet'!G29/'Data Sheet'!G$17 -> 0.02451474 | I18: ='Data Sheet'!H29/'Data Sheet'!H$17 -> 0.028909427 | J18: ='Data Sheet'!I29/'Data Sheet'!I$17 -> 0.022061702 | ... L18: ='Data Sheet'!K29/'Data Sheet'!K$17 -> 0.019729631
... B20: ='Data Sheet'!A31 -> Dividend Amount | C20: ='Data Sheet'!B31/'Data Sheet'!B$17 -> 0.017406904 | D20: ='Data Sheet'!C31/'Data Sheet'!C$17 -> 0.0206529 | E20: ='Data Sheet'!D31/'Data Sheet'!D$17 -> 0.02244354 | F20: ='Data Sheet'!E31/'Data Sheet'!E$17 -> 0.016910507 | G20: ='Data Sheet'!F31/'Data Sheet'!F$17 -> 0.016447976 | H20: ='Data Sheet'!G31/'Data Sheet'!G$17 -> 0.023177888 | I20: ='Data Sheet'!H31/'Data Sheet'!H$17 -> 0.021934689 | J20: ='Data Sheet'!I31/'Data Sheet'!I$17 -> 0.019164513 | ... L20: ='Data Sheet'!K31/'Data Sheet'!K$17 -> 0.01524251
B21: ='Data Sheet'!A34 -> EBITDA | C21: ='Data Sheet'!B34/'Data Sheet'!B$17 -> 0.08776977 | D21: ='Data Sheet'!C34/'Data Sheet'!C$17 -> 0.10199897 | E21: ='Data Sheet'!D34/'Data Sheet'!D$17 -> 0.10080582 | F21: ='Data Sheet'!E34/'Data Sheet'!E$17 -> 0.11699601 | G21: ='Data Sheet'!F34/'Data Sheet'!F$17 -> 0.079698762 | H21: ='Data Sheet'!G34/'Data Sheet'!G$17 -> 0.11611514 | I21: ='Data Sheet'!H34/'Data Sheet'!H$17 -> 0.12032039 | J21: ='Data Sheet'!I34/'Data Sheet'!I$17 -> 0.10359408 | ... L21: ='Data Sheet'!K34/'Data Sheet'!K$17 -> 0.095416971
B23: ="Common Size Balance Sheet Statement"&" - "&'Data Sheet'!B1 -> Common Size Balance Sheet Statement - TITAN COMPANY LTD
B25: Pariculars | C25: =C4 -> 42825 | D25: =D4 -> 43190 | E25: =E4 -> 43555 | F25: =F4 -> 43921 | G25: =G4 -> 44286 | H25: =H4 -> 44651 | I25: =I4 -> 45016 | J25: =J4 -> 45382 | ... L25: =L4 -> 46112
B27: Total Liabilities | C27: ='Data Sheet'!B61/'Data Sheet'!B61 -> 1 | D27: ='Data Sheet'!C61/'Data Sheet'!C61 -> 1 | E27: ='Data Sheet'!D61/'Data Sheet'!D61 -> 1 | F27: ='Data Sheet'!E61/'Data Sheet'!E61 -> 1 | G27: ='Data Sheet'!F61/'Data Sheet'!F61 -> 1 | H27: ='Data Sheet'!G61/'Data Sheet'!G61 -> 1 | I27: ='Data Sheet'!H61/'Data Sheet'!H61 -> 1 | J27: ='Data Sheet'!I61/'Data Sheet'!I61 -> 1 | ... L27: ='Data Sheet'!K61/'Data Sheet'!K61 -> 1
B28: ='Data Sheet'!A57 -> Equity Share Capital | C28: ='Data Sheet'!B57/'Data Sheet'!B$61 -> 0.010559531 | D28: ='Data Sheet'!C57/'Data Sheet'!C$61 -> 0.0093246116 | E28: ='Data Sheet'!D57/'Data Sheet'!D$61 -> 0.0075816578 | F28: ='Data Sheet'!E57/'Data Sheet'!E$61 -> 0.0065711754 | G28: ='Data Sheet'!F57/'Data Sheet'!F$61 -> 0.0054123084 | H28: ='Data Sheet'!G57/'Data Sheet'!G$61 -> 0.0042004908 | I28: ='Data Sheet'!H57/'Data Sheet'!H$61 -> 0.0032938564 | J28: ='Data Sheet'!I57/'Data Sheet'!I$61 -> 0.0028211874 | ... L28: ='Data Sheet'!K57/'Data Sheet'!K$61 -> 0.0014695926
B29: ='Data Sheet'!A58 -> Reserves | C29: ='Data Sheet'!B58/'Data Sheet'!B$61 -> 0.49284157 | D29: ='Data Sheet'!C58/'Data Sheet'!C$61 -> 0.52526825 | E29: ='Data Sheet'!D58/'Data Sheet'!D$61 -> 0.51079861 | F29: ='Data Sheet'!E58/'Data Sheet'!E$61 -> 0.48582398 | G29: ='Data Sheet'!F58/'Data Sheet'!F$61 -> 0.45049866 | H29: ='Data Sheet'!G58/'Data Sheet'!G$61 -> 0.43486879 | I29: ='Data Sheet'!H58/'Data Sheet'!H$61 -> 0.43530718 | J29: ='Data Sheet'!I58/'Data Sheet'!I$61 -> 0.29492503 | ... L29: ='Data Sheet'!K58/'Data Sheet'!K$61 -> 0.25782269
B30: ='Data Sheet'!A59 -> Borrowings | C30: ='Data Sheet'!B59/'Data Sheet'!B$61 -> 0.22389704 | D30: ='Data Sheet'!C59/'Data Sheet'!C$61 -> 0.1776077 | E30: ='Data Sheet'!D59/'Data Sheet'!D$61 -> 0.20435634 | F30: ='Data Sheet'!E59/'Data Sheet'!E$61 -> 0.26299468 | G30: ='Data Sheet'!F59/'Data Sheet'!F$61 -> 0.34286062 | H30: ='Data Sheet'!G59/'Data Sheet'!G$61 -> 0.34335473 | I30: ='Data Sheet'!H59/'Data Sheet'!H$61 -> 0.34666913 | J30: ='Data Sheet'!I59/'Data Sheet'!I$61 -> 0.49221796 | ... L30: ='Data Sheet'!K59/'Data Sheet'!K$61 -> 0.50562243
B31: ='Data Sheet'!A33 -> Trade Payables | C31: ='Data Sheet'!B33/'Data Sheet'!B$61 -> 0.093130358 | D31: ='Data Sheet'!C33/'Data Sheet'!C$61 -> 0.092216817 | E31: ='Data Sheet'!D33/'Data Sheet'!D$61 -> 0.077370827 | F31: ='Data Sheet'!E33/'Data Sheet'!E$61 -> 0.044004725 | G31: ='Data Sheet'!F33/'Data Sheet'!F$61 -> 0.047981027 | H31: ='Data Sheet'!G33/'Data Sheet'!G$61 -> 0.061072305 | I31: ='Data Sheet'!H33/'Data Sheet'!H$61 -> 0.044929682 | J31: ='Data Sheet'!I33/'Data Sheet'!I$61 -> 0.044695217 | ... L31: ='Data Sheet'!K33/'Data Sheet'!K$61 -> 0.047291161
B32: ='Data Sheet'!A60 -> Other Liabilities | C32: =('Data Sheet'!B60-'Data Sheet'!B33)/'Data Sheet'!B$61 -> 0.17957151 | D32: =('Data Sheet'!C60-'Data Sheet'!C33)/'Data Sheet'!C$61 -> 0.19558263 | E32: =('Data Sheet'!D60-'Data Sheet'!D33)/'Data Sheet'!D$61 -> 0.19989257 | F32: =('Data Sheet'!E60-'Data Sheet'!E33)/'Data Sheet'!E$61 -> 0.20060543 | G32: =('Data Sheet'!F60-'Data Sheet'!F33)/'Data Sheet'!F$61 -> 0.15324739 | H32: =('Data Sheet'!G60-'Data Sheet'!G33)/'Data Sheet'!G$61 -> 0.15650368 | I32: =('Data Sheet'!H60-'Data Sheet'!H33)/'Data Sheet'!H$61 -> 0.16980015 | J32: =('Data Sheet'!I60-'Data Sheet'!I33)/'Data Sheet'!I$61 -> 0.1653406 | ... L32: =('Data Sheet'!K60-'Data Sheet'!K33)/'Data Sheet'!K$61 -> 0.18779412
B34: Total Assets | C34: ='Data Sheet'!B66/'Data Sheet'!B66 -> 1 | D34: ='Data Sheet'!C66/'Data Sheet'!C66 -> 1 | E34: ='Data Sheet'!D66/'Data Sheet'!D66 -> 1 | F34: ='Data Sheet'!E66/'Data Sheet'!E66 -> 1 | G34: ='Data Sheet'!F66/'Data Sheet'!F66 -> 1 | H34: ='Data Sheet'!G66/'Data Sheet'!G66 -> 1 | I34: ='Data Sheet'!H66/'Data Sheet'!H66 -> 1 | J34: ='Data Sheet'!I66/'Data Sheet'!I66 -> 1 | ... L34: ='Data Sheet'!K66/'Data Sheet'!K66 -> 1
B35: ='Data Sheet'!A62 -> Net Block | C35: ='Data Sheet'!B62/'Data Sheet'!B$61 -> 0.14138687 | D35: ='Data Sheet'!C62/'Data Sheet'!C$61 -> 0.15479506 | E35: ='Data Sheet'!D62/'Data Sheet'!D$61 -> 0.13378748 | F35: ='Data Sheet'!E62/'Data Sheet'!E$61 -> 0.19440343 | G35: ='Data Sheet'!F62/'Data Sheet'!F$61 -> 0.15342982 | H35: ='Data Sheet'!G62/'Data Sheet'!G$61 -> 0.12006796 | I35: ='Data Sheet'!H62/'Data Sheet'!H$61 -> 0.11095485 | J35: ='Data Sheet'!I62/'Data Sheet'!I$61 -> 0.11757061 | ... L35: ='Data Sheet'!K62/'Data Sheet'!K$61 -> 0.11357144
B36: ='Data Sheet'!A63 -> Capital Work in Progress | C36: ='Data Sheet'!B63/'Data Sheet'!B$61 -> 0.018087271 | D36: ='Data Sheet'!C63/'Data Sheet'!C$61 -> 0.0045551746 | E36: ='Data Sheet'!D63/'Data Sheet'!D$61 -> 0.0027131028 | F36: ='Data Sheet'!E63/'Data Sheet'!E$61 -> 0.0013290018 | G36: ='Data Sheet'!F63/'Data Sheet'!F$61 -> 0.0019459985 | H36: ='Data Sheet'!G63/'Data Sheet'!G$61 -> 0.0040117047 | I36: ='Data Sheet'!H63/'Data Sheet'!H$61 -> 0.0053293856 | J36: ='Data Sheet'!I63/'Data Sheet'!I$61 -> 0.0030747773 | ... L36: ='Data Sheet'!K63/'Data Sheet'!K$61 -> 0.0026915011
B37: ='Data Sheet'!A64 -> Investments | C37: ='Data Sheet'!B64/'Data Sheet'!B$61 -> 0.051231212 | D37: ='Data Sheet'!C64/'Data Sheet'!C$61 -> 0.0037800492 | E37: ='Data Sheet'!D64/'Data Sheet'!D$61 -> 0.0092588797 | F37: ='Data Sheet'!E64/'Data Sheet'!E$61 -> 0.011665682 | G37: ='Data Sheet'!F64/'Data Sheet'!F$61 -> 0.17173437 | H37: ='Data Sheet'!G64/'Data Sheet'!G$61 -> 0.013875779 | I37: ='Data Sheet'!H64/'Data Sheet'!H$61 -> 0.093079201 | J37: ='Data Sheet'!I64/'Data Sheet'!I$61 -> 0.074333534 | ... L37: ='Data Sheet'!K64/'Data Sheet'!K$61 -> 0.057892043
B38: ='Data Sheet'!A65 -> Other Assets | C38: ='Data Sheet'!B74/'Data Sheet'!B$66 -> 0.086086705 | D38: ='Data Sheet'!C74/'Data Sheet'!C$66 -> 0.11862465 | E38: ='Data Sheet'!D74/'Data Sheet'!D$66 -> 0.12615629 | F38: ='Data Sheet'!E74/'Data Sheet'!E$66 -> 0.14316302 | G38: ='Data Sheet'!F74/'Data Sheet'!F$66 -> 0.10526636 | H38: ='Data Sheet'!G74/'Data Sheet'!G$66 -> 0.11884085 | I38: ='Data Sheet'!H74/'Data Sheet'!H$66 -> 0.10222058 | J38: ='Data Sheet'!I74/'Data Sheet'!I$66 -> 0.12048689 | ... L38: ='Data Sheet'!K74/'Data Sheet'!K$66 -> 0.073281485
B39: ='Data Sheet'!A67 -> Receivables | C39: ='Data Sheet'!B67/'Data Sheet'!B$61 -> 0.024692033 | D39: ='Data Sheet'!C67/'Data Sheet'!C$61 -> 0.031056481 | E39: ='Data Sheet'!D67/'Data Sheet'!D$61 -> 0.0359057 | F39: ='Data Sheet'!E67/'Data Sheet'!E$61 -> 0.023036031 | G39: ='Data Sheet'!F67/'Data Sheet'!F$61 -> 0.022257358 | H39: ='Data Sheet'!G67/'Data Sheet'!G$61 -> 0.026666037 | I39: ='Data Sheet'!H67/'Data Sheet'!H$61 -> 0.024944486 | J39: ='Data Sheet'!I67/'Data Sheet'!I$61 -> 0.032269312 | ... L39: ='Data Sheet'!K67/'Data Sheet'!K$61 -> 0.015125246
B40: ='Data Sheet'!A68 -> Inventory | C40: ='Data Sheet'!B68/'Data Sheet'!B$61 -> 0.58586964 | D40: ='Data Sheet'!C68/'Data Sheet'!C$61 -> 0.62228916 | E40: ='Data Sheet'!D68/'Data Sheet'!D$61 -> 0.601103 | F40: ='Data Sheet'!E68/'Data Sheet'!E$61 -> 0.5982723 | G40: ='Data Sheet'!F68/'Data Sheet'!F$61 -> 0.51131112 | H40: ='Data Sheet'!G68/'Data Sheet'!G$61 -> 0.64229753 | I40: ='Data Sheet'!H68/'Data Sheet'!H$61 -> 0.61376758 | J40: ='Data Sheet'!I68/'Data Sheet'!I$61 -> 0.6038926 | ... L40: ='Data Sheet'!K68/'Data Sheet'!K$61 -> 0.70578425
B41: ='Data Sheet'!A69 -> Cash & Bank | C41: ='Data Sheet'!B69/'Data Sheet'!B$61 -> 0.09264627 | D41: ='Data Sheet'!C69/'Data Sheet'!C$61 -> 0.064899423 | E41: ='Data Sheet'!D69/'Data Sheet'!D$61 -> 0.09107554 | F41: ='Data Sheet'!E69/'Data Sheet'!E$61 -> 0.028130538 | G41: ='Data Sheet'!F69/'Data Sheet'!F$61 -> 0.034054974 | H41: ='Data Sheet'!G69/'Data Sheet'!G$61 -> 0.074240136 | I41: ='Data Sheet'!H69/'Data Sheet'!H$61 -> 0.049703923 | J41: ='Data Sheet'!I69/'Data Sheet'!I$61 -> 0.04837227 | ... L41: ='Data Sheet'!K69/'Data Sheet'!K$61 -> 0.031654035

Sheet Assumptions Sheet
B2: ="Assumption Sheet"&" - "&'Data Sheet'!B1 -> Assumption Sheet - TITAN COMPANY LTD
B4: 1. P & L Drivers
B5: Years | C5: ='Data Sheet'!F56 -> 44286 | D5: ='Data Sheet'!G56 -> 44651 | E5: ='Data Sheet'!H56 -> 45016 | F5: ='Data Sheet'!I56 -> 45382 | G5: ='Data Sheet'!J56 -> 45747 | H5: ='Data Sheet'!K56 -> 46112 | I5: =H5+365 -> 46477 | J5: =I5+365 -> 46842 | K5: =J5+365 -> 47207 | L5: =K5+365 -> 47572 | M5: =L5+365 -> 47937
B7: =HistoricalFS!B10 -> Sales Growth | C7: =HistoricalFS!G10 -> 0.028120844 | D7: =HistoricalFS!H10 -> 0.3305766 | E7: =HistoricalFS!I10 -> 0.40890309 | F7: =HistoricalFS!J10 -> 0.25900185 | G7: =HistoricalFS!K10 -> 0.18346253 | H7: =HistoricalFS!L10 -> 0.44872304 | I7: =IF($C$39="Bull",I42,I41) -> 0.18 | J7: =IF($C$39="Bull",J42,J41) -> 0.16 | K7: =IF($C$39="Bull",K42,K41) -> 0.15 | L7: =IF($C$39="Bull",L42,L41) -> 0.14 | M7: =IF($C$39="Bull",M42,M41) -> 0.13
B8: =HistoricalFS!B13 -> COGS % of Sales | C8: =HistoricalFS!G13 -> 0.81597671 | D8: =HistoricalFS!H13 -> 0.80645161 | E8: =HistoricalFS!I13 -> 0.79593346 | F8: =HistoricalFS!J13 -> 0.81559784 | G8: =HistoricalFS!K13 -> 0.82744475 | H8: =HistoricalFS!L13 -> 0.83874909 | I8: =IF($C$39="Bull",I44,I43) -> 0.835 | J8: =IF($C$39="Bull",J44,J43) -> 0.83 | K8: =IF($C$39="Bull",K44,K43) -> 0.825 | L8: =IF($C$39="Bull",L44,L43) -> 0.82 | M8: =IF($C$39="Bull",M44,M43) -> 0.815
B9: =HistoricalFS!B16 -> Gross Margins | C9: =HistoricalFS!G16 -> 0.18402329 | D9: =HistoricalFS!H16 -> 0.19354839 | E9: =HistoricalFS!I16 -> 0.20406654 | F9: =HistoricalFS!J16 -> 0.18440216 | G9: =HistoricalFS!K16 -> 0.17255525 | H9: =HistoricalFS!L16 -> 0.16125091 | I9: =1-I8 -> 0.165 | J9: =1-J8 -> 0.17 | K9: =1-K8 -> 0.175 | L9: =1-L8 -> 0.18 | M9: =1-M8 -> 0.185
B10: =HistoricalFS!B19 -> S&G % of Sales | C10: =HistoricalFS!G19 -> 0.10432452 | D10: =HistoricalFS!H19 -> 0.077433244 | E10: =HistoricalFS!I19 -> 0.083746149 | F10: =HistoricalFS!J19 -> 0.080808081 | G10: =HistoricalFS!K19 -> 0.078371047 | H10: =HistoricalFS!L19 -> 0.065833942 | I10: =IF($C$39="Bull",I46,I45) -> 0.064 | J10: =IF($C$39="Bull",J46,J45) -> 0.062 | K10: =IF($C$39="Bull",K46,K45) -> 0.06 | L10: =IF($C$39="Bull",L46,L45) -> 0.059 | M10: =IF($C$39="Bull",M46,M45) -> 0.058
B11: =HistoricalFS!B22 -> EBITDA Margins | C11: =HistoricalFS!G22 -> 0.079698762 | D11: =HistoricalFS!H22 -> 0.11611514 | E11: =HistoricalFS!I22 -> 0.12032039 | F11: =HistoricalFS!J22 -> 0.10359408 | G11: =HistoricalFS!K22 -> 0.0941842 | H11: =HistoricalFS!L22 -> 0.095416971 | I11: =I9-I10 -> 0.101 | J11: =J9-J10 -> 0.108 | K11: =K9-K10 -> 0.115 | L11: =L9-L10 -> 0.121 | M11: =M9-M10 -> 0.127
B12: Other Income (Crs) | C12: =HistoricalFS!G24 -> 180 | D12: =HistoricalFS!H24 -> 177 | E12: =HistoricalFS!I24 -> 306 | F12: =HistoricalFS!J24 -> 534 | G12: =HistoricalFS!K24 -> 487 | H12: =HistoricalFS!L24 -> 450 | I12: =H12*(1+0.1) -> 495 | J12: =I12*(1+0.1) -> 544.5 | K12: =J12*(1+0.1) -> 598.95 | L12: =K12*(1+0.1) -> 658.845 | M12: =L12*(1+0.1) -> 724.7295
B13: Depreciation (Crs) | C13: =HistoricalFS!G27 -> 375 | D13: =HistoricalFS!H27 -> 399 | E13: =HistoricalFS!I27 -> 441 | F13: =HistoricalFS!J27 -> 584 | G13: =HistoricalFS!K27 -> 693 | H13: =HistoricalFS!L27 -> 826 | I13: =H13*(1+0.15) -> 949.9 | J13: =I13*(1+0.15) -> 1092.385 | K13: =J13*(1+0.15) -> 1256.2427 | L13: =K13*(1+0.15) -> 1444.6792 | M13: =L13*(1+0.15) -> 1661.381
