Workbook

Sheet Financial>

Sheet HistoricalFS
B2: ="Historical Financial Statement"&" - "&'Data Sheet'!B1 -> Historical Financial Statement - MARUTI SUZUKI INDIA LTD
B3: Years | C3: ='Data Sheet'!B16 -> 42825 | D3: ='Data Sheet'!C16 -> 43190 | E3: ='Data Sheet'!D16 -> 43555 | F3: ='Data Sheet'!E16 -> 43921 | G3: ='Data Sheet'!F16 -> 44286 | H3: ='Data Sheet'!G16 -> 44651 | I3: ='Data Sheet'!H16 -> 45016 | J3: ='Data Sheet'!I16 -> 45382 | ... L3: ='Data Sheet'!K16 -> 46112 | M3: LTM
A5: # | B5: Income Statement
B6: Sales | C6: =IFERROR('Data Sheet'!B17,0) -> 68085 | D6: =IFERROR('Data Sheet'!C17,0) -> 79809.4 | E6: =IFERROR('Data Sheet'!D17,0) -> 86068.5 | F6: =IFERROR('Data Sheet'!E17,0) -> 75660 | G6: =IFERROR('Data Sheet'!F17,0) -> 70372 | H6: =IFERROR('Data Sheet'!G17,0) -> 88329.8 | I6: =IFERROR('Data Sheet'!H17,0) -> 117571.3 | J6: =IFERROR('Data Sheet'!I17,0) -> 141858.2 | ... L6: =IFERROR('Data Sheet'!K17,0) -> 183316 | M6: =IFERROR(SUM('Data Sheet'!H42:K42),0) -> 183316
B7: Sales Growth | D7: =IFERROR(D6/C6-1,0) -> 0.17220239 | E7: =IFERROR(E6/D6-1,0) -> 0.078425599 | F7: =IFERROR(F6/E6-1,0) -> -0.12093275 | G7: =IFERROR(G6/F6-1,0) -> -0.06989162 | H7: =IFERROR(H6/G6-1,0) -> 0.25518388 | I7: =IFERROR(I6/H6-1,0) -> 0.33104909 | J7: =IFERROR(J6/I6-1,0) -> 0.20657167 | K7: =IFERROR(K6/J6-1,0) -> 0.077928523 | ... M7: =IFERROR(M6/L6-1,0) -> 0
B9: COGS | C9: =IFERROR(SUM('Data Sheet'!B18,'Data Sheet'!B20:B22)-1*'Data Sheet'!B19,0) -> 50004 | D9: =IFERROR(SUM('Data Sheet'!C18,'Data Sheet'!C20:C22)-1*'Data Sheet'!C19,0) -> 58985 | E9: =IFERROR(SUM('Data Sheet'!D18,'Data Sheet'!D20:D22)-1*'Data Sheet'!D19,0) -> 64182.2 | F9: =IFERROR(SUM('Data Sheet'!E18,'Data Sheet'!E20:E22)-1*'Data Sheet'!E19,0) -> 57657.1 | G9: =IFERROR(SUM('Data Sheet'!F18,'Data Sheet'!F20:F22)-1*'Data Sheet'!F19,0) -> 55415.6 | H9: =IFERROR(SUM('Data Sheet'!G18,'Data Sheet'!G20:G22)-1*'Data Sheet'!G19,0) -> 71578.8 | I9: =IFERROR(SUM('Data Sheet'!H18,'Data Sheet'!H20:H22)-1*'Data Sheet'!H19,0) -> 92796.1 | J9: =IFERROR(SUM('Data Sheet'!I18,'Data Sheet'!I20:I22)-1*'Data Sheet'!I19,0) -> 108015.2 | ... L9: =IFERROR(SUM('Data Sheet'!K18,'Data Sheet'!K20:K22)-1*'Data Sheet'!K19,0) -> 141625.2 | M9: =IFERROR(SUM('Data Sheet'!H43:K43),0) -> 161876
B10: COGS % Sales | C10: =IFERROR(C9/C6,0) -> 0.7344349 | D10: =IFERROR(D9/D6,0) -> 0.73907334 | E10: =IFERROR(E9/E6,0) -> 0.74571068 | F10: =IFERROR(F9/F6,0) -> 0.76205525 | G10: =IFERROR(G9/G6,0) -> 0.78746661 | H10: =IFERROR(H9/H6,0) -> 0.81035845 | I10: =IFERROR(I9/I6,0) -> 0.7892751 | J10: =IFERROR(J9/J6,0) -> 0.76143078 | ... M10: =IFERROR(M9/M6,0) -> 0.88304349
B12: Gross Profit | C12: =IFERROR(C6-C9,0) -> 18081 | D12: =IFERROR(D6-D9,0) -> 20824.4 | E12: =IFERROR(E6-E9,0) -> 21886.3 | F12: =IFERROR(F6-F9,0) -> 18002.9 | G12: =IFERROR(G6-G9,0) -> 14956.4 | H12: =IFERROR(H6-H9,0) -> 16751 | I12: =IFERROR(I6-I9,0) -> 24775.2 | J12: =IFERROR(J6-J9,0) -> 33843 | ... M12: =IFERROR(M6-M9,0) -> 21440
B13: Gross Margin | C13: =IFERROR(C12/C6,0) -> 0.2655651 | D13: =IFERROR(D12/D6,0) -> 0.26092666 | E13: =IFERROR(E12/E6,0) -> 0.25428932 | F13: =IFERROR(F12/F6,0) -> 0.23794475 | G13: =IFERROR(G12/G6,0) -> 0.21253339 | H13: =IFERROR(H12/H6,0) -> 0.18964155 | I13: =IFERROR(I12/I6,0) -> 0.2107249 | J13: =IFERROR(J12/J6,0) -> 0.23856922 | ... M13: =IFERROR(M12/M6,0) -> 0.11695651
B15: Selling & General Expenses | C15: =IFERROR(SUM('Data Sheet'!B23:B24),0) -> 7659.7 | D15: =IFERROR(SUM('Data Sheet'!C23:C24),0) -> 8706.5 | E15: =IFERROR(SUM('Data Sheet'!D23:D24),0) -> 10830 | F15: =IFERROR(SUM('Data Sheet'!E23:E24),0) -> 10647.9 | G15: =IFERROR(SUM('Data Sheet'!F23:F24),0) -> 9545.8 | H15: =IFERROR(SUM('Data Sheet'!G23:G24),0) -> 10999 | I15: =IFERROR(SUM('Data Sheet'!H23:H24),0) -> 13746 | J15: =IFERROR(SUM('Data Sheet'!I23:I24),0) -> 15216.7 | ... M15: =IFERROR(SUM('Data Sheet'!L23:L24),0) -> 0
B16: S&G Exp % Sales | C16: =IFERROR(C15/C6,0) -> 0.11250202 | D16: =IFERROR(D15/D6,0) -> 0.10909116 | E16: =IFERROR(E15/E6,0) -> 0.12583001 | F16: =IFERROR(F15/F6,0) -> 0.14073354 | G16: =IFERROR(G15/G6,0) -> 0.1356477 | H16: =IFERROR(H15/H6,0) -> 0.12452196 | I16: =IFERROR(I15/I6,0) -> 0.11691629 | J16: =IFERROR(J15/J6,0) -> 0.10726698 | ... M16: =IFERROR(M15/M6,0) -> 0
B18: EBITDA | C18: =IFERROR(C12-C15,0) -> 10421.3 | D18: =IFERROR(D12-D15,0) -> 12117.9 | E18: =IFERROR(E12-E15,0) -> 11056.3 | F18: =IFERROR(F12-F15,0) -> 7355 | G18: =IFERROR(G12-G15,0) -> 5410.6 | H18: =IFERROR(H12-H15,0) -> 5752 | I18: =IFERROR(I12-I15,0) -> 11029.2 | J18: =IFERROR(J12-J15,0) -> 18626.3 | ... L18: =IFERROR(L12-L15,0) -> 21456.2 | M18: =IFERROR(SUM('Data Sheet'!H50:K50,'Data Sheet'!H45:K45),0) -> 28181.7
B19: EBITDA Margin | C19: =IFERROR(C18/C6,0) -> 0.15306308 | D19: =IFERROR(D18/D6,0) -> 0.1518355 | E19: =IFERROR(E18/E6,0) -> 0.12845931 | F19: =IFERROR(F18/F6,0) -> 0.097211208 | G19: =IFERROR(G18/G6,0) -> 0.076885693 | H19: =IFERROR(H18/H6,0) -> 0.065119586 | I19: =IFERROR(I18/I6,0) -> 0.093808608 | J19: =IFERROR(J18/J6,0) -> 0.13130224 | ... M19: =IFERROR(M18/M6,0) -> 0.1537329
B21: Other Income | C21: =IFERROR('Data Sheet'!B25,0) -> 2399.2 | D21: =IFERROR('Data Sheet'!C25,0) -> 2154.6 | E21: =IFERROR('Data Sheet'!D25,0) -> 2664.2 | F21: =IFERROR('Data Sheet'!E25,0) -> 3410.4 | G21: =IFERROR('Data Sheet'!F25,0) -> 3046.3 | H21: =IFERROR('Data Sheet'!G25,0) -> 1860.8 | I21: =IFERROR('Data Sheet'!H25,0) -> 2306.6 | J21: =IFERROR('Data Sheet'!I25,0) -> 4247.6 | ... L21: =IFERROR('Data Sheet'!K25,0) -> 4642.7 | M21: =IFERROR(SUM('Data Sheet'!H44:K44),0) -> 4658.9
B22: Other Income % sales | C22: =IFERROR(C21/C6,0) -> 0.035238305 | D22: =IFERROR(D21/D6,0) -> 0.02699682 | E22: =IFERROR(E21/E6,0) -> 0.030954414 | F22: =IFERROR(F21/F6,0) -> 0.045075337 | G22: =IFERROR(G21/G6,0) -> 0.043288524 | H22: =IFERROR(H21/H6,0) -> 0.021066503 | I22: =IFERROR(I21/I6,0) -> 0.019618733 | J22: =IFERROR(J21/J6,0) -> 0.029942576 | ... M22: =IFERROR(M21/M6,0) -> 0.025414585
B24: Interest | C24: =IFERROR('Data Sheet'!B27,0) -> 89.4 | D24: =IFERROR('Data Sheet'!C27,0) -> 345.8 | E24: =IFERROR('Data Sheet'!D27,0) -> 75.9 | F24: =IFERROR('Data Sheet'!E27,0) -> 134.2 | G24: =IFERROR('Data Sheet'!F27,0) -> 101.8 | H24: =IFERROR('Data Sheet'!G27,0) -> 126.6 | I24: =IFERROR('Data Sheet'!H27,0) -> 187 | J24: =IFERROR('Data Sheet'!I27,0) -> 193.6 | ... L24: =IFERROR('Data Sheet'!K27,0) -> 238.7 | M24: =IFERROR(SUM('Data Sheet'!H46:K46),0) -> 238.7
B25: Interest % Sales | C25: =IFERROR(C24/C6,0) -> 0.0013130646 | D25: =IFERROR(D24/D6,0) -> 0.004332823 | E25: =IFERROR(E24/E6,0) -> 0.00088185573 | F25: =IFERROR(F24/F6,0) -> 0.0017737246 | G25: =IFERROR(G24/G6,0) -> 0.0014465981 | H25: =IFERROR(H24/H6,0) -> 0.0014332649 | I25: =IFERROR(I24/I6,0) -> 0.0015905242 | J25: =IFERROR(J24/J6,0) -> 0.0013647431 | ... M25: =IFERROR(M24/M6,0) -> 0.0013021231
B27: Depreciation | C27: =IFERROR('Data Sheet'!B26,0) -> 2603.9 | D27: =IFERROR('Data Sheet'!C26,0) -> 2759.8 | E27: =IFERROR('Data Sheet'!D26,0) -> 3020.8 | F27: =IFERROR('Data Sheet'!E26,0) -> 3528.4 | G27: =IFERROR('Data Sheet'!F26,0) -> 3034.1 | H27: =IFERROR('Data Sheet'!G26,0) -> 2789 | I27: =IFERROR('Data Sheet'!H26,0) -> 2825.7 | J27: =IFERROR('Data Sheet'!I26,0) -> 5255.8 | ... L27: =IFERROR('Data Sheet'!K26,0) -> 6741.7 | M27: =IFERROR(SUM('Data Sheet'!H45:K45),0) -> 6741.7
B28: Depreciation % Sales | C28: =IFERROR(C27/C6,0) -> 0.038244841 | D28: =IFERROR(D27/D6,0) -> 0.034579887 | E28: =IFERROR(E27/E6,0) -> 0.035097626 | F28: =IFERROR(F27/F6,0) -> 0.046634946 | G28: =IFERROR(G27/G6,0) -> 0.043115159 | H28: =IFERROR(H27/H6,0) -> 0.031574848 | I28: =IFERROR(I27/I6,0) -> 0.024033927 | J28: =IFERROR(J27/J6,0) -> 0.037049674 | ... M28: =IFERROR(M27/M6,0) -> 0.036776386
B30: Earning Before Tax | C30: =IFERROR(SUM(C18,C21)-SUM(C24,C27),0) -> 10127.2 | D30: =IFERROR(SUM(D18,D21)-SUM(D24,D27),0) -> 11166.9 | E30: =IFERROR(SUM(E18,E21)-SUM(E24,E27),0) -> 10623.8 | F30: =IFERROR(SUM(F18,F21)-SUM(F24,F27),0) -> 7102.8 | G30: =IFERROR(SUM(G18,G21)-SUM(G24,G27),0) -> 5321 | H30: =IFERROR(SUM(H18,H21)-SUM(H24,H27),0) -> 4697.2 | I30: =IFERROR(SUM(I18,I21)-SUM(I24,I27),0) -> 10323.1 | J30: =IFERROR(SUM(J18,J21)-SUM(J24,J27),0) -> 17424.5 | ... M30: =IFERROR(SUM(M18,M21)-SUM(M24,M27),0) -> 25860.2
B31: EBT % Sales | C31: =IFERROR(C30/C6,0) -> 0.14874348 | D31: =IFERROR(D30/D6,0) -> 0.13991961 | E31: =IFERROR(E30/E6,0) -> 0.12343424 | F31: =IFERROR(F30/F6,0) -> 0.093877875 | G31: =IFERROR(G30/G6,0) -> 0.07561246 | H31: =IFERROR(H30/H6,0) -> 0.053177976 | I31: =IFERROR(I30/I6,0) -> 0.087802891 | J31: =IFERROR(J30/J6,0) -> 0.1228304 | ... M31: =IFERROR(M30/M6,0) -> 0.14106897
B33: Tax | C33: =IFERROR('Data Sheet'!B29,0) -> 2616.2 | D33: =IFERROR('Data Sheet'!C29,0) -> 3286.2 | E33: =IFERROR('Data Sheet'!D29,0) -> 2973.2 | F33: =IFERROR('Data Sheet'!E29,0) -> 1425.2 | G33: =IFERROR('Data Sheet'!F29,0) -> 931.9 | H33: =IFERROR('Data Sheet'!G29,0) -> 817.7 | I33: =IFERROR('Data Sheet'!H29,0) -> 2112.1 | J33: =IFERROR('Data Sheet'!I29,0) -> 3936.3 | ... L33: =IFERROR('Data Sheet'!K29,0) -> 4439 | M33: =IFERROR(SUM('Data Sheet'!H48:K48),0) -> 4439
B34: Effective Tax Rate | C34: =IFERROR(C33/C30,0) -> 0.25833399 | D34: =IFERROR(D33/D30,0) -> 0.29428042 | E34: =IFERROR(E33/E30,0) -> 0.2798622 | F34: =IFERROR(F33/F30,0) -> 0.20065326 | G34: =IFERROR(G33/G30,0) -> 0.17513625 | H34: =IFERROR(H33/H30,0) -> 0.17408243 | I34: =IFERROR(I33/I30,0) -> 0.20459939 | J34: =IFERROR(J33/J30,0) -> 0.22590605 | ... M34: =IFERROR(M33/M30,0) -> 0.17165374
B36: Net Profit | C36: =IFERROR(C30-C33,0) -> 7511 | D36: =IFERROR(D30-D33,0) -> 7880.7 | E36: =IFERROR(E30-E33,0) -> 7650.6 | F36: =IFERROR(F30-F33,0) -> 5677.6 | G36: =IFERROR(G30-G33,0) -> 4389.1 | H36: =IFERROR(H30-H33,0) -> 3879.5 | I36: =IFERROR(I30-I33,0) -> 8211 | J36: =IFERROR(J30-J33,0) -> 13488.2 | ... M36: =IFERROR(M30-M33,0) -> 21421.2
B37: Net Margin | C37: =IFERROR(C36/C6,0) -> 0.11031798 | D37: =IFERROR(D36/D6,0) -> 0.098744008 | E37: =IFERROR(E36/E6,0) -> 0.088889663 | F37: =IFERROR(F36/F6,0) -> 0.075040973 | G37: =IFERROR(G36/G6,0) -> 0.062369977 | H37: =IFERROR(H36/H6,0) -> 0.043920625 | I37: =IFERROR(I36/I6,0) -> 0.069838472 | J37: =IFERROR(J36/J6,0) -> 0.095082272 | ... M37: =IFERROR(M36/M6,0) -> 0.11685396
B39: No of Equity Shares | C39: =IFERROR('Data Sheet'!B93,0) -> 30.21 | D39: =IFERROR('Data Sheet'!C93,0) -> 30.21 | E39: =IFERROR('Data Sheet'!D93,0) -> 30.21 | F39: =IFERROR('Data Sheet'!E93,0) -> 30.21 | G39: =IFERROR('Data Sheet'!F93,0) -> 30.21 | H39: =IFERROR('Data Sheet'!G93,0) -> 30.21 | I39: =IFERROR('Data Sheet'!H93,0) -> 30.21 | J39: =IFERROR('Data Sheet'!I93,0) -> 31.44 | ... M39: =IFERROR('Data Sheet'!L93,0) -> 0
B41: Earning per Share | C41: =IFERROR(C36/C39,0) -> 248.62628 | D41: =IFERROR(D36/D39,0) -> 260.86395 | E41: =IFERROR(E36/E39,0) -> 253.24727 | F41: =IFERROR(F36/F39,0) -> 187.93777 | G41: =IFERROR(G36/G39,0) -> 145.28633 | H41: =IFERROR(H36/H39,0) -> 128.41774 | I41: =IFERROR(I36/I39,0) -> 271.79742 | J41: =IFERROR(J36/J39,0) -> 429.01399 | ... M41: =IFERROR(M36/M39,0) -> 0
B42: EPS Growth % | D42: =IFERROR(D41/C41-1,0) -> 0.049221142 | E42: =IFERROR(E41/D41-1,0) -> -0.029197914 | F42: =IFERROR(F41/E41-1,0) -> -0.25788827 | G42: =IFERROR(G41/F41-1,0) -> -0.22694448 | H42: =IFERROR(H41/G41-1,0) -> -0.11610581 | I42: =IFERROR(I41/H41-1,0) -> 1.1165099 | J42: =IFERROR(J41/I41-1,0) -> 0.57843293 | K42: =IFERROR(K41/J41-1,0) -> 0.075028543 | L42: =IFERROR(L41/K41-1,0) -> 0.012365347
B44: Dividend per Share | C44: =IFERROR('Data Sheet'!B31/HistoricalFS!C39,0) -> 74.975174 | D44: =IFERROR('Data Sheet'!C31/HistoricalFS!D39,0) -> 79.973519 | E44: =IFERROR('Data Sheet'!D31/HistoricalFS!E39,0) -> 79.973519 | F44: =IFERROR('Data Sheet'!E31/HistoricalFS!F39,0) -> 59.980139 | G44: =IFERROR('Data Sheet'!F31/HistoricalFS!G39,0) -> 44.985104 | H44: =IFERROR('Data Sheet'!G31/HistoricalFS!H39,0) -> 59.980139 | I44: =IFERROR('Data Sheet'!H31/HistoricalFS!I39,0) -> 89.970209 | J44: =IFERROR('Data Sheet'!I31/HistoricalFS!J39,0) -> 125 | ... M44: =IFERROR('Data Sheet'!L31/HistoricalFS!M39,0) -> 0
B45: Dividend payout ratio | C45: =IFERROR(C44/C41,0) -> 0.30155772 | D45: =IFERROR(D44/D41,0) -> 0.30657175 | E45: =IFERROR(E44/E41,0) -> 0.31579223 | F45: =IFERROR(F44/F41,0) -> 0.31914894 | G45: =IFERROR(G44/G41,0) -> 0.30963068 | H45: =IFERROR(H44/H41,0) -> 0.4670705 | I45: =IFERROR(I44/I41,0) -> 0.33101936 | J45: =IFERROR(J44/J41,0) -> 0.29136579 | ... M45: =IFERROR(M44/M41,0) -> 0
B47: Retained Earnings | C47: =IFERROR(IF(C41>C44,1-C45),0) -> 0.69844228 | D47: =IFERROR(IF(D41>D44,1-D45),0) -> 0.69342825 | E47: =IFERROR(IF(E41>E44,1-E45),0) -> 0.68420777 | F47: =IFERROR(IF(F41>F44,1-F45),0) -> 0.68085106 | G47: =IFERROR(IF(G41>G44,1-G45),0) -> 0.69036932 | H47: =IFERROR(IF(H41>H44,1-H45),0) -> 0.5329295 | I47: =IFERROR(IF(I41>I44,1-I45),0) -> 0.66898064 | J47: =IFERROR(IF(J41>J44,1-J45),0) -> 0.70863421 | ... L47: =IFERROR(IF(L41>L44,1-L45),0) -> 0.70015327
A49: # | B49: Balance Sheet
B50: Equity Share Capital | C50: =IFERROR('Data Sheet'!B57,0) -> 151 | D50: =IFERROR('Data Sheet'!C57,0) -> 151 | E50: =IFERROR('Data Sheet'!D57,0) -> 151 | F50: =IFERROR('Data Sheet'!E57,0) -> 151 | G50: =IFERROR('Data Sheet'!F57,0) -> 151 | H50: =IFERROR('Data Sheet'!G57,0) -> 151 | I50: =IFERROR('Data Sheet'!H57,0) -> 151 | J50: =IFERROR('Data Sheet'!I57,0) -> 157.2 | ... L50: =IFERROR('Data Sheet'!K57,0) -> 157.2
B51: Reserves | C51: =IFERROR('Data Sheet'!B58,0) -> 36924.1 | D51: =IFERROR('Data Sheet'!C58,0) -> 42408.4 | E51: =IFERROR('Data Sheet'!D58,0) -> 46941.1 | F51: =IFERROR('Data Sheet'!E58,0) -> 49262 | G51: =IFERROR('Data Sheet'!F58,0) -> 52349.6 | H51: =IFERROR('Data Sheet'!G58,0) -> 55182.5 | I51: =IFERROR('Data Sheet'!H58,0) -> 61640.3 | J51: =IFERROR('Data Sheet'!I58,0) -> 85478.8 | ... L51: =IFERROR('Data Sheet'!K58,0) -> 106999.1
B52: Borrowings | C52: =IFERROR('Data Sheet'!B59,0) -> 483.6 | D52: =IFERROR('Data Sheet'!C59,0) -> 120.8 | E52: =IFERROR('Data Sheet'!D59,0) -> 159.6 | F52: =IFERROR('Data Sheet'!E59,0) -> 184.1 | G52: =IFERROR('Data Sheet'!F59,0) -> 540.9 | H52: =IFERROR('Data Sheet'!G59,0) -> 425.5 | I52: =IFERROR('Data Sheet'!H59,0) -> 1247.3 | J52: =IFERROR('Data Sheet'!I59,0) -> 118.6 | ... L52: =IFERROR('Data Sheet'!K59,0) -> 102.5
B53: Other Liabilities | C53: =IFERROR('Data Sheet'!B60,0) -> 14401.8 | D53: =IFERROR('Data Sheet'!C60,0) -> 17568.2 | E53: =IFERROR('Data Sheet'!D60,0) -> 16717 | F53: =IFERROR('Data Sheet'!E60,0) -> 14030.6 | G53: =IFERROR('Data Sheet'!F60,0) -> 18334.6 | H53: =IFERROR('Data Sheet'!G60,0) -> 18896.5 | I53: =IFERROR('Data Sheet'!H60,0) -> 21558.3 | J53: =IFERROR('Data Sheet'!I60,0) -> 29549.5 | ... L53: =IFERROR('Data Sheet'!K60,0) -> 41622.2
B54: Total Liabilities | C54: =IFERROR('Data Sheet'!B61,0) -> 51960.5 | D54: =IFERROR('Data Sheet'!C61,0) -> 60248.4 | E54: =IFERROR('Data Sheet'!D61,0) -> 63968.7 | F54: =IFERROR('Data Sheet'!E61,0) -> 63627.7 | G54: =IFERROR('Data Sheet'!F61,0) -> 71376.1 | H54: =IFERROR('Data Sheet'!G61,0) -> 74655.5 | I54: =IFERROR('Data Sheet'!H61,0) -> 84596.9 | J54: =IFERROR('Data Sheet'!I61,0) -> 115304.1 | ... L54: =IFERROR('Data Sheet'!K61,0) -> 148881
B56: Fixed Assets Net Block | C56: =IFERROR('Data Sheet'!B62,0) -> 13310.7 | D56: =IFERROR('Data Sheet'!C62,0) -> 13388.8 | E56: =IFERROR('Data Sheet'!D62,0) -> 15437.3 | F56: =IFERROR('Data Sheet'!E62,0) -> 15744.4 | G56: =IFERROR('Data Sheet'!F62,0) -> 14988.7 | H56: =IFERROR('Data Sheet'!G62,0) -> 13747.2 | I56: =IFERROR('Data Sheet'!H62,0) -> 17830.4 | J56: =IFERROR('Data Sheet'!I62,0) -> 27864.8 | ... L56: =IFERROR('Data Sheet'!K62,0) -> 34955.4
B57: Capital Work in Progress | C57: =IFERROR('Data Sheet'!B63,0) -> 1252.3 | D57: =IFERROR('Data Sheet'!C63,0) -> 2132.1 | E57: =IFERROR('Data Sheet'!D63,0) -> 1606.9 | F57: =IFERROR('Data Sheet'!E63,0) -> 1415.2 | G57: =IFERROR('Data Sheet'!F63,0) -> 1496.8 | H57: =IFERROR('Data Sheet'!G63,0) -> 2936.5 | I57: =IFERROR('Data Sheet'!H63,0) -> 2904.1 | J57: =IFERROR('Data Sheet'!I63,0) -> 7734.8 | ... L57: =IFERROR('Data Sheet'!K63,0) -> 9406.2
B58: Investments | C58: =IFERROR('Data Sheet'!B64,0) -> 29150.6 | D58: =IFERROR('Data Sheet'!C64,0) -> 36123.1 | E58: =IFERROR('Data Sheet'!D64,0) -> 37503.6 | F58: =IFERROR('Data Sheet'!E64,0) -> 37488 | G58: =IFERROR('Data Sheet'!F64,0) -> 42944.8 | H58: =IFERROR('Data Sheet'!G64,0) -> 42034.7 | I58: =IFERROR('Data Sheet'!H64,0) -> 49184.3 | J58: =IFERROR('Data Sheet'!I64,0) -> 57296 | ... L58: =IFERROR('Data Sheet'!K64,0) -> 76838.5
...

Sheet Ratio Analysis
B2: ="Ratio Analysis"&" - "&'Data Sheet'!B1 -> Ratio Analysis - MARUTI SUZUKI INDIA LTD
B3: Years | C3: =HistoricalFS!C3 -> 42825 | D3: =HistoricalFS!D3 -> 43190 | E3: =HistoricalFS!E3 -> 43555 | F3: =HistoricalFS!F3 -> 43921 | G3: =HistoricalFS!G3 -> 44286 | H3: =HistoricalFS!H3 -> 44651 | I3: =HistoricalFS!I3 -> 45016 | J3: =HistoricalFS!J3 -> 45382 | ... L3: =HistoricalFS!L3 -> 46112 | M3: Trend Line | N3: Mean | O3: Median
B5: Sales Growth | D5: =IFERROR(HistoricalFS!D6/HistoricalFS!C6-1,0) -> 0.17220239 | E5: =IFERROR(HistoricalFS!E6/HistoricalFS!D6-1,0) -> 0.078425599 | F5: =IFERROR(HistoricalFS!F6/HistoricalFS!E6-1,0) -> -0.12093275 | G5: =IFERROR(HistoricalFS!G6/HistoricalFS!F6-1,0) -> -0.06989162 | H5: =IFERROR(HistoricalFS!H6/HistoricalFS!G6-1,0) -> 0.25518388 | I5: =IFERROR(HistoricalFS!I6/HistoricalFS!H6-1,0) -> 0.33104909 | J5: =IFERROR(HistoricalFS!J6/HistoricalFS!I6-1,0) -> 0.20657167 | K5: =IFERROR(HistoricalFS!K6/HistoricalFS!J6-1,0) -> 0.077928523 | L5: =IFERROR(HistoricalFS!L6/HistoricalFS!K6-1,0) -> 0.19882548 | N5: =IFERROR(AVERAGE(D5:L5),0) -> 0.1254847 | O5: =IFERROR(MEDIAN(D5:L5),0) -> 0.17220239
B6: EBITDA Growth | D6: =IFERROR(HistoricalFS!D18/HistoricalFS!C18-1,0) -> 0.16280119 | E6: =IFERROR(HistoricalFS!E18/HistoricalFS!D18-1,0) -> -0.087605938 | F6: =IFERROR(HistoricalFS!F18/HistoricalFS!E18-1,0) -> -0.33476841 | G6: =IFERROR(HistoricalFS!G18/HistoricalFS!F18-1,0) -> -0.26436438 | H6: =IFERROR(HistoricalFS!H18/HistoricalFS!G18-1,0) -> 0.063098362 | I6: =IFERROR(HistoricalFS!I18/HistoricalFS!H18-1,0) -> 0.9174548 | J6: =IFERROR(HistoricalFS!J18/HistoricalFS!I18-1,0) -> 0.68881696 | K6: =IFERROR(HistoricalFS!K18/HistoricalFS!J18-1,0) -> 0.085755088 | L6: =IFERROR(HistoricalFS!L18/HistoricalFS!K18-1,0) -> 0.060948595 | N6: =IFERROR(AVERAGE(D6:L6),0) -> 0.1435707 | O6: =IFERROR(MEDIAN(D6:L6),0) -> 0.063098362
B7: EBIT Growth | D7: =IFERROR(SUM(HistoricalFS!D24,HistoricalFS!D30)/SUM(HistoricalFS!C24,HistoricalFS!C30)-1,0) -> 0.12686217 | E7: =IFERROR(SUM(HistoricalFS!E24,HistoricalFS!E30)/SUM(HistoricalFS!D24,HistoricalFS!D30)-1,0) -> -0.070617666 | F7: =IFERROR(SUM(HistoricalFS!F24,HistoricalFS!F30)/SUM(HistoricalFS!E24,HistoricalFS!E30)-1,0) -> -0.3236259 | G7: =IFERROR(SUM(HistoricalFS!G24,HistoricalFS!G30)/SUM(HistoricalFS!F24,HistoricalFS!F30)-1,0) -> -0.25068399 | H7: =IFERROR(SUM(HistoricalFS!H24,HistoricalFS!H30)/SUM(HistoricalFS!G24,HistoricalFS!G30)-1,0) -> -0.11045954 | I7: =IFERROR(SUM(HistoricalFS!I24,HistoricalFS!I30)/SUM(HistoricalFS!H24,HistoricalFS!H30)-1,0) -> 1.1788009 | J7: =IFERROR(SUM(HistoricalFS!J24,HistoricalFS!J30)/SUM(HistoricalFS!I24,HistoricalFS!I30)-1,0) -> 0.67630184 | K7: =IFERROR(SUM(HistoricalFS!K24,HistoricalFS!K30)/SUM(HistoricalFS!J24,HistoricalFS!J30)-1,0) -> 0.12465022 | L7: =IFERROR(SUM(HistoricalFS!L24,HistoricalFS!L30)/SUM(HistoricalFS!K24,HistoricalFS!K30)-1,0) -> -0.023064267 | N7: =IFERROR(AVERAGE(D7:L7),0) -> 0.14757376 | O7: =IFERROR(MEDIAN(D7:L7),0) -> -0.023064267
B8: Net Profit Growth | D8: =IFERROR(HistoricalFS!D36/HistoricalFS!C36-1,0) -> 0.049221142 | E8: =IFERROR(HistoricalFS!E36/HistoricalFS!D36-1,0) -> -0.029197914 | F8: =IFERROR(HistoricalFS!F36/HistoricalFS!E36-1,0) -> -0.25788827 | G8: =IFERROR(HistoricalFS!G36/HistoricalFS!F36-1,0) -> -0.22694448 | H8: =IFERROR(HistoricalFS!H36/HistoricalFS!G36-1,0) -> -0.11610581 | I8: =IFERROR(HistoricalFS!I36/HistoricalFS!H36-1,0) -> 1.1165099 | J8: =IFERROR(HistoricalFS!J36/HistoricalFS!I36-1,0) -> 0.64269882 | K8: =IFERROR(HistoricalFS!K36/HistoricalFS!J36-1,0) -> 0.075028543 | L8: =IFERROR(HistoricalFS!L36/HistoricalFS!K36-1,0) -> 0.012365347 | N8: =IFERROR(AVERAGE(D8:L8),0) -> 0.14063192 | O8: =IFERROR(MEDIAN(D8:L8),0) -> 0.012365347
B9: Dividend Growth | D9: =IFERROR(HistoricalFS!D44/HistoricalFS!C44-1,0) -> 0.066666667 | E9: =IFERROR(HistoricalFS!E44/HistoricalFS!D44-1,0) -> 0 | F9: =IFERROR(HistoricalFS!F44/HistoricalFS!E44-1,0) -> -0.25 | G9: =IFERROR(HistoricalFS!G44/HistoricalFS!F44-1,0) -> -0.25 | H9: =IFERROR(HistoricalFS!H44/HistoricalFS!G44-1,0) -> 0.33333333 | I9: =IFERROR(HistoricalFS!I44/HistoricalFS!H44-1,0) -> 0.5 | J9: =IFERROR(HistoricalFS!J44/HistoricalFS!I44-1,0) -> 0.38934879 | K9: =IFERROR(HistoricalFS!K44/HistoricalFS!J44-1,0) -> 0.08 | L9: =IFERROR(HistoricalFS!L44/HistoricalFS!K44-1,0) -> 0.037037037 | N9: =IFERROR(AVERAGE(D9:L9),0) -> 0.10070954 | O9: =IFERROR(MEDIAN(D9:L9),0) -> 0.066666667
B11: Gross Margin | C11: =IFERROR(HistoricalFS!C13,0) -> 0.2655651 | D11: =IFERROR(HistoricalFS!D13,0) -> 0.26092666 | E11: =IFERROR(HistoricalFS!E13,0) -> 0.25428932 | F11: =IFERROR(HistoricalFS!F13,0) -> 0.23794475 | G11: =IFERROR(HistoricalFS!G13,0) -> 0.21253339 | H11: =IFERROR(HistoricalFS!H13,0) -> 0.18964155 | I11: =IFERROR(HistoricalFS!I13,0) -> 0.2107249 | J11: =IFERROR(HistoricalFS!J13,0) -> 0.23856922 | ... L11: =IFERROR(HistoricalFS!L13,0) -> 0.22742587 | N11: =IFERROR(AVERAGE(C11:L11),0) -> 0.23287927 | O11: =IFERROR(MEDIAN(C11:L11),0) -> 0.23455836
B12: EBITDA Margin | C12: =IFERROR(HistoricalFS!C19,0) -> 0.15306308 | D12: =IFERROR(HistoricalFS!D19,0) -> 0.1518355 | E12: =IFERROR(HistoricalFS!E19,0) -> 0.12845931 | F12: =IFERROR(HistoricalFS!F19,0) -> 0.097211208 | G12: =IFERROR(HistoricalFS!G19,0) -> 0.076885693 | H12: =IFERROR(HistoricalFS!H19,0) -> 0.065119586 | I12: =IFERROR(HistoricalFS!I19,0) -> 0.093808608 | J12: =IFERROR(HistoricalFS!J19,0) -> 0.13130224 | ... L12: =IFERROR(HistoricalFS!L19,0) -> 0.11704488 | N12: =IFERROR(AVERAGE(C12:L12),0) -> 0.11469857 | O12: =IFERROR(MEDIAN(C12:L12),0) -> 0.1227521
B13: EBIT Margin | C13: =IFERROR(SUM(HistoricalFS!C30,HistoricalFS!C24)/HistoricalFS!C6,0) -> 0.15005655 | D13: =IFERROR(SUM(HistoricalFS!D30,HistoricalFS!D24)/HistoricalFS!D6,0) -> 0.14425243 | E13: =IFERROR(SUM(HistoricalFS!E30,HistoricalFS!E24)/HistoricalFS!E6,0) -> 0.1243161 | F13: =IFERROR(SUM(HistoricalFS!F30,HistoricalFS!F24)/HistoricalFS!F6,0) -> 0.095651599 | G13: =IFERROR(SUM(HistoricalFS!G30,HistoricalFS!G24)/HistoricalFS!G6,0) -> 0.077059058 | H13: =IFERROR(SUM(HistoricalFS!H30,HistoricalFS!H24)/HistoricalFS!H6,0) -> 0.054611241 | I13: =IFERROR(SUM(HistoricalFS!I30,HistoricalFS!I24)/HistoricalFS!I6,0) -> 0.089393415 | J13: =IFERROR(SUM(HistoricalFS!J30,HistoricalFS!J24)/HistoricalFS!J6,0) -> 0.12419515 | ... L13: =IFERROR(SUM(HistoricalFS!L30,HistoricalFS!L24)/HistoricalFS!L6,0) -> 0.10559471 | N13: =IFERROR(AVERAGE(C13:L13),0) -> 0.10947085 | O13: =IFERROR(MEDIAN(C13:L13),0) -> 0.11489493
B14: EBT Margin | C14: =IFERROR(HistoricalFS!C31,0) -> 0.14874348 | D14: =IFERROR(HistoricalFS!D31,0) -> 0.13991961 | E14: =IFERROR(HistoricalFS!E31,0) -> 0.12343424 | F14: =IFERROR(HistoricalFS!F31,0) -> 0.093877875 | G14: =IFERROR(HistoricalFS!G31,0) -> 0.07561246 | H14: =IFERROR(HistoricalFS!H31,0) -> 0.053177976 | I14: =IFERROR(HistoricalFS!I31,0) -> 0.087802891 | J14: =IFERROR(HistoricalFS!J31,0) -> 0.1228304 | ... L14: =IFERROR(HistoricalFS!L31,0) -> 0.10429259 | N14: =IFERROR(AVERAGE(C14:L14),0) -> 0.10779998 | O14: =IFERROR(MEDIAN(C14:L14),0) -> 0.1135615
B15: Net Profit Margin | C15: =IFERROR(HistoricalFS!C37,0) -> 0.11031798 | D15: =IFERROR(HistoricalFS!D37,0) -> 0.098744008 | E15: =IFERROR(HistoricalFS!E37,0) -> 0.088889663 | F15: =IFERROR(HistoricalFS!F37,0) -> 0.075040973 | G15: =IFERROR(HistoricalFS!G37,0) -> 0.062369977 | H15: =IFERROR(HistoricalFS!H37,0) -> 0.043920625 | I15: =IFERROR(HistoricalFS!I37,0) -> 0.069838472 | J15: =IFERROR(HistoricalFS!J37,0) -> 0.095082272 | ... L15: =IFERROR(HistoricalFS!L37,0) -> 0.080077571 | N15: =IFERROR(AVERAGE(C15:L15),0) -> 0.081910802 | O15: =IFERROR(MEDIAN(C15:L15),0) -> 0.084483617
B17: Sales Exp % Sales | C17: =IFERROR(HistoricalFS!C16,0) -> 0.11250202 | D17: =IFERROR(HistoricalFS!D16,0) -> 0.10909116 | E17: =IFERROR(HistoricalFS!E16,0) -> 0.12583001 | F17: =IFERROR(HistoricalFS!F16,0) -> 0.14073354 | G17: =IFERROR(HistoricalFS!G16,0) -> 0.1356477 | H17: =IFERROR(HistoricalFS!H16,0) -> 0.12452196 | I17: =IFERROR(HistoricalFS!I16,0) -> 0.11691629 | J17: =IFERROR(HistoricalFS!J16,0) -> 0.10726698 | ... L17: =IFERROR(HistoricalFS!L16,0) -> 0.11038098 | N17: =IFERROR(AVERAGE(C17:L17),0) -> 0.1181807 | O17: =IFERROR(MEDIAN(C17:L17),0) -> 0.11470915
B18: Depreciation % Sales | C18: =IFERROR(HistoricalFS!C28,0) -> 0.038244841 | D18: =IFERROR(HistoricalFS!D28,0) -> 0.034579887 | E18: =IFERROR(HistoricalFS!E28,0) -> 0.035097626 | F18: =IFERROR(HistoricalFS!F28,0) -> 0.046634946 | G18: =IFERROR(HistoricalFS!G28,0) -> 0.043115159 | H18: =IFERROR(HistoricalFS!H28,0) -> 0.031574848 | I18: =IFERROR(HistoricalFS!I28,0) -> 0.024033927 | J18: =IFERROR(HistoricalFS!J28,0) -> 0.037049674 | ... L18: =IFERROR(HistoricalFS!L28,0) -> 0.036776386 | N18: =IFERROR(AVERAGE(C18:L18),0) -> 0.036378305 | O18: =IFERROR(MEDIAN(C18:L18),0) -> 0.036726071
B19: Operating Income % Sales | C19: =IFERROR('Ratio Analysis'!C13,0) -> 0.15005655 | D19: =IFERROR('Ratio Analysis'!D13,0) -> 0.14425243 | E19: =IFERROR('Ratio Analysis'!E13,0) -> 0.1243161 | F19: =IFERROR('Ratio Analysis'!F13,0) -> 0.095651599 | G19: =IFERROR('Ratio Analysis'!G13,0) -> 0.077059058 | H19: =IFERROR('Ratio Analysis'!H13,0) -> 0.054611241 | I19: =IFERROR('Ratio Analysis'!I13,0) -> 0.089393415 | J19: =IFERROR('Ratio Analysis'!J13,0) -> 0.12419515 | ... L19: =IFERROR('Ratio Analysis'!L13,0) -> 0.10559471 | N19: =IFERROR(AVERAGE(C19:L19),0) -> 0.10947085 | O19: =IFERROR(MEDIAN(C19:L19),0) -> 0.11489493
B21: Return on Capital Employed | C21: =IFERROR(SUM(HistoricalFS!C30,HistoricalFS!C24)/(SUM(HistoricalFS!C50:C52)),0) -> 0.27201687 | D21: =IFERROR(SUM(HistoricalFS!D30,HistoricalFS!D24)/(SUM(HistoricalFS!D50:D52)),0) -> 0.26974335 | E21: =IFERROR(SUM(HistoricalFS!E30,HistoricalFS!E24)/(SUM(HistoricalFS!E50:E52)),0) -> 0.22644053 | F21: =IFERROR(SUM(HistoricalFS!F30,HistoricalFS!F24)/(SUM(HistoricalFS!F50:F52)),0) -> 0.14591579 | G21: =IFERROR(SUM(HistoricalFS!G30,HistoricalFS!G24)/(SUM(HistoricalFS!G50:G52)),0) -> 0.10223693 | H21: =IFERROR(SUM(HistoricalFS!H30,HistoricalFS!H24)/(SUM(HistoricalFS!H50:H52)),0) -> 0.086511595 | I21: =IFERROR(SUM(HistoricalFS!I30,HistoricalFS!I24)/(SUM(HistoricalFS!I50:I52)),0) -> 0.16672483 | J21: =IFERROR(SUM(HistoricalFS!J30,HistoricalFS!J24)/(SUM(HistoricalFS!J50:J52)),0) -> 0.20544787 | ... L21: =IFERROR(SUM(HistoricalFS!L30,HistoricalFS!L24)/(SUM(HistoricalFS!L50:L52)),0) -> 0.18047191 | N21: =IFERROR(AVERAGE(C21:L21),0) -> 0.18612071 | O21: =IFERROR(MEDIAN(C21:L21),0) -> 0.19295989
B22: Retained Earning % | C22: =IFERROR(HistoricalFS!C47,0) -> 0.69844228 | D22: =IFERROR(HistoricalFS!D47,0) -> 0.69342825 | E22: =IFERROR(HistoricalFS!E47,0) -> 0.68420777 | F22: =IFERROR(HistoricalFS!F47,0) -> 0.68085106 | G22: =IFERROR(HistoricalFS!G47,0) -> 0.69036932 | H22: =IFERROR(HistoricalFS!H47,0) -> 0.5329295 | I22: =IFERROR(HistoricalFS!I47,0) -> 0.66898064 | J22: =IFERROR(HistoricalFS!J47,0) -> 0.70863421 | ... L22: =IFERROR(HistoricalFS!L47,0) -> 0.70015327 | N22: =IFERROR(AVERAGE(C22:L22),0) -> 0.67652831 | O22: =IFERROR(MEDIAN(C22:L22),0) -> 0.69189879
B23: Return on Equity % | C23: =IFERROR(HistoricalFS!C36/SUM(HistoricalFS!C50:C51),0) -> 0.2025888 | D23: =IFERROR(HistoricalFS!D36/SUM(HistoricalFS!D50:D51),0) -> 0.18516943 | E23: =IFERROR(HistoricalFS!E36/SUM(HistoricalFS!E50:E51),0) -> 0.16246037 | F23: =IFERROR(HistoricalFS!F36/SUM(HistoricalFS!F50:F51),0) -> 0.11490094 | G23: =IFERROR(HistoricalFS!G36/SUM(HistoricalFS!G50:G51),0) -> 0.083600949 | H23: =IFERROR(HistoricalFS!H36/SUM(HistoricalFS!H50:H51),0) -> 0.070111235 | I23: =IFERROR(HistoricalFS!I36/SUM(HistoricalFS!I50:I51),0) -> 0.13288278 | J23: =IFERROR(HistoricalFS!J36/SUM(HistoricalFS!J50:J51),0) -> 0.15750619 | ... L23: =IFERROR(HistoricalFS!L36/SUM(HistoricalFS!L50:L51),0) -> 0.13699148 | N23: =IFERROR(AVERAGE(C23:L23),0) -> 0.13968794 | O23: =IFERROR(MEDIAN(C23:L23),0) -> 0.14382936
B24: Self Sustained Growth Rate | C24: =IFERROR(C23*C22,0) -> 0.14149658 | D24: =IFERROR(D23*D22,0) -> 0.12840172 | E24: =IFERROR(E23*E22,0) -> 0.11115665 | F24: =IFERROR(F23*F22,0) -> 0.078230425 | G24: =IFERROR(G23*G22,0) -> 0.057715531 | H24: =IFERROR(H23*H22,0) -> 0.037364345 | I24: =IFERROR(I23*I22,0) -> 0.08889601 | J24: =IFERROR(J23*J22,0) -> 0.11161427 | ... L24: =IFERROR(L23*L22,0) -> 0.095915033 | N24: =IFERROR(AVERAGE(C24:L24),0) -> 0.095735552 | O24: =IFERROR(MEDIAN(C24:L24),0) -> 0.10123999
B25: Interest Coverage Ratio | C25: =IFERROR(SUM(HistoricalFS!C30,HistoricalFS!C24)/HistoricalFS!C24,0) -> 114.27964 | D25: =IFERROR(SUM(HistoricalFS!D30,HistoricalFS!D24)/HistoricalFS!D24,0) -> 33.292944 | E25: =IFERROR(SUM(HistoricalFS!E30,HistoricalFS!E24)/HistoricalFS!E24,0) -> 140.97101 | F25: =IFERROR(SUM(HistoricalFS!F30,HistoricalFS!F24)/HistoricalFS!F24,0) -> 53.926975 | G25: =IFERROR(SUM(HistoricalFS!G30,HistoricalFS!G24)/HistoricalFS!G24,0) -> 53.269155 | H25: =IFERROR(SUM(HistoricalFS!H30,HistoricalFS!H24)/HistoricalFS!H24,0) -> 38.102686 | I25: =IFERROR(SUM(HistoricalFS!I30,HistoricalFS!I24)/HistoricalFS!I24,0) -> 56.203743 | J25: =IFERROR(SUM(HistoricalFS!J30,HistoricalFS!J24)/HistoricalFS!J24,0) -> 91.002583 | ... L25: =IFERROR(SUM(HistoricalFS!L30,HistoricalFS!L24)/HistoricalFS!L24,0) -> 81.094261 | N25: =IFERROR(AVERAGE(C25:L25),0) -> 76.417287 | O25: =IFERROR(MEDIAN(C25:L25),0) -> 68.649002
B27: Debtor Turnover Ratio | C27: =IFERROR(HistoricalFS!C6/HistoricalFS!C62,0) -> 56.614835 | D27: =IFERROR(HistoricalFS!D6/HistoricalFS!D62,0) -> 54.462536 | E27: =IFERROR(HistoricalFS!E6/HistoricalFS!E62,0) -> 37.213983 | F27: =IFERROR(HistoricalFS!F6/HistoricalFS!F62,0) -> 38.256561 | G27: =IFERROR(HistoricalFS!G6/HistoricalFS!G62,0) -> 54.982421 | H27: =IFERROR(HistoricalFS!H6/HistoricalFS!H62,0) -> 43.415974 | I27: =IFERROR(HistoricalFS!I6/HistoricalFS!I62,0) -> 35.612558 | J27: =IFERROR(HistoricalFS!J6/HistoricalFS!J62,0) -> 30.860207 | ... L27: =IFERROR(HistoricalFS!L6/HistoricalFS!L62,0) -> 34.315987 | N27: =IFERROR(AVERAGE(C27:L27),0) -> 40.911733 | O27: =IFERROR(MEDIAN(C27:L27),0) -> 37.735272
B28: Creditor Turnover Ratio | C28: =IFERROR(HistoricalFS!C6/HistoricalFS!C53,0) -> 4.7275341 | D28: =IFERROR(HistoricalFS!D6/HistoricalFS!D53,0) -> 4.5428331 | E28: =IFERROR(HistoricalFS!E6/HistoricalFS!E53,0) -> 5.1485613 | F28: =IFERROR(HistoricalFS!F6/HistoricalFS!F53,0) -> 5.3924993 | G28: =IFERROR(HistoricalFS!G6/HistoricalFS!G53,0) -> 3.8382075 | H28: =IFERROR(HistoricalFS!H6/HistoricalFS!H53,0) -> 4.6744 | I28: =IFERROR(HistoricalFS!I6/HistoricalFS!I53,0) -> 5.4536443 | J28: =IFERROR(HistoricalFS!J6/HistoricalFS!J53,0) -> 4.8006971 | ... L28: =IFERROR(HistoricalFS!L6/HistoricalFS!L53,0) -> 4.4042843 | N28: =IFERROR(AVERAGE(C28:L28),0) -> 4.7272632 | O28: =IFERROR(MEDIAN(C28:L28),0) -> 4.700967
B29: Inventory Turnover Ratio | C29: =IFERROR(HistoricalFS!C6/HistoricalFS!C63,0) -> 20.861292 | D29: =IFERROR(HistoricalFS!D6/HistoricalFS!D63,0) -> 25.254541 | E29: =IFERROR(HistoricalFS!E6/HistoricalFS!E63,0) -> 25.903961 | F29: =IFERROR(HistoricalFS!F6/HistoricalFS!F63,0) -> 23.541492 | G29: =IFERROR(HistoricalFS!G6/HistoricalFS!G63,0) -> 23.080354 | H29: =IFERROR(HistoricalFS!H6/HistoricalFS!H63,0) -> 25.006313 | I29: =IFERROR(HistoricalFS!I6/HistoricalFS!I63,0) -> 27.447485 | J29: =IFERROR(HistoricalFS!J6/HistoricalFS!J63,0) -> 26.674602 | ... L29: =IFERROR(HistoricalFS!L6/HistoricalFS!L63,0) -> 16.193135 | N29: =IFERROR(AVERAGE(C29:L29),0) -> 23.608216 | O29: =IFERROR(MEDIAN(C29:L29),0) -> 24.273902
B30: Fixed Asset Turnover | C30: =IFERROR(HistoricalFS!C6/HistoricalFS!C56,0) -> 5.1150578 | D30: =IFERROR(HistoricalFS!D6/HistoricalFS!D56,0) -> 5.9609076 | E30: =IFERROR(HistoricalFS!E6/HistoricalFS!E56,0) -> 5.5753597 | F30: =IFERROR(HistoricalFS!F6/HistoricalFS!F56,0) -> 4.8055182 | G30: =IFERROR(HistoricalFS!G6/HistoricalFS!G56,0) -> 4.6950036 | H30: =IFERROR(HistoricalFS!H6/HistoricalFS!H56,0) -> 6.4252939 | I30: =IFERROR(HistoricalFS!I6/HistoricalFS!I56,0) -> 6.5938678 | J30: =IFERROR(HistoricalFS!J6/HistoricalFS!J56,0) -> 5.0909463 | ... L30: =IFERROR(HistoricalFS!L6/HistoricalFS!L56,0) -> 5.2442827 | N30: =IFERROR(AVERAGE(C30:L30),0) -> 5.4142395 | O30: =IFERROR(MEDIAN(C30:L30),0) -> 5.1796703
B31: Capital Turnover Ratio | C31: =IFERROR(HistoricalFS!C6/SUM(HistoricalFS!C50:C51),0) -> 1.8364077 | D31: =IFERROR(HistoricalFS!D6/SUM(HistoricalFS!D50:D51),0) -> 1.8752473 | E31: =IFERROR(HistoricalFS!E6/SUM(HistoricalFS!E50:E51),0) -> 1.8276632 | F31: =IFERROR(HistoricalFS!F6/SUM(HistoricalFS!F50:F51),0) -> 1.531176 | G31: =IFERROR(HistoricalFS!G6/SUM(HistoricalFS!G50:G51),0) -> 1.3404037 | H31: =IFERROR(HistoricalFS!H6/SUM(HistoricalFS!H50:H51),0) -> 1.5963169 | I31: =IFERROR(HistoricalFS!I6/SUM(HistoricalFS!I50:I51),0) -> 1.9027161 | J31: =IFERROR(HistoricalFS!J6/SUM(HistoricalFS!J50:J51),0) -> 1.6565253 | ... L31: =IFERROR(HistoricalFS!L6/SUM(HistoricalFS!L50:L51),0) -> 1.7107347 | N31: =IFERROR(AVERAGE(C31:L31),0) -> 1.6866064 | O31: =IFERROR(MEDIAN(C31:L31),0) -> 1.68363
B33: Debtor Days | C33: =IFERROR(365/C27,0) -> 6.4470735 | D33: =IFERROR(365/D27,0) -> 6.7018547 | E33: =IFERROR(365/E27,0) -> 9.8081412 | F33: =IFERROR(365/F27,0) -> 9.5408472 | G33: =IFERROR(365/G27,0) -> 6.6384855 | H33: =IFERROR(365/H27,0) -> 8.4070438 | I33: =IFERROR(365/I27,0) -> 10.249193 | J33: =IFERROR(365/J27,0) -> 11.827529 | ... L33: =IFERROR(365/L27,0) -> 10.636442 | N33: =IFERROR(AVERAGE(C33:L33),0) -> 9.5866732 | O33: =IFERROR(MEDIAN(C33:L33),0) -> 9.6744942
B34: Payable Days | C34: =IFERROR(365/C28,0) -> 77.20727 | D34: =IFERROR(365/D28,0) -> 80.346338 | E34: =IFERROR(365/E28,0) -> 70.893591 | F34: =IFERROR(365/F28,0) -> 67.686611 | G34: =IFERROR(365/G28,0) -> 95.096473 | H34: =IFERROR(365/H28,0) -> 78.084888 | I34: =IFERROR(365/I28,0) -> 66.927724 | J34: =IFERROR(365/J28,0) -> 76.030624 | ... L34: =IFERROR(365/L28,0) -> 82.873852 | N34: =IFERROR(AVERAGE(C34:L34),0) -> 78.022954 | O34: =IFERROR(MEDIAN(C34:L34),0) -> 77.646079
B35: Inventory Days | C35: =IFERROR(365/C29,0) -> 17.496519 | D35: =IFERROR(365/D29,0) -> 14.452846 | E35: =IFERROR(365/E29,0) -> 14.090509 | F35: =IFERROR(365/F29,0) -> 15.50454 | G35: =IFERROR(365/G29,0) -> 15.814315 | H35: =IFERROR(365/H29,0) -> 14.596314 | I35: =IFERROR(365/I29,0) -> 13.298122 | J35: =IFERROR(365/J29,0) -> 13.683428 | ... L35: =IFERROR(365/L29,0) -> 22.540417 | N35: =IFERROR(AVERAGE(C35:L35),0) -> 15.797867 | O35: =IFERROR(MEDIAN(C35:L35),0) -> 15.050427
B36: Cash Conversion Cycle | C36: =SUM(C33+C35-C34) -> -53.263678 | D36: =SUM(D33+D35-D34) -> -59.191637 | E36: =SUM(E33+E35-E34) -> -46.99494 | F36: =SUM(F33+F35-F34) -> -42.641224 | G36: =SUM(G33+G35-G34) -> -72.643672 | H36: =SUM(H33+H35-H34) -> -55.08153 | I36: =SUM(I33+I35-I34) -> -43.380408 | J36: =SUM(J33+J35-J34) -> -50.519667 | ... L36: =SUM(L33+L35-L34) -> -49.696993 | N36: =IFERROR(AVERAGE(C36:L36),0) -> -52.638414 | O36: =IFERROR(MEDIAN(C36:L36),0) -> -51.745028
B38: CFO/Sales | C38: =IFERROR(HistoricalFS!C81/HistoricalFS!C6,0) -> 0.18322685 | D38: =IFERROR(HistoricalFS!D81/HistoricalFS!D6,0) -> 0.18289826 | E38: =IFERROR(HistoricalFS!E81/HistoricalFS!E6,0) -> 0.061416198 | F38: =IFERROR(HistoricalFS!F81/HistoricalFS!F6,0) -> 0.012225747 | G38: =IFERROR(HistoricalFS!G81/HistoricalFS!G6,0) -> 0.18746092 | H38: =IFERROR(HistoricalFS!H81/HistoricalFS!H6,0) -> -0.011004214 | I38: =IFERROR(HistoricalFS!I81/HistoricalFS!I6,0) -> 0.081873723 | J38: =IFERROR(HistoricalFS!J81/HistoricalFS!J6,0) -> 0.130567 | ... L38: =IFERROR(HistoricalFS!L81/HistoricalFS!L6,0) -> 0.11311069 | N38: =IFERROR(AVERAGE(C38:L38),0) -> 0.10448338 | O38: =IFERROR(MEDIAN(C38:L38),0) -> 0.10808465
B39: CFO/Total Assets | C39: =IFERROR(HistoricalFS!C81/HistoricalFS!C67,0) -> 0.24008622 | D39: =IFERROR(HistoricalFS!D81/HistoricalFS!D67,0) -> 0.24228029 | E39: =IFERROR(HistoricalFS!E81/HistoricalFS!E67,0) -> 0.082634163 | F39: =IFERROR(HistoricalFS!F81/HistoricalFS!F67,0) -> 0.014537693 | G39: =IFERROR(HistoricalFS!G81/HistoricalFS!G67,0) -> 0.18482377 | H39: =IFERROR(HistoricalFS!H81/HistoricalFS!H67,0) -> -0.013019804 | I39: =IFERROR(HistoricalFS!I81/HistoricalFS!I67,0) -> 0.11378668 | J39: =IFERROR(HistoricalFS!J81/HistoricalFS!J67,0) -> 0.16063609 | ... L39: =IFERROR(HistoricalFS!L81/HistoricalFS!L67,0) -> 0.1392723 | N39: =IFERROR(AVERAGE(C39:L39),0) -> 0.12844498 | O39: =IFERROR(MEDIAN(C39:L39),0) -> 0.12934236
B40: CFO/Total Debt | D40: =IFERROR(HistoricalFS!D81/HistoricalFS!D52,0) -> 120.83609 | E40: =IFERROR(HistoricalFS!E81/HistoricalFS!E52,0) -> 33.120301 | F40: =IFERROR(HistoricalFS!F81/HistoricalFS!F52,0) -> 5.0244432 | G40: =IFERROR(HistoricalFS!G81/HistoricalFS!G52,0) -> 24.388981 | H40: =IFERROR(HistoricalFS!H81/HistoricalFS!H52,0) -> -2.2843713 | I40: =IFERROR(HistoricalFS!I81/HistoricalFS!I52,0) -> 7.7174697 | J40: =IFERROR(HistoricalFS!J81/HistoricalFS!J52,0) -> 156.17201 | K40: =IFERROR(HistoricalFS!K81/HistoricalFS!K52,0) -> 181.13793 | L40: =IFERROR(HistoricalFS!L81/HistoricalFS!L52,0) -> 202.29268 | N40: =IFERROR(AVERAGE(C40:L40),0) -> 80.933949 | O40: =IFERROR(MEDIAN(C40:L40),0) -> 33.120301

Sheet Common Size Statement
B2: ="Common Size Income Statement"&" - "&'Data Sheet'!B1 -> Common Size Income Statement - MARUTI SUZUKI INDIA LTD
B4: Particulars | C4: ='Data Sheet'!B16 -> 42825 | D4: ='Data Sheet'!C16 -> 43190 | E4: ='Data Sheet'!D16 -> 43555 | F4: ='Data Sheet'!E16 -> 43921 | G4: ='Data Sheet'!F16 -> 44286 | H4: ='Data Sheet'!G16 -> 44651 | I4: ='Data Sheet'!H16 -> 45016 | J4: ='Data Sheet'!I16 -> 45382 | ... L4: ='Data Sheet'!K16 -> 46112
B6: ='Data Sheet'!A17 -> Sales | C6: ='Data Sheet'!B17/'Data Sheet'!B$17 -> 1 | D6: ='Data Sheet'!C17/'Data Sheet'!C$17 -> 1 | E6: ='Data Sheet'!D17/'Data Sheet'!D$17 -> 1 | F6: ='Data Sheet'!E17/'Data Sheet'!E$17 -> 1 | G6: ='Data Sheet'!F17/'Data Sheet'!F$17 -> 1 | H6: ='Data Sheet'!G17/'Data Sheet'!G$17 -> 1 | I6: ='Data Sheet'!H17/'Data Sheet'!H$17 -> 1 | J6: ='Data Sheet'!I17/'Data Sheet'!I$17 -> 1 | ... L6: ='Data Sheet'!K17/'Data Sheet'!K$17 -> 1
B7: ='Data Sheet'!A18 -> Raw Material Cost | C7: ='Data Sheet'!B18/'Data Sheet'!B$17 -> 0.69209811 | D7: ='Data Sheet'!C18/'Data Sheet'!C$17 -> 0.6884565 | E7: ='Data Sheet'!D18/'Data Sheet'!D$17 -> 0.68952753 | F7: ='Data Sheet'!E18/'Data Sheet'!E$17 -> 0.70581549 | G7: ='Data Sheet'!F18/'Data Sheet'!F$17 -> 0.71833258 | H7: ='Data Sheet'!G18/'Data Sheet'!G$17 -> 0.74875184 | I7: ='Data Sheet'!H18/'Data Sheet'!H$17 -> 0.73703957 | J7: ='Data Sheet'!I18/'Data Sheet'!I$17 -> 0.70577168 | ... L7: ='Data Sheet'!K18/'Data Sheet'!K$17 -> 0.73560409
B8: ='Data Sheet'!A19 -> Change in Inventory | C8: ='Data Sheet'!B19/'Data Sheet'!B$17 -> 0.0055709775 | D8: ='Data Sheet'!C19/'Data Sheet'!C$17 -> -0.00051121798 | E8: ='Data Sheet'!D19/'Data Sheet'!D$17 -> -0.0024585069 | F8: ='Data Sheet'!E19/'Data Sheet'!E$17 -> 0.0031549035 | G8: ='Data Sheet'!F19/'Data Sheet'!F$17 -> -0.00388791 | H8: ='Data Sheet'!G19/'Data Sheet'!G$17 -> 0.0010540044 | I8: ='Data Sheet'!H19/'Data Sheet'!H$17 -> 0.0034353622 | J8: ='Data Sheet'!I19/'Data Sheet'!I$17 -> 0.0026688623 | ... L8: ='Data Sheet'!K19/'Data Sheet'!K$17 -> 0.012396627
B9: ='Data Sheet'!A20 -> Power and Fuel | C9: ='Data Sheet'!B20/'Data Sheet'!B$17 -> 0.0076169494 | D9: ='Data Sheet'!C20/'Data Sheet'!C$17 -> 0.0084376026 | E9: ='Data Sheet'!D20/'Data Sheet'!D$17 -> 0.010030383 | F9: ='Data Sheet'!E20/'Data Sheet'!E$17 -> 0.009245308 | G9: ='Data Sheet'!F20/'Data Sheet'!F$17 -> 0.00677258 | H9: ='Data Sheet'!G20/'Data Sheet'!G$17 -> 0.0071425499 | I9: ='Data Sheet'!H20/'Data Sheet'!H$17 -> 0.0067193269 | J9: ='Data Sheet'!I20/'Data Sheet'!I$17 -> 0.0072847393 | ... L9: ='Data Sheet'!K20/'Data Sheet'!K$17 -> 0
B10: ='Data Sheet'!A21 -> Other Mfr. Exp | C10: ='Data Sheet'!B21/'Data Sheet'!B$17 -> 0.0056238525 | D10: ='Data Sheet'!C21/'Data Sheet'!C$17 -> 0.0057900448 | E10: ='Data Sheet'!D21/'Data Sheet'!D$17 -> 0.005526993 | F10: ='Data Sheet'!E21/'Data Sheet'!E$17 -> 0.0049973566 | G10: ='Data Sheet'!F21/'Data Sheet'!F$17 -> 0.0097098278 | H10: ='Data Sheet'!G21/'Data Sheet'!G$17 -> 0.0096513294 | I10: ='Data Sheet'!H21/'Data Sheet'!H$17 -> 0.0095320882 | J10: ='Data Sheet'!I21/'Data Sheet'!I$17 -> 0.0066214008 | ... L10: ='Data Sheet'!K21/'Data Sheet'!K$17 -> 0
B11: ='Data Sheet'!A22 -> Employee Cost | C11: ='Data Sheet'!B22/'Data Sheet'!B$17 -> 0.03466696 | D11: ='Data Sheet'!C22/'Data Sheet'!C$17 -> 0.035877979 | E11: ='Data Sheet'!D22/'Data Sheet'!D$17 -> 0.038167274 | F11: ='Data Sheet'!E22/'Data Sheet'!E$17 -> 0.045151996 | G11: ='Data Sheet'!F22/'Data Sheet'!F$17 -> 0.048763713 | H11: ='Data Sheet'!G22/'Data Sheet'!G$17 -> 0.04586674 | I11: ='Data Sheet'!H22/'Data Sheet'!H$17 -> 0.039419484 | J11: ='Data Sheet'!I22/'Data Sheet'!I$17 -> 0.044421824 | ... L11: ='Data Sheet'!K22/'Data Sheet'!K$17 -> 0.049366667
B12: ='Data Sheet'!A23 -> Selling and admin | C12: ='Data Sheet'!B23/'Data Sheet'!B$17 -> 0.089759859 | D12: ='Data Sheet'!C23/'Data Sheet'!C$17 -> 0.084642912 | E12: ='Data Sheet'!D23/'Data Sheet'!D$17 -> 0.097483981 | F12: ='Data Sheet'!E23/'Data Sheet'!E$17 -> 0.11176712 | G12: ='Data Sheet'!F23/'Data Sheet'!F$17 -> 0.1126016 | H12: ='Data Sheet'!G23/'Data Sheet'!G$17 -> 0.10323922 | I12: ='Data Sheet'!H23/'Data Sheet'!H$17 -> 0.099471555 | J12: ='Data Sheet'!I23/'Data Sheet'!I$17 -> 0.085173786 | ... L12: ='Data Sheet'!K23/'Data Sheet'!K$17 -> 0
B13: ='Data Sheet'!A24 -> Other Expenses | C13: ='Data Sheet'!B24/'Data Sheet'!B$17 -> 0.022742161 | D13: ='Data Sheet'!C24/'Data Sheet'!C$17 -> 0.024448248 | E13: ='Data Sheet'!D24/'Data Sheet'!D$17 -> 0.028346027 | F13: ='Data Sheet'!E24/'Data Sheet'!E$17 -> 0.028966429 | G13: ='Data Sheet'!F24/'Data Sheet'!F$17 -> 0.023046098 | H13: ='Data Sheet'!G24/'Data Sheet'!G$17 -> 0.021282738 | I13: ='Data Sheet'!H24/'Data Sheet'!H$17 -> 0.017444734 | J13: ='Data Sheet'!I24/'Data Sheet'!I$17 -> 0.022093189 | ... L13: ='Data Sheet'!K24/'Data Sheet'!K$17 -> 0.11038098
B14: ='Data Sheet'!A25 -> Other Income | C14: ='Data Sheet'!B25/'Data Sheet'!B$17 -> 0.035238305 | D14: ='Data Sheet'!C25/'Data Sheet'!C$17 -> 0.02699682 | E14: ='Data Sheet'!D25/'Data Sheet'!D$17 -> 0.030954414 | F14: ='Data Sheet'!E25/'Data Sheet'!E$17 -> 0.045075337 | G14: ='Data Sheet'!F25/'Data Sheet'!F$17 -> 0.043288524 | H14: ='Data Sheet'!G25/'Data Sheet'!G$17 -> 0.021066503 | I14: ='Data Sheet'!H25/'Data Sheet'!H$17 -> 0.019618733 | J14: ='Data Sheet'!I25/'Data Sheet'!I$17 -> 0.029942576 | ... L14: ='Data Sheet'!K25/'Data Sheet'!K$17 -> 0.025326213
B15: ='Data Sheet'!A26 -> Depreciation | C15: ='Data Sheet'!B26/'Data Sheet'!B$17 -> 0.038244841 | D15: ='Data Sheet'!C26/'Data Sheet'!C$17 -> 0.034579887 | E15: ='Data Sheet'!D26/'Data Sheet'!D$17 -> 0.035097626 | F15: ='Data Sheet'!E26/'Data Sheet'!E$17 -> 0.046634946 | G15: ='Data Sheet'!F26/'Data Sheet'!F$17 -> 0.043115159 | H15: ='Data Sheet'!G26/'Data Sheet'!G$17 -> 0.031574848 | I15: ='Data Sheet'!H26/'Data Sheet'!H$17 -> 0.024033927 | J15: ='Data Sheet'!I26/'Data Sheet'!I$17 -> 0.037049674 | ... L15: ='Data Sheet'!K26/'Data Sheet'!K$17 -> 0.036776386
B16: ='Data Sheet'!A27 -> Interest | C16: ='Data Sheet'!B27/'Data Sheet'!B$17 -> 0.0013130646 | D16: ='Data Sheet'!C27/'Data Sheet'!C$17 -> 0.004332823 | E16: ='Data Sheet'!D27/'Data Sheet'!D$17 -> 0.00088185573 | F16: ='Data Sheet'!E27/'Data Sheet'!E$17 -> 0.0017737246 | G16: ='Data Sheet'!F27/'Data Sheet'!F$17 -> 0.0014465981 | H16: ='Data Sheet'!G27/'Data Sheet'!G$17 -> 0.0014332649 | I16: ='Data Sheet'!H27/'Data Sheet'!H$17 -> 0.0015905242 | J16: ='Data Sheet'!I27/'Data Sheet'!I$17 -> 0.0013647431 | ... L16: ='Data Sheet'!K27/'Data Sheet'!K$17 -> 0.0013021231
B17: ='Data Sheet'!A28 -> Profit before tax | C17: ='Data Sheet'!B28/'Data Sheet'!B$17 -> 0.14874348 | D17: ='Data Sheet'!C28/'Data Sheet'!C$17 -> 0.13991961 | E17: ='Data Sheet'!D28/'Data Sheet'!D$17 -> 0.12343424 | F17: ='Data Sheet'!E28/'Data Sheet'!E$17 -> 0.093877875 | G17: ='Data Sheet'!F28/'Data Sheet'!F$17 -> 0.07561246 | H17: ='Data Sheet'!G28/'Data Sheet'!G$17 -> 0.053177976 | I17: ='Data Sheet'!H28/'Data Sheet'!H$17 -> 0.087802891 | J17: ='Data Sheet'!I28/'Data Sheet'!I$17 -> 0.1228304 | ... L17: ='Data Sheet'!K28/'Data Sheet'!K$17 -> 0.10429259
... B21: ='Data Sheet'!A32 -> EBITDA | C21: ='Data Sheet'!B32/'Data Sheet'!B$17 -> 0.15304693 | D21: ='Data Sheet'!C32/'Data Sheet'!C$17 -> 0.15182673 | E21: ='Data Sheet'!D32/'Data Sheet'!D$17 -> 0.12844188 | F21: ='Data Sheet'!E32/'Data Sheet'!E$17 -> 0.097190061 | G21: ='Data Sheet'!F32/'Data Sheet'!F$17 -> 0.076885693 | H21: ='Data Sheet'!G32/'Data Sheet'!G$17 -> 0.065119586 | I21: ='Data Sheet'!H32/'Data Sheet'!H$17 -> 0.093808608 | J21: ='Data Sheet'!I32/'Data Sheet'!I$17 -> 0.13130224 | ... L21: ='Data Sheet'!K32/'Data Sheet'!K$17 -> 0.11704488
B23: ="Common Size Balance Sheet"&" - "&'Data Sheet'!B1 -> Common Size Balance Sheet - MARUTI SUZUKI INDIA LTD
B25: Particulars | C25: ='Data Sheet'!B16 -> 42825 | D25: ='Data Sheet'!C16 -> 43190 | E25: ='Data Sheet'!D16 -> 43555 | F25: ='Data Sheet'!E16 -> 43921 | G25: ='Data Sheet'!F16 -> 44286 | H25: ='Data Sheet'!G16 -> 44651 | I25: ='Data Sheet'!H16 -> 45016 | J25: ='Data Sheet'!I16 -> 45382 | ... L25: ='Data Sheet'!K16 -> 46112
B27: Total Liabilities | C27: ='Data Sheet'!B61/'Data Sheet'!B$61 -> 1 | D27: ='Data Sheet'!C61/'Data Sheet'!C$61 -> 1 | E27: ='Data Sheet'!D61/'Data Sheet'!D$61 -> 1 | F27: ='Data Sheet'!E61/'Data Sheet'!E$61 -> 1 | G27: ='Data Sheet'!F61/'Data Sheet'!F$61 -> 1 | H27: ='Data Sheet'!G61/'Data Sheet'!G$61 -> 1 | I27: ='Data Sheet'!H61/'Data Sheet'!H$61 -> 1 | J27: ='Data Sheet'!I61/'Data Sheet'!I$61 -> 1 | ... L27: ='Data Sheet'!K61/'Data Sheet'!K$61 -> 1
B28: ='Data Sheet'!A57 -> Equity Share Capital | C28: ='Data Sheet'!B57/'Data Sheet'!B$61 -> 0.0029060536 | D28: ='Data Sheet'!C57/'Data Sheet'!C$61 -> 0.0025062906 | E28: ='Data Sheet'!D57/'Data Sheet'!D$61 -> 0.0023605294 | F28: ='Data Sheet'!E57/'Data Sheet'!E$61 -> 0.0023731802 | G28: ='Data Sheet'!F57/'Data Sheet'!F$61 -> 0.0021155541 | H28: ='Data Sheet'!G57/'Data Sheet'!G$61 -> 0.0020226239 | I28: ='Data Sheet'!H57/'Data Sheet'!H$61 -> 0.0017849354 | J28: ='Data Sheet'!I57/'Data Sheet'!I$61 -> 0.0013633513 | ... L28: ='Data Sheet'!K57/'Data Sheet'!K$61 -> 0.0010558768
B29: ='Data Sheet'!A58 -> Reserves | C29: ='Data Sheet'!B58/'Data Sheet'!B$61 -> 0.71061864 | D29: ='Data Sheet'!C58/'Data Sheet'!C$61 -> 0.70389255 | E29: ='Data Sheet'!D58/'Data Sheet'!D$61 -> 0.73381357 | F29: ='Data Sheet'!E58/'Data Sheet'!E$61 -> 0.77422255 | G29: ='Data Sheet'!F58/'Data Sheet'!F$61 -> 0.73343318 | H29: ='Data Sheet'!G58/'Data Sheet'!G$61 -> 0.73916188 | I29: ='Data Sheet'!H58/'Data Sheet'!H$61 -> 0.72863545 | J29: ='Data Sheet'!I58/'Data Sheet'!I$61 -> 0.74133357 | ... L29: ='Data Sheet'!K58/'Data Sheet'!K$61 -> 0.71868875
B30: ='Data Sheet'!A59 -> Borrowings | C30: ='Data Sheet'!B59/'Data Sheet'!B$61 -> 0.0093070698 | D30: ='Data Sheet'!C59/'Data Sheet'!C$61 -> 0.0020050325 | E30: ='Data Sheet'!D59/'Data Sheet'!D$61 -> 0.0024949702 | F30: ='Data Sheet'!E59/'Data Sheet'!E$61 -> 0.0028933939 | G30: ='Data Sheet'!F59/'Data Sheet'!F$61 -> 0.0075781669 | H30: ='Data Sheet'!G59/'Data Sheet'!G$61 -> 0.0056995131 | I30: ='Data Sheet'!H59/'Data Sheet'!H$61 -> 0.014744039 | J30: ='Data Sheet'!I59/'Data Sheet'!I$61 -> 0.0010285844 | ... L30: ='Data Sheet'!K59/'Data Sheet'!K$61 -> 0.00068846931
B31: ='Data Sheet'!A60 -> Other Liabilities | C31: ='Data Sheet'!B60/'Data Sheet'!B$61 -> 0.27716823 | D31: ='Data Sheet'!C60/'Data Sheet'!C$61 -> 0.29159613 | E31: ='Data Sheet'!D60/'Data Sheet'!D$61 -> 0.26133093 | F31: ='Data Sheet'!E60/'Data Sheet'!E$61 -> 0.22051088 | G31: ='Data Sheet'!F60/'Data Sheet'!F$61 -> 0.2568731 | H31: ='Data Sheet'!G60/'Data Sheet'!G$61 -> 0.25311598 | I31: ='Data Sheet'!H60/'Data Sheet'!H$61 -> 0.25483558 | J31: ='Data Sheet'!I60/'Data Sheet'!I$61 -> 0.2562745 | ... L31: ='Data Sheet'!K60/'Data Sheet'!K$61 -> 0.2795669
B33: Total Assets | C33: ='Data Sheet'!B75/'Data Sheet'!B$75 -> 1 | D33: ='Data Sheet'!C75/'Data Sheet'!C$75 -> 1 | E33: ='Data Sheet'!D75/'Data Sheet'!D$75 -> 1 | F33: ='Data Sheet'!E75/'Data Sheet'!E$75 -> 1 | G33: ='Data Sheet'!F75/'Data Sheet'!F$75 -> 1 | H33: ='Data Sheet'!G75/'Data Sheet'!G$75 -> 1 | I33: ='Data Sheet'!H75/'Data Sheet'!H$75 -> 1 | J33: ='Data Sheet'!I75/'Data Sheet'!I$75 -> 1 | ... L33: ='Data Sheet'!K75/'Data Sheet'!K$75 -> 1
B34: ='Data Sheet'!A62 -> Net Block | C34: ='Data Sheet'!B62/'Data Sheet'!B$75 -> 0.25616959 | D34: ='Data Sheet'!C62/'Data Sheet'!C$75 -> 0.22222665 | E34: ='Data Sheet'!D62/'Data Sheet'!D$75 -> 0.24132584 | F34: ='Data Sheet'!E62/'Data Sheet'!E$75 -> 0.24744569 | G34: ='Data Sheet'!F62/'Data Sheet'!F$75 -> 0.20999606 | H34: ='Data Sheet'!G62/'Data Sheet'!G$75 -> 0.18414182 | I34: ='Data Sheet'!H62/'Data Sheet'!H$75 -> 0.21076895 | J34: ='Data Sheet'!I62/'Data Sheet'!I$75 -> 0.24166357 | ... L34: ='Data Sheet'!K62/'Data Sheet'!K$75 -> 0.23478751
B35: ='Data Sheet'!A63 -> Capital Work in Progress | C35: ='Data Sheet'!B63/'Data Sheet'!B$75 -> 0.024101 | D35: ='Data Sheet'!C63/'Data Sheet'!C$75 -> 0.035388492 | E35: ='Data Sheet'!D63/'Data Sheet'!D$75 -> 0.025120098 | F35: ='Data Sheet'!E63/'Data Sheet'!E$75 -> 0.022241885 | G35: ='Data Sheet'!F63/'Data Sheet'!F$75 -> 0.020970605 | H35: ='Data Sheet'!G63/'Data Sheet'!G$75 -> 0.039334008 | I35: ='Data Sheet'!H63/'Data Sheet'!H$75 -> 0.034328681 | J35: ='Data Sheet'!I63/'Data Sheet'!I$75 -> 0.067081743 | ... L35: ='Data Sheet'!K63/'Data Sheet'!K$75 -> 0.063179318
B36: ='Data Sheet'!A64 -> Investments | C36: ='Data Sheet'!B64/'Data Sheet'!B$75 -> 0.56101462 | D36: ='Data Sheet'!C64/'Data Sheet'!C$75 -> 0.59956945 | E36: ='Data Sheet'!D64/'Data Sheet'!D$75 -> 0.58628048 | F36: ='Data Sheet'!E64/'Data Sheet'!E$75 -> 0.58917736 | G36: ='Data Sheet'!F64/'Data Sheet'!F$75 -> 0.60166919 | H36: ='Data Sheet'!G64/'Data Sheet'!G$75 -> 0.56304894 | I36: ='Data Sheet'!H64/'Data Sheet'!H$75 -> 0.58139601 | J36: ='Data Sheet'!I64/'Data Sheet'!I$75 -> 0.49691208 | ... L36: ='Data Sheet'!K64/'Data Sheet'!K$75 -> 0.51610682
B37: ='Data Sheet'!A65 -> Other Assets | C37: ='Data Sheet'!B74/'Data Sheet'!B$75 -> 0.072306848 | D37: ='Data Sheet'!C74/'Data Sheet'!C$75 -> 0.06481168 | E37: ='Data Sheet'!D74/'Data Sheet'!D$75 -> 0.056241568 | F37: ='Data Sheet'!E74/'Data Sheet'!E$75 -> 0.059085901 | G37: ='Data Sheet'!F74/'Data Sheet'!F$75 -> 0.064024232 | H37: ='Data Sheet'!G74/'Data Sheet'!G$75 -> 0.098158876 | I37: ='Data Sheet'!H74/'Data Sheet'!H$75 -> 0.0833553 | J37: ='Data Sheet'!I74/'Data Sheet'!I$75 -> 0.083832231 | ... L37: ='Data Sheet'!K74/'Data Sheet'!K$75 -> 0.063394926
B38: ='Data Sheet'!A67 -> Receivables | C38: ='Data Sheet'!B67/'Data Sheet'!B$75 -> 0.023144504 | D38: ='Data Sheet'!C67/'Data Sheet'!C$75 -> 0.024322638 | E38: ='Data Sheet'!D67/'Data Sheet'!D$75 -> 0.036155182 | F38: ='Data Sheet'!E67/'Data Sheet'!E$75 -> 0.031082375 | G38: ='Data Sheet'!F67/'Data Sheet'!F$75 -> 0.017931773 | H38: ='Data Sheet'!G67/'Data Sheet'!G$75 -> 0.027251843 | I38: ='Data Sheet'!H67/'Data Sheet'!H$75 -> 0.039025071 | J38: ='Data Sheet'!I67/'Data Sheet'!I$75 -> 0.039866752 | ... L38: ='Data Sheet'!K67/'Data Sheet'!K$75 -> 0.035881006
B39: ='Data Sheet'!A68 -> Inventory | C39: ='Data Sheet'!B68/'Data Sheet'!B$75 -> 0.062811174 | D39: ='Data Sheet'!C68/'Data Sheet'!C$75 -> 0.052452845 | E39: ='Data Sheet'!D68/'Data Sheet'!D$75 -> 0.051941027 | F39: ='Data Sheet'!E68/'Data Sheet'!E$75 -> 0.05051102 | G39: ='Data Sheet'!F68/'Data Sheet'!F$75 -> 0.04271738 | H39: ='Data Sheet'!G68/'Data Sheet'!G$75 -> 0.047314665 | I39: ='Data Sheet'!H68/'Data Sheet'!H$75 -> 0.050634243 | J39: ='Data Sheet'!I68/'Data Sheet'!I$75 -> 0.046122384 | ... L39: ='Data Sheet'!K68/'Data Sheet'!K$75 -> 0.076037909
B40: ='Data Sheet'!A69 -> Cash & Bank | C40: ='Data Sheet'!B69/'Data Sheet'!B$75 -> 0.00045226663 | D40: ='Data Sheet'!C69/'Data Sheet'!C$75 -> 0.0012282484 | E40: ='Data Sheet'!D69/'Data Sheet'!D$75 -> 0.0029358108 | F40: ='Data Sheet'!E69/'Data Sheet'!E$75 -> 0.00045577634 | G40: ='Data Sheet'!F69/'Data Sheet'!F$75 -> 0.042690761 | H40: ='Data Sheet'!G69/'Data Sheet'!G$75 -> 0.040749844 | I40: ='Data Sheet'!H69/'Data Sheet'!H$75 -> 0.00049174379 | J40: ='Data Sheet'!I69/'Data Sheet'!I$75 -> 0.024521244 | ... L40: ='Data Sheet'!K69/'Data Sheet'!K$75 -> 0.010612503

Sheet IS-Forecasting
B2: ="Sales Forecasting"&" - "&'Data Sheet'!B1 -> Sales Forecasting - MARUTI SUZUKI INDIA LTD | G2: ="EBITDA Forecasting"&" - "&'Data Sheet'!B1 -> EBITDA Forecasting - MARUTI SUZUKI INDIA LTD | L2: ="COGS % Sales Forecasting"&" - "&'Data Sheet'!B1 -> COGS % Sales Forecasting - MARUTI SUZUKI INDIA LTD | R2: ="EBT Forecasting"&" - "&'Data Sheet'!B1 -> EBT Forecasting - MARUTI SUZUKI INDIA LTD | W2: ="Net Profit Forecasting"&" - "&'Data Sheet'!B1 -> Net Profit Forecasting - MARUTI SUZUKI INDIA LTD
B3: Year Weight | C3: Years | D3: Sales | E3: Sales Growth | G3: Year Weight | H3: Years | I3: EBITDA | J3: EBITDA Growth | L3: Year Weight | M3: Years | N3: Sales | O3: COGS | P3: COGS % Sales | R3: Year Weight | S3: Years | T3: EBT | U3: EBT Growth | W3: Year Weight | X3: Years | Y3: Sales | Z3: Net Profit | AA3: Net Margin
B4: 1 | C4: 2017 | D4: 68085 | G4: 1 | H4: 2017 | I4: 10421.3 | L4: 1 | M4: 2017 | N4: 68085 | O4: 50004 | P4: =O4/N4 -> 0.7344349 | R4: 1 | S4: 2017 | T4: 10127.2 | W4: 1 | X4: 2017 | Y4: 68085 | Z4: 7511 | AA4: =Z4/Y4 -> 0.11031798
B5: =B4+1 -> 2 | C5: =C4+1 -> 2018 | D5: 79809 | E5: =D5/D4-1 -> 0.17219652 | G5: =G4+1 -> 2 | H5: =H4+1 -> 2018 | I5: 12117.9 | J5: =I5/I4-1 -> 0.16280119 | L5: =L4+1 -> 2 | M5: =M4+1 -> 2018 | N5: 79809 | O5: 58985 | P5: =O5/N5 -> 0.73907705 | R5: =R4+1 -> 2 | S5: =S4+1 -> 2018 | T5: 11166.9 | U5: =T5/T4-1 -> 0.10266411 | W5: =W4+1 -> 2 | X5: =X4+1 -> 2018 | Y5: 79809 | Z5: 7880.7 | AA5: =Z5/Y5 -> 0.098744502
B6: =B5+1 -> 3 | C6: =C5+1 -> 2019 | D6: 86068 | E6: =D6/D5-1 -> 0.078424739 | G6: =G5+1 -> 3 | H6: =H5+1 -> 2019 | I6: 11056.3 | J6: =I6/I5-1 -> -0.087605938 | L6: =L5+1 -> 3 | M6: =M5+1 -> 2019 | N6: 86068 | O6: 64182.2 | P6: =O6/N6 -> 0.74571502 | R6: =R5+1 -> 3 | S6: =S5+1 -> 2019 | T6: 10623.8 | U6: =T6/T5-1 -> -0.048634805 | W6: =W5+1 -> 3 | X6: =X5+1 -> 2019 | Y6: 86068 | Z6: 7650.6 | AA6: =Z6/Y6 -> 0.08889018
B7: =B6+1 -> 4 | C7: =C6+1 -> 2020 | D7: 75660 | E7: =D7/D6-1 -> -0.12092764 | G7: =G6+1 -> 4 | H7: =H6+1 -> 2020 | I7: 7355 | J7: =I7/I6-1 -> -0.33476841 | L7: =L6+1 -> 4 | M7: =M6+1 -> 2020 | N7: 75660 | O7: 57657.1 | P7: =O7/N7 -> 0.76205525 | R7: =R6+1 -> 4 | S7: =S6+1 -> 2020 | T7: 7102.8 | U7: =T7/T6-1 -> -0.33142567 | W7: =W6+1 -> 4 | X7: =X6+1 -> 2020 | Y7: 75660 | Z7: 5677.6 | AA7: =Z7/Y7 -> 0.075040973
B8: =B7+1 -> 5 | C8: =C7+1 -> 2021 | D8: 70372 | E8: =D8/D7-1 -> -0.06989162 | G8: =G7+1 -> 5 | H8: =H7+1 -> 2021 | I8: 5410.6 | J8: =I8/I7-1 -> -0.26436438 | L8: =L7+1 -> 5 | M8: =M7+1 -> 2021 | N8: 70372 | O8: 55415.6 | P8: =O8/N8 -> 0.78746661 | R8: =R7+1 -> 5 | S8: =S7+1 -> 2021 | T8: 5321 | U8: =T8/T7-1 -> -0.25085882 | W8: =W7+1 -> 5 | X8: =X7+1 -> 2021 | Y8: 70372 | Z8: 4389.1 | AA8: =Z8/Y8 -> 0.062369977
B9: =B8+1 -> 6 | C9: =C8+1 -> 2022 | D9: 88330 | E9: =D9/D8-1 -> 0.25518672 | G9: =G8+1 -> 6 | H9: =H8+1 -> 2022 | I9: 5752 | J9: =I9/I8-1 -> 0.063098362 | L9: =L8+1 -> 6 | M9: =M8+1 -> 2022 | N9: 88330 | O9: 71578.8 | P9: =O9/N9 -> 0.81035662 | R9: =R8+1 -> 6 | S9: =S8+1 -> 2022 | T9: 4697.2 | U9: =T9/T8-1 -> -0.1172336 | W9: =W8+1 -> 6 | X9: =X8+1 -> 2022 | Y9: 88330 | Z9: 3879.5 | AA9: =Z9/Y9 -> 0.043920525
B10: =B9+1 -> 7 | C10: =C9+1 -> 2023 | D10: 117571 | E10: =D10/D9-1 -> 0.33104268 | G10: =G9+1 -> 7 | H10: =H9+1 -> 2023 | I10: 11029.2 | J10: =I10/I9-1 -> 0.9174548 | L10: =L9+1 -> 7 | M10: =M9+1 -> 2023 | N10: 117571 | O10: 92796.1 | P10: =O10/N10 -> 0.78927712 | R10: =R9+1 -> 7 | S10: =S9+1 -> 2023 | T10: 10323.1 | U10: =T10/T9-1 -> 1.1977135 | W10: =W9+1 -> 7 | X10: =X9+1 -> 2023 | Y10: 117571 | Z10: 8211 | AA10: =Z10/Y10 -> 0.069838651
B11: =B10+1 -> 8 | C11: =C10+1 -> 2024 | D11: 141858 | E11: =D11/D10-1 -> 0.20657305 | G11: =G10+1 -> 8 | H11: =H10+1 -> 2024 | I11: 18626.3 | J11: =I11/I10-1 -> 0.68881696 | L11: =L10+1 -> 8 | M11: =M10+1 -> 2024 | N11: 141858 | O11: 108015.2 | P11: =O11/N11 -> 0.76143185 | R11: =R10+1 -> 8 | S11: =S10+1 -> 2024 | T11: 17424.5 | U11: =T11/T10-1 -> 0.68791351 | W11: =W10+1 -> 8 | X11: =X10+1 -> 2024 | Y11: 141858 | Z11: 13488.2 | AA11: =Z11/Y11 -> 0.095082406
B12: =B11+1 -> 9 | C12: =C11+1 -> 2025 | D12: 152913 | E12: =D12/D11-1 -> 0.077930043 | G12: =G11+1 -> 9 | H12: =H11+1 -> 2025 | I12: 20223.6 | J12: =I12/I11-1 -> 0.085755088 | L12: =L11+1 -> 9 | M12: =M11+1 -> 2025 | N12: 152913 | O12: 117563.8 | P12: =O12/N12 -> 0.76882803 | R12: =R11+1 -> 9 | S12: =S11+1 -> 2025 | T12: 19620 | U12: =T12/T11-1 -> 0.12600075 | W12: =W11+1 -> 9 | X12: =X11+1 -> 2025 | Y12: 152913 | Z12: 14500.2 | AA12: =Z12/Y12 -> 0.09482647
B13: =B12+1 -> 10 | C13: =C12+1 -> 2026 | D13: 183316 | E13: =D13/D12-1 -> 0.19882548 | G13: =G12+1 -> 10 | H13: =H12+1 -> 2026 | I13: 21456.2 | J13: =I13/I12-1 -> 0.060948595 | L13: =L12+1 -> 10 | M13: =M12+1 -> 2026 | N13: 183316 | O13: 141625.2 | P13: =O13/N13 -> 0.77257413 | R13: =R12+1 -> 10 | S13: =S12+1 -> 2026 | T13: 19118.5 | U13: =T13/T12-1 -> -0.025560652 | W13: =W12+1 -> 10 | X13: =X12+1 -> 2026 | Y13: 183316 | Z13: 14679.5 | AA13: =Z13/Y13 -> 0.080077571
B14: =B13+1 -> 11 | C14: =C13+1 -> 2027 | D14: =$C$36+B14*$C$37 -> 172113.13 | E14: =D14/D13-1 -> -0.061112323 | G14: =G13+1 -> 11 | H14: =H13+1 -> 2027 | I14: =$C$55+G14*$C$56 -> 19187.107 | J14: =I14/I13-1 -> -0.10575467 | L14: =L13+1 -> 11 | M14: =M13+1 -> 2027 | N14: 172113.13 | O14: =$M$36+L14*$M$37 -> 134295.22 | P14: =O14/N14 -> 0.78027294 | R14: =R13+1 -> 11 | S14: =S13+1 -> 2027 | T14: =$M$55+R14*$M$56 -> 17656.967 | U14: =T14/T13-1 -> -0.076446025 | W14: =W13+1 -> 11 | X14: =X13+1 -> 2027 | Y14: 172113.13 | Z14: =$X$36+$X$37*W14 -> 13691.127 | AA14: =Z14/Y14 -> 0.079547251
B15: =B14+1 -> 12 | C15: =C14+1 -> 2028 | D15: =$C$36+B15*$C$37 -> 184061.3 | E15: =D15/D14-1 -> 0.069420441 | G15: =G14+1 -> 12 | H15: =H14+1 -> 2028 | I15: =$C$55+G15*$C$56 -> 20431.155 | J15: =I15/I14-1 -> 0.064837732 | L15: =L14+1 -> 12 | M15: =M14+1 -> 2028 | N15: 184061.3 | O15: =$M$36+L15*$M$37 -> 143843.02 | P15: =O15/N15 -> 0.78149519 | R15: =R14+1 -> 12 | S15: =S14+1 -> 2028 | T15: =$M$55+R15*$M$56 -> 18766.87 | U15: =T15/T14-1 -> 0.062859213 | W15: =W14+1 -> 12 | X15: =X14+1 -> 2028 | Y15: 184061.3 | Z15: =$X$36+$X$37*W15 -> 14582.833 | AA15: =Z15/Y15 -> 0.079228133
B16: =B15+1 -> 13 | C16: =C15+1 -> 2029 | D16: =$C$36+B16*$C$37 -> 196009.47 | E16: =D16/D15-1 -> 0.064914078 | G16: =G15+1 -> 13 | H16: =H15+1 -> 2029 | I16: =$C$55+G16*$C$56 -> 21675.204 | J16: =I16/I15-1 -> 0.060889777 | L16: =L15+1 -> 13 | M16: =M15+1 -> 2029 | N16: 196009.47 | O16: =$M$36+L16*$M$37 -> 153390.83 | P16: =O16/N16 -> 0.78256844 | R16: =R15+1 -> 13 | S16: =S15+1 -> 2029 | T16: =$M$55+R16*$M$56 -> 19876.773 | U16: =T16/T15-1 -> 0.059141618 | W16: =W15+1 -> 13 | X16: =X15+1 -> 2029 | Y16: 196009.47 | Z16: =$X$36+$X$37*W16 -> 15474.54 | AA16: =Z16/Y16 -> 0.078947919
